Workbook

Sheet 실증절차
A2: 실 증 절 차
A3: (한국채택국제회계기준)
A5: 본 실증절차는 감사계획수립시에 감사대상회사에 적용하는 경우에는 감사위험 수준을 반영한 적발위험의 목표수준설정에 따라 적절히 수정 또는 보완하여 사용한다.
A6: 예시한 감사절차는 제조업을 대상으로 한 일반적인 감사절차를 기술한 것이므로 제조업 이외의 업종이나 기타 회사의 개별상황에 따라 적절히 수정 또는 보완하여 사용한다.
A7: 감사인은 평가된 중요왜곡표시위험과 관계없이 중요한 각 거래유형과 계정잔액 및 공시에 대하여는 실증절차를 설계하고 수행하여야 한다.
A8: 감사인은 기업의 재무제표 결산절차와 관련된 실증절차를 수행할 때 다음의 감사절차를 포함하여야 한다. (a) 재무제표의 정보 가 그 기초가 되는 회계기록과 일치하는지를 확인하거나 차이를 조정함(총계정원장과 보조원장 내에서 입수된 정보이든 외부에서 입수된 정보이든 공시에 포함된 정보가 일치하는지 확인하거나 차이를 조정하는 것을 포함) (b) 재무제표를 작성하는 과정에서 행한 중요한 분개 및 기타 수정사항에 대하여 조사함
A9: 인덱스 | B9: 계정과목 | C9: 담당자 | D9: 종료일
A10: A | B10: 현금및현금성자산, 장단기금융상품 | C10: 홍길동 | D10: 2024년 x월 xx일
A11: B | B11: 유가증권(유동,비유동) | C11: 홍길동 | D11: 2024년 x월 xx일
A12: SAJ | B12: 종속기업 또는 관계기업, 공동기업 | C12: 홍길동 | D12: 2024년 x월 xx일
A13: DER | B13: 파생상품 | C13: 홍길동 | D13: 2024년 x월 xx일
A14: C | B14: 매출채권(장단기) | C14: 홍길동 | D14: 2024년 x월 xx일
A15: DL | B15: 리스 | C15: 홍길동 | D15: 2024년 x월 xx일
A16: D | B16: 기타유동자산 | C16: 홍길동 | D16: 2024년 x월 xx일
A17: E | B17: 재고자산 | C17: 홍길동 | D17: 2024년 x월 xx일
A18: E100 | B18: 재고자산실사입회 | C18: 홍길동 | D18: 2024년 x월 xx일
A19: F | B19: 투자부동산 | C19: 홍길동 | D19: 2024년 x월 xx일
A20: G | B20: 유형자산 | C20: 홍길동 | D20: 2024년 x월 xx일
... A32: GG | B32: 자본 | C32: 홍길동 | D32: 2024년 x월 xx일
D33: 2024년 x월 xx일
A34: P | B34: 매출 및 기타수익 | C34: 홍길동 | D34: 2024년 x월 xx일
A35: Q | B35: 매출원가 및 제조원가 | C35: 홍길동 | D35: 2024년 x월 xx일
A36: R | B36: 판매비와 관리비 | C36: 홍길동 | D36: 2024년 x월 xx일
A37: S | B37: 기타이익, 기타비용 | C37: 홍길동 | D37: 2024년 x월 xx일
A38: T | B38: 이연법인세․미지급법인세 | C38: 홍길동 | D38: 2024년 x월 xx일
A39: U | B39: 매각예정비유동자산과 중단사업 | C39: 홍길동 | D39: 2024년 x월 xx일
A40: V | B40: K-IFRS 최초채택 | C40: 홍길동 | D40: 2024년 x월 xx일
A41: JV | B41: 공동약정 | C41: 홍길동 | D41: 2024년 x월 xx일
A42: SEG | B42: 부문별정보 | C42: 홍길동 | D42: 2024년 x월 xx일
A43: EST | B43: 공정가치 등 회계추정치 | C43: 홍길동 | D43: 2024년 x월 xx일
A44: IOC | B44: 정보시스템조직의 회계관리 입출력 | C44: 홍길동 | D44: 2024년 x월 xx일
A45: CF | B45: 현금흐름표 | C45: 홍길동 | D45: 2024년 x월 xx일

Sheet A
A1: 실 증 절 차
A2: (A. 현금및현금성자산, 장단기금융상품)
A4: 회사명 | F4: 작성자 | I4: 일자
A5: 결산일 | F5: 검토자 | I5: 일자
A6: 경영진 주장 :
A7: A | B7: : 정확성(Accuracy) | D7: E | E7: : 실재성(Existence) | G7: RO | H7: : 권리와 의무(Rights and obligations)
A8: C | B8: : 완전성(Completeness) | D8: O | E8: : 발생사실(Occurrence) | G8: CL | H8: : 분류(Classification)
A9: CO | B9: : 기간귀속(Cutoff) | D9: V | E9: : 평가(Valuation) | G9: U | H9: : 이해가능성(Understandability)
A10: P | B10: : 표시(Presentation)
A11: ※ 업무요령 : 조서번호 2302 감사위험의 평가(경영진 주장 수준)에서 파악된 위험과 조서번호 3100 위험에 대한 대응에 기재된 실증절차에 맞게 실증절차를 수행한다.
A13: Part 1. 절차 예시
A14: 감사절차 | J14: 경영진 주장 | K14: 조서번호
A15: 1. 현금및현금성자산 총괄표 작성 | J15: E, C, CL
A16: 당기말잔액은 총계정원장과, 전기말잔액은 전기감사보고서와 각각 대조하고, 양년도간 특별한 변동사항은 그 원인을 규명한다.
A17: 2. 현금및현금성자산 및 장단기금융상품 명세서 | J17: C, V
A18: (1) 현금및현금성자산, 장단기금융상품 명세서를 입수하여 금액을 계산검증하고 보조부와 대조 확인한다.
A19: (2) 명세서를 스캔하여 유의적이거나 비경상적인 항목들을 검토한다.
A20: 3. 현금, 미사용수표 및 어음의 실사를 수행한다. | J20: E, C, RO
A21: 4. 금융기관 등에 대한 조회 | J21: E, RO
A22: 외부 조회에 대한 구체적인 절차는 Audit Guide 3320 외부조회를 참고한다.
A23: 5. 사용이 제한된 예금과 장기성예금 해당 여부 | J23: CL
A24: 예금의 사용제한이나 질권, 기타 담보제공 및 장기성 예금 여부를 확인하기 위하여 은행조회서, 의사록, 대출약정서 등을 검토하고, 경영진에게 질문한다.
A25: 6.재무제표 공시사항 검토(공시사항점검표 참조) | J25: C, CL, U, P
A26: 7.감사결론의 기술
A29: Part 2. 추가 고려 절차
A30: 감사절차 | J30: 경영진주장 | K30: 조서번호
A31: 1. 금융기관 등에 대한 조회 시 유의사항 | J31: E, RO
A32: (1) 기중에 거래가 해지되었거나 잔액이 없는 예금계정을 포함하여 모든 금융기관으로부터 조회서를 발송 및 회수한다.
A33: (2) 조회서상의 미회수 어음/수표내역을 보고기간종료일 현재 미사용, 견질제공, 지급어음명세서 등을 통하여 확인한다.
A34: (3) 은행연합회가 제공하는 월보 및 일보(여수신현황표)를 입수하여 차입금, 여신한도, 담보제공, 지급보증, 파생상품 등의 내역이 금융기관조회서의 내용과 일치하는지 확인한다.
A35: (4) 회사로부터 조회서 발송대상 금융기관 리스트를 입수하여 다음과 같은 절차를 수행한다.
A36: ① 당기 또는 전기말 현재 예․적금, 차입금, 지급보증 등의 잔액이 있는 모든 금융기관이 포함되어 있는지를 잔액명세서와 대조하여 확인한다.
A37: ② 당기말 현재 잔액은 없으나 기중 거래가 있었던 모든 금융기관이 포함되어 있는지를 확인하기 위하여 예금, 차입금 및 이자비용 장부를 개관한다.
A38: ③ 당기중 파생상품거래, 지급보증거래, 한도거래 등이 있었던 모든 금융기관이 포함되어 있는지를 확인하기 위하여 회사의 자금 담당자에게 질문하고 또한 징구 받은 제계약서 및 제의사록을 검토한다.
A39: (5) 모든 계좌를 조회하지 않는 경우 그 근거를 조서화한다.
A40: (6) 금융기관조회서의 작성은 회사가 하는 것이 효율적이나, 발송과 회신은 감사인이 직접 수행하여야 한다.
A41: 2. 양도성예금증서(CD) 및 표지어음의 실사를 수행한다. | J41: E, RO
A42: (1) CD의 사본(또는 발생사실 확인서)이 아니라 반드시 실물을 회사가 소유하고 있는지 기말재고실사시 및 기말감사시점에 모두 확인한다.
A43: (2) 분석적절차를 통하여 회사의 영업현황, 재무구조 또는 자금능력 등에 비추어 그 보유사유의 타당성과 보유규모의 적정성을 평가한다.
A44: (3) 회사에게 취득자금의 원천 및 입․출금 관련 증빙자료(통장기록등)를 요구하여 정상적인 회사의 자금능력으로 해당 CD 등을 취득하였는지 여부를 검토한다.
...

Sheet B
A1: 실 증 절 차
A2: (B. 유가증권(유동,비유동))
A4: 회사명 | C4: 0 | F4: 작성자 | G4: 0 | I4: 일자
A5: 결산일 | C5: 2021-01-00 | F5: 검토자 | G5: 0 | I5: 일자
A6: 경영진 주장 :
A7: A | B7: : 정확성(Accuracy) | D7: E | E7: : 실재성(Existence) | G7: RO | H7: : 권리와 의무(Rights and obligations)
A8: C | B8: : 완전성(Completeness) | D8: O | E8: : 발생사실(Occurrence) | G8: CL | H8: : 분류(Classification)
A9: CO | B9: : 기간귀속(Cutoff) | D9: V | E9: : 평가(Valuation) | G9: U | H9: : 이해가능성(Understandability)
A10: P | B10: : 표시(Presentation)
A11: ※ 업무요령 : 조서번호 2302 감사위험의 평가(경영진 주장 수준)에서 파악된 위험과 조서번호 3100 위험에 대한 대응에 기재된 실증절차에 맞게 실증절차를 수행한다.
A13: Part 1. 절차 예시
A14: 감사절차 | J14: 경영진 주장 | K14: 조서번호
A15: 1. 금융자산 총괄표 작성 | J15: E, C, CL
A16: 당기말잔액은 총계정원장과, 전기말잔액은 전기감사보고서와 각각 대조하고, 양년도간 특별한 변동사항은 그 원인을 규명한다.
A17: 2.금융자산 명세서 | J17: C, V
A18: (1) 금융자산명세서를 입수하여 금액을 계산검증하고 보조부와 대조 확인한다.
A19: (2) 명세서를 스캔하여 유의적이거나 비경상적인 항목들을 검토한다.
A20: 3. 금융자산의 실재성 확인 | J20: E, RO
A21: (1) 다음의 방법으로 금융자산의 실재성을 확인한다.
A22: ① 회사가 직접 보유중인 금융자산은 실사한다.
A23: ② 타처 보관 또는 담보로 제공된 금융자산은 보관자에게 직접 조회하거나 보관확인서를 입수한다.
A24: ③ 조회서, 계약서 및 의사록 등의 검토를 통하여 유치권, 저당권 및 담보제공 등을 확인한다. 외부 조회에 대한 구체적인 절차는 Audit Guide 3320 외부조회를 참고한다.
A25: ④ 제 3자 소유 금융자산을 대신하여 보유하고 있는 경우, 금융자산명세서에 포함되어 있지 않음을 확인하고, 실제 소유자에게 성격과 수량을 확인한다.
A26: (2) 금융자산 수탁기관의 존속가능성을 평가한다.
A27: 4. 금융자산 완전성 검토 | J27: C
A28: 이사회의사록 및 과거거래원장을 검토하고 계정 잔액과 기타관련계정간의 관계를 분석하며 다른 테스트를 고려하여 금융자산의 완전성을 검토한다.
A29: 5. 중요한 증감의 검토 | J29: O, C,
A30: (1) 기중 중요한 금융자산의 취득거래에 대하여는 거래증빙을 대사하여 거래의 기간귀속, 발생사실, 취득원가 등을 확인한다. | J30: CO, V
A31: (2) 최초인식시 공정가치(일반적으로 제공한 대가와 동일)로 측정되었음을 확인하고, 당기손익-공정가치 측정 금융자산의 거래원가는 당기손익으로, 그 외의 금융자산의 거래원가는 해당 공정가치에 가산되었음을 확인한다.
A32: (3) 기중 중요한 금융자산의 처분거래에 대해 거래증빙을 대사하여 거래의 기간귀속, 발생사실, 처분손익 등을 확인한다.
A33: 6. 금융자산의 분류 | J33: CL
A34: 금융자산이 K-IFRS 1109, 1027, 1028, 1111에 따라 당기손익-공정가치측정 금융자산, 기타포괄손익-공정가치측정 금융자산, 상각후원가측정 금융자산 또는 종속기업, 관계기업, 공동기업 등으로 적절히 분류되었는지 검토한다. (종속기업, 관계기업, 공동기업으로 분류된 경우 "SAJ.종속기업 또는 관계기업, 공동기업 " 에서 절차를 수행)
A35: 7. 금융자산의 후속측정 | J35: V
A36: (1) 공정가치로 평가하는 금융자산에 대하여 다음의 절차를 수행한다.
A37: ① 공시가격으로 측정된 금융자산 - 독립적으로 입수한 공시가격과 대사한다. 유동성이 적은 금융자산에 대하여는 공시가격의 적합성을 평가한다.
A38: ② 평가기법을 사용한 공정가치로 측정된 금융자산 - 활성시장에서 공시되는 거래가격이 없음을 확인하고, ‘공정가치 등 회계추정치에 대한 실증절차’를 수행한다.
A39: ③ 평가로 인한 손익이 각 분류별로 당기손익 또는 기타포괄손익누계액으로 적절히 반영되었는지 검토한다.
A40: ④ 기타포괄손익-공정가치측정 금융자산의 미실현보유손익의 변동내역과 처분에 따른 실현손익의 내용을 검토한다.
A41: ⑤ 비상장주식을 원가로 측정하는 경우, 원가가 공정가치의 적절한 추정치가 될 수 있는 요건을 모두 충족하는지 검토한다. '비상장주식에 대한 공정가치평가 관련 감독지침(2019.3.12)' 및 '비상장주식에 대한 공정가치평가 관련 가이드라인(2020.1.22)' 참고
A42: (2) 상각후원가측정 금융자산의 경우, 최초인식금액과 만기가액의 차이가 유효이자율에 따라 적절히 상각되고, 이를 취득원가와 이자수익에 가감하고 있는지 확인한다.
...

Sheet SAJ
A1: 실 증 절 차
A2: (SAJ. 종속기업 또는 관계기업, 공동기업)
A4: 회 사 명 : | C4: 0 | F4: 작 성 자 : | G4: =A!G4 -> 0 | I4: 일 자 :
A5: 결 산 일 : | C5: 0 | F5: 검 토 자 : | G5: =A!G5 -> 0 | I5: 일 자 :
A6: 경영진 주장 :
A7: A | B7: : 정확성(Accuracy) | D7: E | E7: : 실재성(Existence) | G7: RO | H7: : 권리와 의무(Rights and obligations)
A8: C | B8: : 완전성(Completeness) | D8: O | E8: : 발생사실(Occurrence) | G8: CL | H8: : 분류(Classification)
A9: CO | B9: : 기간귀속(Cutoff) | D9: V | E9: : 평가(Valuation) | G9: U | H9: : 이해가능성(Understandability)
A10: P | B10: : 표시(Presentation)
A11: ※ 업무요령 : 조서번호 2302 감사위험의 평가(경영진 주장 수준)에서 파악된 위험과 조서번호 3100 위험에 대한 대응에 기재된 실증절차에 맞게 실증절차를 수행한다.
A13: Part 1. 절차 예시
A14: 감 사 절 차 | J14: 경영진 주장 | K14: 조서번호
A15: 1. 종속기업 또는 관계기업, 공동기업 총괄표 작성
A16: (1) 회사가 보유한 종속기업 또는 관계기업, 공동기업에 대한 기초자료를 징구한다. | J16: E, C, CL
A17: (2) 총괄표를 작성한다. 당기와 전기의 잔액과 총계정원장 및 전기 보고서를 대사하고, 양년도간 특별한 변동사항은 그 원인을 규명한다.
A18: 2. 종속기업 또는 관계기업, 공동기업 명세서
A19: (1) 종속기업 또는 관계기업, 공동기업 명세서를 입수하여 금액을 계산검증하고 보조부와 대조 확인한다. | J19: C, V
A20: (2) 명세서를 스캔하여 유의적이거나 비경상적인 항목들을 검토한다.
A21: 3. 실재성 확인 및 중요한 증감의 검토 | J21: E, RO, O, C
A22: (1) 주주총회, 이사회 및 기타 지배기구회의의 의사록에 대한 검토 및 유의적인 계약의 발생사실 여부에 대한 인터뷰 결과를 고려한다.
A23: (2) 주식양수도 계약서 및 주권(또는 주권미발행확인서)을 징구하여 발생사실 및 실재성을 확인한다.
A24: (3) 당기의 중요한 처분건에 대해, 주식양수도 계약서 등 거래증빙을 대사하여 거래의 기간귀속, 발생사실, 처분손익 등을 확인한다.
A25: 4. 종속기업 또는 관계기업, 공동기업에 대한 측정의 적정성 검토 | J25: V
A26: (1) 별도재무제표상 종속기업 또는 관계기업, 공동기업이 K-IFRS 1027호에 따라 측정 되었는지 확인한다.
A27: 가. 공정가치법을 적용한 경우 : K-IFRS 1113호에 따라 측정되었는지 확인한다.
A28: 나. 원가법을 적용한 경우 : 취득대가 및 거래원가 등이 적절히 반영되어있는지 검토한다.
A29: 다. 지분법을 적용한 경우 :
A30: - 종속기업 또는 관계기업, 공동기업의 재무정보에 대한 충분하고 적합한 감사증거를 획득하고, 지분법회계처리가 적정한지 검토한다(연결재무제표에 대한 감사절차 참고).
A31: - 지분법적용회사에 대한 회계기준 및 회계정책이 일치 여부를 확인하고 불일치시 조정내역을 점검한다.
A32: 5. 손상차손 등 | J32: V
A33: (1) 손상징후 여부를 검토하고, 징후가 있는경우 손상평가를 수행한다.
A34: 6. 재무제표 공시사항(공시사항 점검표 참조) | J34: C, CL, U,P
A35: 7. 감사결론의 기술
A38: Part 2. 추가감사절차
A40: * 감사인이 상기 감사절차예시 이외의 추가절차를 수행할 경우, 아래에 해당 내용을 기재한다.
A42: 감사절차 | J42: 경영진주장 | K42: 조서번호

Sheet DER
A1: 실 증 절 차
A2: (DER. 파생상품)
A4: 회사명 | C4: =A!C4 -> 0 | F4: 작성자 | G4: =A!G4 -> 0 | I4: 일자
A5: 결산일 | C5: =A!C5 -> 0 | F5: 검토자 | G5: =A!G5 -> 0 | I5: 일자
A6: 경영진 주장 :
A7: A | B7: : 정확성(Accuracy) | D7: E | E7: : 실재성(Existence) | G7: RO | H7: : 권리와 의무(Rights and obligations)
A8: C | B8: : 완전성(Completeness) | D8: O | E8: : 발생사실(Occurrence) | G8: CL | H8: : 분류(Classification)
A9: CO | B9: : 기간귀속(Cutoff) | D9: V | E9: : 평가(Valuation) | G9: U | H9: : 이해가능성(Understandability)
A10: P | B10: : 표시(Presentation)
A11: ※ 업무요령 : 조서번호 2302 감사위험의 평가(경영진 주장 수준)에서 파악된 위험과 조서번호 3100 위험에 대한 대응에 기재된 실증절차에 맞게 실증절차를 수행한다.
A13: Part 1. 절차 예시
A14: 감사절차 | J14: 경영진 주장 | K14: 조서번호
A15: 1. 파생상품 총괄표 작성 | J15: E, C, CL
A16: 당기말잔액은 총계정원장과, 전기말잔액은 전기감사보고서와 각각 대조하고, 양년도간 특별한 변동사항은 그 원인을 규명한다.
A17: 2. 파생상품 명세 | J17: C, V
A18: 파생상품명세서를 입수하여 계산검증하고, 보조부와 대조 확인한다. 명세서는 다음과 같은 세부사항을 포함한다.
A19: ● 파생상품의 유형(스왑, 선물, 옵션 등) 및 기초상품(주식, 이자율, 환율, 상품 등)
A20: ● 파생상품의 계약조건 (계약단위수량, 통화, 매매일, 만기일, 거래상대방, 결제조항, 매도제한 등)
A21: ● 파생상품거래의 목적(매매목적 또는 위험회피목적)
A22: ● 위험회피회계의 적용 여부 및 위험회피대상, 관련 문서화 내용
A23: ● 공정가치
A24: 3. 파생상품 거래의 조회 | J24: E, RO
A25: 파생상품의 거래상대방(금융기관 등)에게 조회서를 발송하여 거래의 실재성 및 완전성을 확인하고, 거래조건의 정확성을 확인한다. 외부 조회에 대한 구체적인 절차는 Audit Guide 3320 외부조회를 참고한다.
A26: 4. 파생상품의 완전성 | J26: C
A27: 파생상품 관련 보조부, 이사회의사록, 금융기관조회서 등을 확인하여 회사제시 파생상품 거래내역의 완전성을 확인한다.
A28: 5. 파생상품의 후속측정 | J28: V
A29: (1) 활성시장의 공시가격으로 측정된 파생상품 - 공정가치가 보고기간말의 공시가격과 동일한지 검증한다.
A30: (2) 평가기법을 사용한 공정가치로 측정된 파생상품 - 활성시장에서 공시되는 거래가격이 없음을 확인하고, ‘공정가치 등 회계추정치에 대한 실증절차’를 수행한다. ‘전문가의 활용’을 고려한다.
A31: (3) 권리와 의무가 적절한 공정가치로 측정되어 자산, 부채로 계상되어 있는지 확인한다. 평가로 인한 손익이 당기손익으로 적절히 회계처리되었는지 확인한다. 단, 위험회피수단으로 지정된 파생상품의 경우, 위험회피유형별로 적절하게 회계처리되었는지 확인한다.
A32: (4) 매도 등에서 발생할 수 있는 거래원가가 공정가치에서 가감되지 않았는지 검증한다.
A33: 6. 파생상품의 표시 | J33: CL
A34: (1) 공정가치가 양(+)인 모든 파생상품이 유동자산으로 표시되었고 공정가치가 음(-)인 모든 파생상품(위험회피수단은 별도표시)은 유동부채로 표시되었는지 확인한다. 파생상품자산과 파생상품부채는 K-IFRS 1032에서 허용하는 경우를 제외하고는 상계되지 않았음을 확인한다.
A35: (2)파생상품관련 손익은 손익계산서에서 적절한 항목으로 포함되고 있는지 손익은 K-IFRS 1001 문단35에서 허용하는 경우를 제외하고는 상계되지 않았음을 확인한다.
A36: 7. 파생상품 손익의 재계산 | J36: A, C
A37: 회사가 작성한 분석에 기초하여 파생상품의 기초와 기말 잔액 간의 변동을 파생상품 관련된 손익 계정과 대사한다. (신규 파생상품과 당기 중에 만기가 도래하였거나 청산된 파생상품을 고려)
A38: 8. 재무제표 공시의 적정성 검토(공시사항점검표 참조) | J38: C, CL, U,P
A39: 9. 감사결론의 기술
A42: Part 2. 추가 고려 절차
A43: 감사절차 | J43: 경영진 주장 | K43: 조서번호
A44: 1. 내재파생상품의 식별과 인식 | J44: C, CL
...

Sheet C
A1: 실 증 절 차
A2: (C. 매출채권(장단기))
A4: 회사명 | C4: =A!C4 -> 0 | F4: 작성자 | G4: =A!G4 -> 0 | I4: 일자
A5: 결산일 | C5: =A!C5 -> 0 | F5: 검토자 | G5: =A!G5 -> 0 | I5: 일자
A6: 경영진 주장 :
A7: A | B7: : 정확성(Accuracy) | D7: E | E7: : 실재성(Existence) | G7: RO | H7: : 권리와 의무(Rights and obligations)
A8: C | B8: : 완전성(Completeness) | D8: O | E8: : 발생사실(Occurrence) | G8: CL | H8: : 분류(Classification)
A9: CO | B9: : 기간귀속(Cutoff) | D9: V | E9: : 평가(Valuation) | G9: U | H9: : 이해가능성(Understandability)
A10: P | B10: : 표시(Presentation)
A11: ※ 업무요령 : 조서번호 2302 감사위험의 평가(경영진 주장 수준)에서 파악된 위험과 조서번호 3100 위험에 대한 대응에 기재된 실증절차에 맞게 실증절차를 수행한다.
A13: Part 1. 절차 예시
A14: 감사절차 | J14: 경영진 주장 | K14: 조서번호
A15: 1. 매출채권 총괄표 작성 | J15: E, C, CL
A16: 당기말잔액은 총계정원장과, 전기말잔액은 전기감사보고서와 각각 대조하고, 양년도간 특별한 변동사항은 그 원인을 규명한다.
A17: 2. 매출채권명세서 | J17: C, V
A18: (1) 거래처별 매출채권명세서를 입수하여 금액을 계산검증하고 보조부와 대조 확인한다.
A19: (2) 명세서를 스캔하여 유의적이거나 비경상적인 항목들을 검토한다.
A20: 3. 외상매출금 외부 조회 | J20: E, RO, V
A21: 외부 조회에 대한 구체적인 절차는 Audit Guide 3320 외부조회를 참고하고, 조회처 선정시 상세테스트의 방법은 Audit Guide 3300 감사증거 및 Audit Guide 3310 표본감사를 참고한다.
A22: 4. 매출채권 명세서를 검토하여 일반적 상거래 이외에서 발생된 채권의 포함여부를 조사하여 계정과목 재분류 여부를 결정하고, 장단기 구분의 적정성을 검토한다. | J22: V, CL
A23: 5. 매출채권의 회수가능성 및 대손충당금의 적정성 | J23: V, A
A24: (1) 거래처별로 연령분석표를 입수하여 검토한다.
A25: (2) 회수기간분석등 분석적검토를 실시한다.
A26: (3) 매출채권 회전율과 회수기일을 검토한다.
A27: (4) 매출채권의 회수가능성에 대하여 경영자와 토의한다.
A28: (5) 담보가 있는 경우 실재성, 소유권, 시가를 검증한다.
A29: (6) 합리적이고 객관적인 대손추계액 산정기준(개별적방법 또는 과거의 대손경험율에 의한 방법 등)에 의하여 대손충당금이 설정되어 있는지 확인하고, 당기의 대손상각 및 대손충당금 비율을 전기의 비율과 비교한다.
A30: 6. 보고기간종료일을 전후한 제품인도 및 용역제공이 해당기간에 적절히 반영되었는지를 검토한다. | J30: RO, V
A31: 7. 외화표시 매출채권의 환산내용을 검토한다. | J31: V, A
A32: 8. 특수관계자와의 거래 | J32: E, CL
A33: 특수관계자와의 거래에 대한 구체적인 절차는 Audit Guide 3500 특수관계자 거래를 참고한다.
A34: 9. 재무제표 공시사항 검토(공시사항점검표 참조) | J34: C, CL, U, P
A35: 10. 감사결론의 기술
A37: Part 2. 추가 고려 절차
A38: 감사절차 | J38: 경영진 주장 | K38: 조서번호
A39: 1. 받을어음의 실사 | J39: E, RO
A40: 보관중인 받을어음은 실사하고 타처보관중인 받을어음은 보관자에게 직접조회하거나 결산일후의 회수 상황을 확인한다.
A41: 2. 할인, 양도 및 담보제공 여부에 대한 검토 | J41: RO, CL
A42: (1) 매출채권중 할인했거나, 배서양도, 팩토링 및 담보제공한 금액에 대해서는 그 명세를 얻어서 K-IFRS 1109호상 제거조건을 충족하는지 검토하고 필요한 경우에는 조회서 등을 통하여 거래사실을 확인한다.
A43: (2) K-IFRS 1109호 상 제거요건을 충족하지 못하는 양도거래의 경우, 관련 자산 및 부채가 적절하게 계상되었는지 확인한다.
...

Sheet DL
A1: 실 증 절 차
A2: (DL.리스(KIFRS 1116호))
A4: 회 사 명 : | C4: 0 | F4: 작 성 자 : | G4: =A!G4 -> 0 | I4: 일 자 :
A5: 결 산 일 : | C5: 0 | F5: 검 토 자 : | G5: =A!G5 -> 0 | I5: 일 자 :
A6: 경영진 주장 :
A7: A | B7: : 정확성(Accuracy) | D7: E | E7: : 실재성(Existence) | G7: RO | H7: : 권리와 의무(Rights and obligations)
A8: C | B8: : 완전성(Completeness) | D8: O | E8: : 발생사실(Occurrence) | G8: CL | H8: : 분류(Classification)
A9: CO | B9: : 기간귀속(Cutoff) | D9: V | E9: : 평가(Valuation) | G9: U | H9: : 이해가능성(Understandability)
A10: P | B10: : 표시(Presentation)
A11: ※ 업무요령 : 조서번호 2302 감사위험의 평가(경영진 주장 수준)에서 파악된 위험과 조서번호 3100 위험에 대한 대응에 기재된 실증절차에 맞게 실증절차를 수행한다.
A13: Part 1. 절차 예시
A14: 감 사 절 차 | J14: 경영진 주장 | K14: 조서번호
A15: 1. 사용권자산과 리스부채 총괄표작성 및 증감표(명세서) 입수 | J15: E, C
A16: (1) 당기말잔액은 총계정원장과, 전기말잔액은 전기감사보고서와 각각 대조하고, 양년도간 특별한 변동사항은 그 원인을 규명한다.
A17: (2) 계약의 약정 시점에 계약 자체가 리스인지, 계약이 리스를 포함하는지 판단하는 경영진의 프로세스를 이해함. 또한 하나의 리스요소와, 하나이상의 추가 리스요소나 비리스요소를 포함하는 계약에서 경영진이 계약대가를 각 요소에 배분하는 방법을 이해한다.
A18: (3) 주요 계약조건이 기술되어있는 새로운 리스계약(별도 리스로 회계처리한 리스변경 포함)의 명세서를 입수, 명세서 금액을 계산검증하고 보조부와 대조 확인한다. 또 명세서를 스캔하여 유의적이거나 비경상적인 항목들을 검토한다.
A19: (4) 유의적인 계약과 약정에 대해 이해한 내용 및 주주총회 및 이사회의사록의 검토결과를 고려, 이전에 운용리스료를 인식하는데 사용했던 계정에 포함된 거래를 검토하여 리스계약(별도 리스로 회계처리한 리스변경 포함) 의 완전성을 확인한다.
A20: 2. 최초 인식 및 측정
A21: (1) 기존 계약중 중요한 리스계약 또는 새로운 리스를 테스트하여, 동 리스식별 및 리스기간의 결정, 인식 및 측정이 적절한지 검토한다
A22: 가. 리스기간 : 리스개시일 및 해지불능기간, 연장선택권 및 종료선택권의 대상기간 및 선택권 보유자에 대한 세부내역을 확인
A23: 나. 사용권자산 : 명세서상 인식된 총 사용권자산 금액 및 리스부채이외의 원가요소의 성격과 금액을 검토
A24: 다. 리스부채 - 총 고정리스료 및 변동리스료, 잔존가치보증에 따라 리스이용자가 지급할 것으로 예상되는 금 액 검토
A25: - 매수선택권을 행사할것이 상당히 확실한경우, 그 매수선택권의 행사가격 리스종료시 부담할 금액 그리고 사용된 할인율검토(내재이자율, 회사의 증분차입이자율, 현재가치 이자율)
A26: 라. 리스식별을 위한 여러 구성요소 검토 - 동시에 또는 가까운 시기에 체결한 계약들이 단일 계약으로 회계처리하기 위한 기준을 충족하였는 가?
A27: - 계약이 동일한 리스제공자와 동시에 또는 가까운 다른 시기에 다른계약으로 체결되었는가?
... A40: (3) 사용권자산에 대한 감사절차는 'F. 투자부동산 및 G. 유형자산 실증절차지시서 또는 H. 무형자산 실증절차지시서”에 기재된 감사절차를 준용하여 실시한다.
A41: 4. 재무제표 공시사항(공시사항 점검표 참조) | J41: C, CL, U,P
A42: 5. 감사결론의 기술
A45: Part 2. 추가감사절차
A47: * 감사인이 상기 감사절차예시 이외의 추가절차를 수행할 경우, 아래에 해당 내용을 기재한다.
A49: 감사절차 | J49: 경영진주장 | K49: 조서번호

Sheet D
A1: 실 증 절 차
A2: (D. 기타유동자산)
A4: 회사명 | C4: =A!C4 -> 0 | F4: 작성자 | G4: =A!G4 -> 0 | I4: 일자
A5: 결산일 | C5: =A!C5 -> 0 | F5: 검토자 | G5: =A!G5 -> 0 | I5: 일자
A6: 경영진 주장 :
A7: A | B7: : 정확성(Accuracy) | D7: E | E7: : 실재성(Existence) | G7: RO | H7: : 권리와 의무(Rights and obligations)
A8: C | B8: : 완전성(Completeness) | D8: O | E8: : 발생사실(Occurrence) | G8: CL | H8: : 분류(Classification)
A9: CO | B9: : 기간귀속(Cutoff) | D9: V | E9: : 평가(Valuation) | G9: U | H9: : 이해가능성(Understandability)
A10: P | B10: : 표시(Presentation)
A11: ※ 업무요령 : 조서번호 2302 감사위험의 평가(경영진 주장 수준)에서 파악된 위험과 조서번호 3100 위험에 대한 대응에 기재된 실증절차에 맞게 실증절차를 수행한다.
A13: Part 1. 절차 예시
A14: 감사절차 | J14: 경영진 주장 | K14: 조서번호
A15: 1. 기타유동자산 총괄표 작성 | J15: E, C, CL
A16: 당기말잔액은 총계정원장과, 전기말잔액은 전기감사보고서와 각각 대조하고, 양년도간 특별한 변동사항은 그 원인을 규명한다.
A17: 2. 기타유동자산 명세서 | J17: C, V
A18: 기타 유동자산 각 계정별 명세서를 입수하여 금액의 계산검증 및 보조부와 대조 확인한다.
A19: 3. 기타유동자산 외부조회 | J19: A, E, C, RO
A20: 주요 거래처에 대한 자산이 중요할 경우 외부 확인을 수행하며 외부 확인에 대한 구체적인 절차는 Audit Guide 3320 외부조회를 참고한다.
A21: 4. 중요한 항목 및 금액에 대하여 관련증빙을 대조확인한다. | J21: A, E, V
A22: 기타 유동자산 중 주요금액에 대하여는 관련 증빙서류와 대조하여 거래발생 및 금액의 타당성을 확인한다. 상세테스트의 방법은 Audit Guide 3300 감사증거 및 Audit Guide 3310 표본감사를 참고한다.
A23: 5. 기간계산에 의하여 인식되는 중요한 항목에 대하여는 기간계산의 적정성을 검증한다. | J23: C, CO
A24: 6. 회수가능성 및 대손충당금의 적정성 | J24: V
A25: 회수불능채권의 대손처리여부를 확인하고, 대손충당금의 설정이 적정한지의 여부와 전년과 동일한 기준의 적용여부를 검토한다.
A26: 7. 외화표시 자산의 환산내용을 검토한다. | J26: V, CL
A27: 8. 특수관계자와의 거래 | J27: E, CL
A28: 특수관계자와의 거래에 대한 구체적인 절차는 Audit Guide 3500 특수관계자 거래를 참고한다.
A29: 9. 재무제표 공시사항 검토(공시사항점검표 참조) | J29: C, CL U, P
A30: 10. 감사결론의 기술
A31: Part 2. 추가 고려 절차
A32: 감사절차 | J32: 경영진 주장 | K32: 조서번호
A33: 1. 선급비용 등에 대한 기간계산의 적정성 검증시에는 다음 사항을 고려한다. | J33: C, CO
A34: (1) 선급비용 등에 대한 계산시, 보험계약, 임대차계약 등 기간계산에 필요한 계약이 누락없이 포함되어 있는지 확인함.
A35: (2) 유의한 조정 항목이 존재하는 경우, 차이 조정에 대한 조사 결과는 적절한 담당자의 검토와 승인을 받았는지 여부를 확인하고, 중요성을 고려하여 중요 조정항목을 관련증빙과 대조확인함.
A36: (3) 선급비용 명세서를 스캔하고 유의적이거나 비경상적인 항목 또는 1년 이상 조정표 상에 남아있는 항목에 대해서 조사함.
A37: 2. 선물 등 파생상품거래유무 | J37: V, CL
A38: 선물 등의 거래유무를 확인하고 그 계약이나 매매에 의하여 발생된 자산, 부채의 처리내용과 동 거래로 인한 손익의 인식이나 처리가 적정한지를 ‘파생상품’과 연계하여 검토한다.
A39: 3. 각종 보험관련거래의 적정성 검토 | J39: E, RO
A40: 피감사회사로부터 보험가입현황을 입수하고, 동 내역의 적정성을 확인하기 위하여 보험증서 등의 증빙을 검토하거나 필요한 경우 외부조회를 실시한다.
A41: 4. 경영진측 및 감사인측 전문가 수행 업무의 평가 | J41: A, E, C,
A42: 감사증거로 사용될 정보가 경영진측 전문가가 수행한 업무의 도움으로 작성되거나 감사과정에서 감사인측 전문가가 수행한 업무를 활용하는 경우 Audit Guide 2131 전문가의 활용을 참조하여 평가한다. | J42: O, V
...

Sheet E
A1: 실 증 절 차
A2: (E. 재고자산)
A4: 회사명 | C4: =A!C4 -> 0 | F4: 작성자 | G4: =A!G4 -> 0 | I4: 일자
A5: 결산일 | C5: =A!C5 -> 0 | F5: 검토자 | G5: =A!G5 -> 0 | I5: 일자
A6: 경영진 주장 :
A7: A | B7: : 정확성(Accuracy) | D7: E | E7: : 실재성(Existence) | G7: RO | H7: : 권리와 의무(Rights and obligations)
A8: C | B8: : 완전성(Completeness) | D8: O | E8: : 발생사실(Occurrence) | G8: CL | H8: : 분류(Classification)
A9: CO | B9: : 기간귀속(Cutoff) | D9: V | E9: : 평가(Valuation) | G9: U | H9: : 이해가능성(Understandability)
A10: P | B10: : 표시(Presentation)
A11: ※ 업무요령 : 조서번호 2302 감사위험의 평가(경영진 주장 수준)에서 파악된 위험과 조서번호 3100 위험에 대한 대응에 기재된 실증절차에 맞게 실증절차를 수행한다.
A13: Part 1. 절차 예시
A14: 감사절차 | J14: 경영진 주장 | K14: 조서번호
A15: 1. 재고자산 총괄표의 작성 | J15: E, C, CL
A16: 당기말잔액은 총계정원장과, 전기말잔액은 전기감사보고서와 각각 대조하고, 양년도간 특별한 변동사항은 그 원인을 규명한다.
A17: 2. 재고자산수불부 검증 | J17: C, V
A18: (1) 재고자산수불부를 계산검증한다.
A19: (2) 재고자산수불부의 입출고와 재무상태표, 손익계산서, 제조원가명세서의 관련 계정과 연결한다.
A20: 3. 재고자산 실사 입회 추가 절차 | J20: E, RO, V
A21: (1) 재고자산 실사입회절차는 조서번호 E100. 재고자산실사입회를 참조한다.
A22: (2) 재고실사입회시 입수한 재고자산집계표와 재고자산수불부의 재고자산 수량을 연결한다. 상세테스트의 방법은 Audit Guide 3300 감사증거 및 Audit Guide 3310 표본감사를 참고한다.
A23: 4. 분석적 검토 | J23: E, C
A24: (1) 매출액 또는 총자산 대비 재고자산비율의 분석
A25: (2) 재고자산증감율의 분석
A26: (3) 매출수량, 생산수량, 매출원가에 대한 재고자산회전율의 분석
A27: 5. 재고자산의 단가 | J27: V, A
A28: (1) 외부로부터 구입한 재고의 단가일 경우, 재고수불부상의 단가를 구입증빙과 대사하고, 원가계산에 의해 산출된 단가일 경우 계산 검증한다.
A29: (2) 품목별 단위당 원가를 전기의 단가와 비교하고 중요한 변화가 있거나 비정상적인 재고단가변동에 대하여 조사한다.
A30: 6. 재고자산의 평가 | J30: V
A31: (1) 파손품, 진부화품, 장기체화재고 및 잉여재고에 대한 향후 판매계획, 생산계획을 확인하여 재고자산평가손실의 적절성을 검토한다.
A32: (2) 재고자산의 순실현가능가액에 대한 타당성을 검토하고, 장부금액이 순실현가능가액을 초과하는 경우 재고자산평가손실이 적절하게 반영되었는지 검토한다.
A33: 7. 재고자산 Cut-off | J33: CO
A34: (1) 결산일 전후 일정기간의 출고증, 판매지시서, 출하일보 및 입고증, 주문서, 검수보고서를 매입보조부와 대조 확인하여 Cut off test한다. 상세테스트의 방법은 Audit Guide 3300 감사증거 및 Audit Guide 3310 표본감사를 참고한다.
A35: 8. 특수관계자와의 거래 | J35: E, CL
A36: (1) 관계회사 등 특수관계인과의 거래유무를 파악하고 거래가격의 타당성(부당한 고가 또는 저가)을 파악한다.
A37: (2) 특수관계자와의 거래에 대한 구체적인 절차는 Audit Guide 3500 특수관계자 거래를 참고한다.
A38: 9. 미착품 명세에 미착부대비용이 적절히 계상되었는지 여부를 확인한다. | J38: RO, C
A39: 10. 담보제공 혹은 양도담보로 제공된 재고자산의 유무를 확인한다. | J39: RO
A40: 11. 재무제표 공시사항 검토(공시사항점검표 참조) | J40: C, CL U, P
A41: 12. 감사결론의 기술
A44: Part 2. 추가 고려 절차
...

Sheet E100
A1: 실 증 절 차
A2: (E100. 재고자산실사입회)
A4: 회사명 | C4: =A!C4 -> 0 | F4: 작성자 | G4: =A!G4 -> 0 | I4: 일자
A5: 결산일 | C5: =A!C5 -> 0 | F5: 검토자 | G5: =A!G5 -> 0 | I5: 일자
A6: 경영진 주장 :
A7: A | B7: : 정확성(Accuracy) | D7: E | E7: : 실재성(Existence) | G7: RO | H7: : 권리와 의무(Rights and obligations)
A8: C | B8: : 완전성(Completeness) | D8: O | E8: : 발생사실(Occurrence) | G8: CL | H8: : 분류(Classification)
A9: CO | B9: : 기간귀속(Cutoff) | D9: V | E9: : 평가(Valuation) | G9: U | H9: : 이해가능성(Understandability)
A10: P | B10: : 표시(Presentation)
A11: ※ 업무요령 : 조서번호 2302 감사위험의 평가(경영진 주장 수준)에서 파악된 위험과 조서번호 3100 위험에 대한 대응에 기재된 실증절차에 맞게 실증절차를 수행한다.
A13: Part 1. 절차 예시
A14: 감사절차 | J14: 경영진 주장 | K14: 조서번호
A15: 1. 구체적인 재고자산 실사입회절차는 Audit Guide 3301 감사증거-특정항목에 대한 구체적인 고려사항를 참조한다. | J15: E, V
A16: 2. 실행불가능한 경우를 제외하고, 회사의 재고실사 계획을 입수하고, 재고실사에 입회하여 다음 절차를 수행한다. | J16: E, V
A17: (1) 재고자산 실사의 결과를 기록하고 통제하기 위한 경영진의 지시와 절차를 평가한다.
A18: (2) 실사 전후 및 실사 중 재고자산의 이동에 대한 통제와 관련된 절차 등 경영진이 수행하는 실사절차에 대해 관찰한다.
A19: (3) 재고자산 실사 입회시 재고자산의 실재성을 확인하고 진부화되었거나 손상된, 또는 장기 보유 중인 재고자산을 식별하기 위하여 재고자산에 대하여 조사한다.
A20: (4) 테스트 실사시 경영진의 실사기록에서 선정된 항목을 실제의 재고로 추적하거나 실제의 재고에서 선정된 항목을 경영진의 실사기록으로 추적한다.
A21: 3. 재고자산의 최종 기록이 재고자산 실사의 결과를 정확하게 반영하고 있는지 여부를 결정하기 위해 재고자산의 최종 기록에 대한 다음의 감사절차를 수행한다. | J21: E
A22: (1) 감사인의 테스트 실사의 결과를 기록한다.
A23: (2) 경영진의 최종 실사기록 사본을 입수한다.
A24: 4. 재무제표일 외의 일자에 수행된 재고자산 실사 | J24: E
A25: (1) 재고자산 실사가 재무제표일이 아닌 일자에 수행될 경우, 실사일과 재무제표일 사이의 재고자산 변동이 정확하게 기록되었는지 확인한다.
A26: (2) 감사인이 예상하지 못한 상황으로 재고자산 실사에 입회할 수 없는 경우, 감사인은 다른 일자를 정하여 재고자산을 실사하거나 실사에 입회하여야 하며, 기업의 재고자산 실사일과 감사인의 실사 입회일 사이의 거래에 대한 감사절차를 수행하여야 한다.
A27: 5. 재고자산 실사의 입회가 실행가능하지 않는 경우 재고자산의 실사 이전에 취득하거나 매입한 특정의 재고자산 항목에 대해 이후의 매출과 관련된 서류를 조사하는 것과 같은 대체적인 감사절차를 수행하며, 대체적인 절차가 가능하지 않은 경우 감사의견을 변형한다. | J27: E
A28: 6. 제 3자가 보관, 통제하고 있는 재고자산이 재무제표에 중요한 경우 당해 제3자에게 외부확인을 요청하거나, 해당 상황에 적합한 조사 또는 기타의 감사절차를 수행한다. 외부 조회에 대한 구체적인 절차는 Audit Guide 3320 외부조회를 참고한다. | J28: E
A30: Part 2. 추가 고려 절차
A31: 감사절차 | J31: 감사목적 | K31: 조서번호
A32: 1. 다음의 경우에는 합리적 확신을 얻을 수 있을 때까지 표본규모를 확대하여 시사를 실시하거나 회사담당자로 하여금 재고실사를 다시 수행하도록 요구한 후 감사인의 시사를 재실시할 것을 고려하여야 한다. | J32: E
A33: (1) 재고자산수량의 적정성에 대한 합리적 확신을 얻을 수 없을 정도로 중요한 예외사항이 발견된 경우
A34: (2) 예외사항이 지나치게 많아서 재고실사의 전반적인 신뢰성에 대하여 합리적 확신을 얻을 수 없는 경우
A35: 2. 입회에 참여한 감사인은 재고실사입회에 대한 방법, 범위, 결과와 기말감사시 유의할 점 등을 기술한다. | J35: E
A36: 3. 유상사급 또는 무상사급거래 유무를 확인하고 동 거래와 관련된 재고를 회사가 보유하고 있는 경우 이에 대한 실사 시 회사가 재고자산에 대해 통제를 획득하였는지 여부를 판단하기 위해 관련 증빙(예: 구매계약서나 매입장 검토 등)을 확인하는 등 추가적인 감사절차 수행을 고려한다. | J36: O,E
A38: Part 3. 추가감사절차
A40: * 감사인이 상기 감사절차예시 이외의 추가절차를 수행할 경우, 아래에 해당 내용을 기재한다.
A42: 감사절차 | J42: 경영진주장 | K42: 조서번호

Sheet F
A1: 실 증 절 차
A2: (F. 투자부동산)
A4: 회사명 | C4: =A!C4 -> 0 | F4: 작성자 | G4: =A!G4 -> 0 | I4: 일자
A5: 결산일 | C5: =A!C5 -> 0 | F5: 검토자 | G5: =A!G5 -> 0 | I5: 일자
A6: 경영진 주장 :
A7: A | B7: : 정확성(Accuracy) | D7: E | E7: : 실재성(Existence) | G7: RO | H7: : 권리와 의무(Rights and obligations)
A8: C | B8: : 완전성(Completeness) | D8: O | E8: : 발생사실(Occurrence) | G8: CL | H8: : 분류(Classification)
A9: CO | B9: : 기간귀속(Cutoff) | D9: V | E9: : 평가(Valuation) | G9: U | H9: : 이해가능성(Understandability)
A10: P | B10: : 표시(Presentation)
A11: ※ 업무요령 : 조서번호 2302 감사위험의 평가(경영진 주장 수준)에서 파악된 위험과 조서번호 3100 위험에 대한 대응에 기재된 실증절차에 맞게 실증절차를 수행한다.
A13: Part 1. 절차 예시
A14: 감사절차 | J14: 경영진 주장 | K14: 조서번호
A15: 1. 투자부동산 총괄표의 작성(사용권자산 포함) | J15: E, C, CL
A16: 당기말 잔액은 총계정원장과 전기말잔액은 전기감사보고서와 각각 대조하고 양년도간에 특별한 변동사항이 있는 경우에는 그 원인을 규명한다.
A17: 2. 투자부동산산명세서 | J17: C, V
A18: 투자부동산산명세서를 입수하여 금액을 계산검증하고 잔액이 보조부와 일치하는지를 확인한다.
A19: 3.실재성확인 | J19: E, RO
A20: (1)중요한 항목은 직접 등기부등본 등을 확인하여 해당조서와 연결하며, 주주총회의사록, 이사회의사록, 보험계약서 등을 검토하여 이 계정으로 분류된 자산의 실재성을 검토하고 유치권, 저당권 및 담보제공의 존재여부를 검토한다.
A21: 4.투자부동산과 관련하여 발생한 임대수익, 처분손익등 관련손익계정이 적정하게 계상되었는가 확인한다. | J21: C, V, A
A22: 5.투자부동산에 대한 회계정책 이해와 평가 | J22: V, A
A23: 투자부동산에 대하여 원가모형을 적용하는지, 공정가치모형을 적용하는지 검토한다.
A24: 6.공정가치모형과 원가모형에 의한 평가의 적정성
A25: (1)공정가치 계산내역과 근거가 되는 기초자료를 검토하고 경영진에게 질문한다.
A26: (2)외부평가에 의해 공정가치를 측정하였다면 평가 대상 투자부동산의 소재 지역에서 최근에 유사한 부동산을 평가한 경험이 있고 전문적 자격이 있는 독립된 평가인의 가치평가에 기초하여 공정가치를 산정하였는지 검토한다.
A27: (3)공정가치를 신뢰성 있게 측정할 수 없어 원가모형이 적용되는 경우 측정의 신뢰성에 대하여 검토한다.
A28: (4)공정가치 평가에 대한 상세절차는 조서번호 EST 공정가치 등 회계추정치를 참조하고, 감사증거로 사용될 정보가 경영진측 전문가가 수행한 업무의 도움으로 작성되거나 감사과정에서 감사인측 전문가가 수행한 업무를 활용하는 경우 Audit Guide 2131 전문가의 활용을 참조하여 평가한다.
A29: 7. 재무제표 공시사항 검토(공시사항점검표 참조) | J29: C, CL, U, P
A30: 8. 감사결론의 기술
A33: Part 2. 추가 고려 절차
A34: 감사절차 | J34: 경영진 주장 | K34: 조서번호
A35: 1. 당기중 중요한 증감내용에 대해 계약서, 등기부등본 등 소유권 관련 문서 확인하고, 투자부동산 계정분류의 적정성 여부를 검토한다.
A36: 2. 유형자산 명세서 상의 부동산 중 임대수익 이나 시세차익을 얻기 위하여 보유하고 있는 부동산이 존재하는지 질문하고, 임대수익 등의 원장을 검토하여 유형자산 명세상의 부동산 중 임대수익 등과 관련된 부동산이 포함되어 있는지 확인한다. | J36: E,CL
A37: -해당 자산이 있는 경우 유형자산이 아닌 투자부동산으로 분류가 되어야 하는지 검토
A38: -해당 자산이 매각예정비유동자산인지 여부를 확인한다
A39: 3. 취득원가에 포함된 취득부대비용 등이 적절한지 확인한다. 취득 및 처분가격이 적정한가를 확인하여 손익계정과 연결한다. | J39: V
A40: 4. 투자부동산으로/에서 대체한 경우 사유가 적정한지, 대체시점의 회계처리가 적절한지 검토한다. | J40: CL
A42: Part 3. 추가감사절차
A44: * 감사인이 상기 감사절차예시 이외의 추가절차를 수행할 경우, 아래에 해당 내용을 기재한다.
A46: 감사절차 | J46: 경영진주장 | K46: 조서번호

Sheet G
A1: 실 증 절 차
A2: (G. 유형자산)
A4: 회사명 | C4: =A!C4 -> 0 | F4: 작성자 | G4: =A!G4 -> 0 | I4: 일자
A5: 결산일 | C5: =A!C5 -> 0 | F5: 검토자 | G5: =A!G5 -> 0 | I5: 일자
A6: 경영진 주장 :
A7: A | B7: : 정확성(Accuracy) | D7: E | E7: : 실재성(Existence) | G7: RO | H7: : 권리와 의무(Rights and obligations)
A8: C | B8: : 완전성(Completeness) | D8: O | E8: : 발생사실(Occurrence) | G8: CL | H8: : 분류(Classification)
A9: CO | B9: : 기간귀속(Cutoff) | D9: V | E9: : 평가(Valuation) | G9: U | H9: : 이해가능성(Understandability)
A10: P | B10: : 표시(Presentation)
A11: ※ 업무요령 : 조서번호 2302 감사위험의 평가(경영진 주장 수준)에서 파악된 위험과 조서번호 3100 위험에 대한 대응에 기재된 실증절차에 맞게 실증절차를 수행한다.
A13: Part 1. 절차 예시
A14: 감사절차 | J14: 경영진 주장 | K14: 조서번호
A15: 1. 유형자산(사용권자산을 유형자산으로 표시하는 경우 사용권자산 포함)총괄표 작성 | J15: E, C, CL
A16: 유형자산(사용권자산을 유형자산으로 표시하는 경우 사용권자산 포함) 장부가액의 변동내용을 나타내는 요약표를 입수하여 분석하고, 당기말 잔액은 총계정원장과 전기말잔액은 전기감사보고서와 각각 대조하고, 양년도간에 특별한 변동사항이 있는 경우에는 그 원인을 규명한다.
A17: 2. 유형자산명세서 | J17: C, V
A18: 유형자산명세서를 입수하여 명세서의 내용을 계산검증하고 유형자산대장등의 보조부와 대조확인한다.
A19: 3. 권리증서(등기부등본, 등록원부 등)를 획득하여 유형자산의 실재성과 소유권 및 담보제공 등의 소유권제한여부를 확인한다. | J19: E, RO
A20: 4. 유형자산처분명세서를 제시받아 처분가격 등의 적정성을 검토하고 처분손익 등 관련손익계정과 연결 | J20: A
A21: 5. 재평가모형으로 측정
A22: (1) 유형자산은 원가모형이나 재평가모형중 하나를 회계정책으로 선택하여 유형자산 분류별로 동일하게 적용하였는지 검토한다. | J22: V, A, C, CL
A23: (2) 최초 인식후에 공정가액을 신뢰성 있게 측정할 수 있는 유형자산은 재평가일의 공정가액에서 이후의 감가상각누계액과 손상차손누계액을 차감한 재평가금액을 장부가액으로 하였는지 검토한다.
A24: (3) 공정가액이 감정에 의해 결정된 경우, 감정이 전문적 자격이 있는 평가인에 의해 이루어졌는지 검토한다.
A25: (4) 재평가된 자산의 공정가액이 장부가액과 중요하게 차이가 나는 경우 재평가를 하였는지 검토한다.
A26: (5) 특정유형자산을 재평가할 때 해당자산이 포함되는 유형자산분류 전체를 재평가 하였는지 검토한다.
A27: (6) 유형자산의 장부가액이 재평가로 인하여 증가된 경우에 그 증가액은 기타포괄손익으로 인식하였는지 검토한다.
A28: (7) 유형자산의 재평가와 관련하여 인식한 기타포괄손익의 잔액이 있다면 그 유형자산을 폐기하거나 처분할 때 재분류조정이 제대로 이루어졌는지 검토한다.
A29: (8) 공정가치 평가에 대한 상세절차는 조서번호 EST 공정가치 등 회계추정치를 참조하고, 감사증거로 사용될 정보가 경영진측 전문가가 수행한 업무의 도움으로 작성되거나 감사과정에서 감사인측 전문가가 수행한 업무를 활용하는 경우 Audit Guide 2131 전문가의 활용을 참조하여 평가한다.
A30: 6. 건설중인 자산의 회계처리의 적정성 및 다음사항을 검토 | J30: A,V
A31: (1) 건설중인 자산에 대한 당기 지출액
A32: (2) 유형자산을 취득하기 위한 약정액
A33: (3) 건설중인 자산의 대체가 적절하게 회계처리 되었는지 검토
A34: (4) 차입원가 자본화 회계처리가 적절하게 이루어졌는지 다음사항을 검토 -적격자산여부, 자본화 대상기간, 자본화가능차입원가 산정(지출액적수, 이자율)
A35: 7. 손상차손 등 | J35: V, A
A36: (1) 사용중인 유형자산중 손상징후가 있다고 판단되는 경우 손상차손의 계상 및 회계처리의 적정성을 검토
A37: (2) 손상차손을 인식한 경우에는 손상을 초래한 상황의 변화나 내용, 손상차손의 평가에 사용된 회수가능가액의 산정방법과 그 금액을 확인
A38: 8. 특수관계자와의 거래 | J38: E, CL
A39: 특수관계자와의 거래에 대한 구체적인 절차는 Audit Guide 3500 특수관계자 거래를 참고한다.
A40: 9. 감가상각비명세서 징구 및 계상의 적정성 | J40: C, V, A
A41: (1) 감가상각비명세서를 징구하여 감가상각방법, 상각개시시점, 내용연수 또는 상각률의 계속적용여부 및 비용배부기준의 타당성을 검토
A42: (2) 신규취득자산에 적용하는 내용연수의 타당성을 검증
...

Sheet H
A1: 실 증 절 차
A2: (H. 무형자산)
A4: 회사명 | C4: =A!C4 -> 0 | F4: 작성자 | G4: =A!G4 -> 0 | I4: 일자
A5: 결산일 | C5: =A!C5 -> 0 | F5: 검토자 | G5: =A!G5 -> 0 | I5: 일자
A6: 경영진 주장 :
A7: A | B7: : 정확성(Accuracy) | D7: E | E7: : 실재성(Existence) | G7: RO | H7: : 권리와 의무(Rights and obligations)
A8: C | B8: : 완전성(Completeness) | D8: O | E8: : 발생사실(Occurrence) | G8: CL | H8: : 분류(Classification)
A9: CO | B9: : 기간귀속(Cutoff) | D9: V | E9: : 평가(Valuation) | G9: U | H9: : 이해가능성(Understandability)
A10: P | B10: : 표시(Presentation)
A11: ※ 업무요령 : 조서번호 2302 감사위험의 평가(경영진 주장 수준)에서 파악된 위험과 조서번호 3100 위험에 대한 대응에 기재된 실증절차에 맞게 실증절차를 수행한다.
A13: Part 1. 절차 예시
A14: 감사절차 | J14: 경영진 주장 | K14: 조서번호
A15: 1. 무형자산(사용권자산을 무형자산으로 표시하는 경우 사용권자산 포함)총괄표 작성 | J15: E, C, CL
A16: 무형자산(사용권자산을 무형자산으로 표시하는 경우 사용권자산 포함) 장부가액의 변동내용을 나타내는 요약표를 입수하여 분석하고, 당기말 잔액은 총계정원장과, 전기말잔액은 전기감사보고서와 각각 대조하고 양년도간에 특별한 변동사항이 있는 경우에는 그 원인을 규명한다.
A17: 2. 무형자산명세서 | J17: C, V
A18: 무형자산명세서를 입수하여 금액을 계산검증하고 잔액이 보조부와 일치하는지를 확인한다.
A19: 3. 등록증, 계약서 및 조회서등을 검토하여 소유권 및 소유권제한사항을 확인하고, 무형자산의 실재성에 대한 의문이 있을 경우, 변호사 또는 기술사용권자 및 상표권자에게 조회한다. | J19: RO
A20: 4. 무형자산처분명세서를 제시받아 처분가격 등의 적정성을 검토하고 처분손익등 관련손익계정과 연결시킨다. | J20: E, V, A
A21: 5. 무형자산상각비의 적정성 | J21: V, A
A22: (1) 상각비명세서를 징구하여 상각액 및 간접법의 경우 상각누계액 계상의 적정성과 상각방법, 내용연수 또는 상각률, 잔존가액의 계속적용여부 및 비용배부기준의 타당성을 검토한다.
A23: (2)상각완료된 자산이 사용되고 있는지 확인하여, 해당 자산의 상각률 또는 내용연수가 적절한지 검토한다.
A24: (3)비한정 내용연수의 무형자산의 경우 내용연수 타당성 검토한다.
A25: (4)후속적 지출이 자산인식 요건에 해당되는지 검토한다.
A26: (5)당기상각액이 손익계정별로 적절하게 계상되었는지 확인한다.
A27: (6) 내용연수가 20년을 초과하는 경우 그 근거(관계법령 또는 계약 등) 및 내용연수 결정에 고려한 중요 요소를 확인 한다.
A28: 6. 손상차손 등
A29: (1) 사용중인 무형자산중 손상징후가 있다고 판단되는 경우 손상차손의 계상 및 회계처리의 적정성을 검토
A30: (2) 손상차손을 인식한 경우에는 손상을 초래한 상황의 변화나 내용, 손상차손의 평가에 사용된 회수가능가액의 산정방법과 그 금액을 확인
A31: 7. 재무제표 공시사항 검토(공시사항점검표 참조) | J31: C, CL,U, P
A32: 8. 감사결론의 기술
A35: Part 2. 추가 고려 절차
A36: 감사절차 | J36: 경영진 주장 | K36: 조서번호
A37: 1. 무형자산에 대한 지출로서 과거 회계연도의 재무제표나 중간재무제표에서 비용으로 인식한 지출(즉, 무형자산의 인식기준충족시점 이전의 지출)이 그 후의 기간에 발생한 무형자산의 취득원가의 일부로 계상되었는지를 검토한다. 특히, 무형자산으로 인식한 개발비와 당기비용으로 인식한 연구비 및 경상개발비의 회계처리 적정성을 검토한다. | J37: V, CL
A38: 2. 차입원가 자본화 회계처리가 적절하게 이루어졌는지 다음사항을 검토 -적격자산여부, 자본화 대상기간, 자본화가능차입원가 산정(지출액적수, 이자율) | J38: A
A39: 3. 제약 바이오 업종의 개발비의 경우, 금융감독원의 [제약 바이오 기업의 연구개발비 회계처리 관련 감독지침 202209 및 제약·바이오 산업 주요 회계처리에 대한 감독지침 220924]에 따라 개발비가 적절히 자산화 되었는지 검토 | J39: A
A40: 4. 사업결합시 외부전문가의 공정가치평가 및 PPA보고서가 감사증거로서 충분하고 적합한지 확인 (전문가의 적격성, 가정/방법 이해, 산식오류 검토) | J40: V
A41: 5. 영업권과 염가매수차익의 회계처리의 적정성을 검토한다.(K-IFRS 1103 사업결합 참조) | J41: V
A42: 6. 정부보조금등 | J42: V, CL
A43: 정부보조금, 공사부담금 등에 의하여 무형자산을 무상 또는 공정가액보다 낮은 대가로 취득한 경우, 그 무형자산에 대한 취득원가 계상액, 이에 대한 회계처리 및 재무제표 표시의 적정성을 검토한다.
A45: Part 3. 추가감사절차
...

Sheet I
A1: 실 증 절 차
A2: (I. 기타비유동자산)
A4: 회사명 | C4: =A!C4 -> 0 | F4: 작성자 | G4: =A!G4 -> 0 | I4: 일자
A5: 결산일 | C5: =A!C5 -> 0 | F5: 검토자 | G5: =A!G5 -> 0 | I5: 일자
A6: A | B6: : 정확성(Accuracy) | D6: E | E6: : 실재성(Existence) | G6: RO | H6: : 권리와 의무(Rights and obligations)
A7: C | B7: : 완전성(Completeness) | D7: O | E7: : 발생사실(Occurrence) | G7: CL | H7: : 분류(Classification)
A8: CO | B8: : 기간귀속(Cutoff) | D8: V | E8: : 평가(Valuation) | G8: U | H8: : 이해가능성(Understandability)
A9: P | B9: : 표시(Presentation)
A10: ※ 업무요령 : 조서번호 2302 감사위험의 평가(경영진 주장 수준)에서 파악된 위험과 조서번호 3100 위험에 대한 대응에 기재된 실증절차에 맞게 실증절차를 수행한다.
A12: Part 1. 절차 예시
A13: 감사절차 | J13: 경영진 주장 | K13: 조서번호
A14: 1. 기타비유동자산 총괄표의 작성 | J14: E, C, CL
A15: 당기말잔액은 총계정원장과, 전기말잔액은 전기감사보고서와 각각 대조하고, 양년도간 특별한 변동사항은 그 원인을 규명한다.
A16: 2. 기타비유동자산명세서 | J16: C, V
A17: 기타비유동자산명세서를 입수하여 금액을 계산검증하고 잔액이 보조부와 일치하는지를 확인한다.
A18: 3. 기타비유동자산 외부확인 | J18: A, E, RO
A19: 주요 거래처에 대한 자산이 중요할 경우 외부 확인을 수행하며 외부 확인에 대한 구체적인 절차는 Audit Guide 3320 외부조회를 참고한다.
A20: 4. 중요한 항목 및 금액에 대하여 관련증빙을 대조확인한다. | J20: E, C, V
A21: 기타비유동자산 중 주요금액에 대하여는 관련 증빙서류와 대조하여 거래발생 및 금액의 타당성을 확인한다. 상세테스트의 방법은 Audit Guide 3300 감사증거 및 Audit Guide 3310 표본감사를 참고한다.
A22: 5. 기타비유동자산과 관련하여 발생한 손익계정이 적정하게 계상되었는가 확인한다. | J22: C, V, A
A23: 6. 회수가능성 | J23: V
A24: 회수불능자산의 대손처리 여부를 검토하고 대손충당금 설정의 타당성 및 계속성여부를 검토한다.
A25: 7. 현재가치에 의한 평가의 적정성 | J25: V, A
A26: 기타비유동자산 중 현재가치에 의한 평가사항이 있는 경우 동 평가액과 할인차금의 계산이 적정한지 검증하고, 관련손익계정에 반영되었는지 확인한다.
A27: 8. 특수관계자와의 거래 | J27: E, CL
A28: 특수관계자와의 거래에 대한 구체적인 절차는 Audit Guide 3500 특수관계자 거래를 참고한다.
A29: 9. 재무제표 공시사항의 적정성 검토(공시사항점검표 참조) | J29: C, CL, U, P
A30: 10. 감사결론의 기술
A32: Part 2. 추가 고려 절차
A33: 감사절차 | J33: 경영진 주장 | K33: 조서번호
A34: 1. 감사인측 및 경영진측 전문가 수행업무의 평가 | J34: A, E, C,
A35: 감사증거로 사용될 정보가 경영진측 전문가가 수행한 업무의 도움으로 작성되거나 감사과정에서 감사인측 전문가가 수행한 업무를 활용하는 경우 Audit Guide 2131 전문가의 활용을 참조하여 평가한다. | J35: O, V
A37: Part 3. 추가감사절차
A39: * 감사인이 상기 감사절차예시 이외의 추가절차를 수행할 경우, 아래에 해당 내용을 기재한다.
A41: 감사절차 | J41: 경영진주장 | K41: 조서번호

Sheet J
A1: 실 증 절 차
A2: (J. 자산손상)
A4: 회사명 | C4: =A!C4 -> 0 | F4: 작성자 | G4: =A!G4 -> 0 | I4: 일자
A5: 결산일 | C5: =A!C5 -> 0 | F5: 검토자 | G5: =A!G5 -> 0 | I5: 일자
A6: 경영진 주장 :
A7: A | B7: : 정확성(Accuracy) | D7: E | E7: : 실재성(Existence) | G7: RO | H7: : 권리와 의무(Rights and obligations)
A8: C | B8: : 완전성(Completeness) | D8: O | E8: : 발생사실(Occurrence) | G8: CL | H8: : 분류(Classification)
A9: CO | B9: : 기간귀속(Cutoff) | D9: V | E9: : 평가(Valuation) | G9: U | H9: : 이해가능성(Understandability)
A10: P | B10: : 표시(Presentation)
A11: ※ 업무요령 : 조서번호 2302 감사위험의 평가(경영진 주장 수준)에서 파악된 위험과 조서번호 3100 위험에 대한 대응에 기재된 실증절차에 맞게 실증절차를 수행한다.
A13: Part 1. 절차 예시
A14: 감사절차 | J14: 경영진 주장 | K14: 조서번호
A15: 1. 손상대상자산의 완전성 검토 | J15: E, O, V
A16: 손상징후 여부에 관계없이 손상검사대상 자산이 존재하는지 검토한다.
A17: 개별자산 또는 현금창출단위에 손상검사대상자산이 모두 포함되는지 검토한다.
A18: 2. 손상징후 검토 | J18: E, O, V
A19: 매 보고기간말마다 자산손상을 시사하는 징후가 있는지 외부정보 및 내부정보를 검토한다.
A20: 손상을 시사하는 외부정보와 내부정보를 회사가 충분히 고려하였는지 검토한다.
A21: 3. 현금창출단위 식별의 적정성
A22: (1) 경영진이 구분한 현금창출단위의 적정성을 검토한다.
A23: (2) 현금창출단위가 변경되는 경우 그 사유에 대하여 검토한다.
A24: 4. 영업권의 현금창출단위로의 배분의 적정성 | J24: V, A
A25: (1) 영업권이 취득일부터 현금창출단위에 배분되었는지 확인한다.
A26: (2)영업권이 배분되는 각 현금창출단위가 영업권을 감독하는 기업 내 최저수준이어야 하며 K-IFRS 1108 '영업부문'에 따라 정의되는 통합전 영업부문보다 크지 않은지 검토한다.
A27: (3) 영업권의 최초 배분이 취득일 후 최초로 개시하는 회계연도 말까지 완료되었는지 검토한다.
A28: 5. 회수가능액 측정의 적정성 | J28: V, A
A29: (1) (순공정가치 산정)구속력 있는 매매계약이 있거나 활성시장의 존재 여부를 확인한다.
A30: (2) (순공정가치 산정)구속력 있는 매매계약이 없거나 활성시장이 존재하지 않는 경우 이용가능한 최선의 정보의 적정성을 검토한다.
A31: (3) (사용가치 산정)사용가치 산정을 위하여 사용한 사업계획의 경영진(이사회) 승인받은 최근의 재무예산과 일치하는지 대사확인 및 과거 사업계획의 소급적검토
A32: (4) (사용가치 산정)외부전문가의 공정가치평가가 감사증거로서 충분하고 적합한지 확인 (전문가의 적격성, 가정/방법 이해, 산식오류 검토)
A33: - 매출(or 영업현금흐름, EBIT)성장율과 관련하여 이용가능한 외부기관 시장추정치 상의 성장율과 비교, 차이가 있다면 근거의 합리성 검토
A34: - 영구성장율 및 할인율 적정성 검토
A35: 6. 손상차손 환입의 적정성 | J35: V, A
A36: 매 보고기간말마다 영업권을 제외한 자산에 대해 과거에 인식한 손상차손이 더 이상 존재하지 않거나 감소된 것을 시사하는 징후가 있는지를 검토한다.
A37: 7. 손상차손을 인식하지 않은 경우에 다른 K-IFRS에 따른 검토 대상 확인 | J37: E, O, V
A38: 자산손상을 시사하는 징후가 있다면 잔여내용연수, 감가상각방법 또는 잔존가치를 검토하여 조정할 필요가 있는지 검토한다.
A39: 8. 재무제표 공시 사항의 적정성 검토(공시사항점검표 참조) | J39: C, CL, U, P
A40: 9. 감사결론의 기술
A41: Part 2. 추가 고려 절차
A42: 감사절차 | J42: 경영진 주장 | K42: 조서번호
...

Sheet AA
A1: 실 증 절 차
A2: (AA. 매입채무(장단기))
A4: 회사명 | C4: =A!C4 -> 0 | F4: 작성자 | G4: =A!G4 -> 0 | I4: 일자
A5: 결산일 | C5: =A!C5 -> 0 | F5: 검토자 | G5: =A!G5 -> 0 | I5: 일자
A6: 경영진 주장 :
A7: A | B7: : 정확성(Accuracy) | D7: E | E7: : 실재성(Existence) | G7: RO | H7: : 권리와 의무(Rights and obligations)
A8: C | B8: : 완전성(Completeness) | D8: O | E8: : 발생사실(Occurrence) | G8: CL | H8: : 분류(Classification)
A9: CO | B9: : 기간귀속(Cutoff) | D9: V | E9: : 평가(Valuation) | G9: U | H9: : 이해가능성(Understandability)
A10: P | B10: : 표시(Presentation)
A11: ※ 업무요령 : 조서번호 2302 감사위험의 평가(경영진 주장 수준)에서 파악된 위험과 조서번호 3100 위험에 대한 대응에 기재된 실증절차에 맞게 실증절차를 수행한다.
A13: Part 1. 절차 예시
A14: 감사절차 | J14: 경영진주장 | K14: 조서번호
A15: 1. 매입채무 총괄표 작성 | J15: E, C, CL
A16: 당기말잔액은 총계정원장과 전기말잔액은 전기감사보고서와 대조하고 양년도간 특별한 변동이유를 규명한다.
A17: 2. 매입채무명세서를 받아 다음 절차를 수행한다. | J17: C, V
A18: (1) 계산검증을 하고, 매입처별 보조부와 대조하고 동 잔액들이 최근의 청구서 등에 근거하여 계상되었는가를 확인한다.
A19: (2) 지급어음명세를 검토하여 정상적인 영업활동 이외의 거래에서 발생된 어음의 포함여부를 조사하여 계정과목 재분류를 검토하고, 장단기구분의 적정성을 검토한다.
A20: 3. 분석적 절차 | J20: C, V
A21: (1) 매입채무명세를 전년도와 비교하고 예측하지 못한 변동이 있는지(예를 들면 주요 공급자, 차변잔액 구성비율 및 계정잔액 경과일수의 변동) 또는 반대로 예측되는 변동이 일어나지 않은 이유 등을 조사한다.
A22: (2) 당기 매입액 및 평균 매입채무를 기초로 하여 회전율 및 지급기간을 예측산정하여 회사의 지급기간과 비교확인하고, 감사인의 예상과 다른 경우 추가적인 원인을 분석한다.
A23: (3) 지급어음, 기업구매카드, 구매자금대출에 대한 평균잔액에 평균이자율을 곱하여 이자비용의 적정성을 테스트한다.
A24: 4. 외부 조회에 대한 구체적인 절차는 Audit Guide 3320 외부조회를 참고한다. | J24: E, RO, C
A25: 5. 보고기간종료일 이후 지급된 매입채무 | J25: E, RO, C
A26: (1) 결산일 전후 일정기간의 매입채무지급액 및 송장, 검수보고서를 추적 검토하여 기간귀속(Cut-off)의 적정성을 확인한다.
A27: (2) 마감일 전후의 매입채무기록, 입고기록, 공급자계산서 및 기타 증빙이 적절한지 테스트하고, 매입채무의 기간귀속을 관련되는 계정(재고자산등)의 기간귀속과 비교한다.
A28: (3) 미착품으로 계상된 재고와 관련하여 소유권의 이전시점(도착지 또는 선적지 인도기준등)에 따라 적절히 매입채무로 계상되고 있는지 검토한다.
A29: 6. 재무제표 표시사항의 적정성 검토 | J29: CL, P
A30: (1) 재고자산구매에서 발생하지 아니한 채무의 재분류
A31: (2) 1년 이후 지급될 금액의 재분류(예：장기성 매입채무)
A32: (3) 결산일후 행해진 주요수정사항을 검토
A33: (4) 기업구매카드 및 기업구매자금대출제도에 의한 매입시 계정분류의 적정성을 확인한다(기업구매지금대출시 판매기업이 환어음을 결제하기 전까지는 매입채무로, 환어음을 결제한 후에는 단기차입금으로 회계처리함).
A34: (5) 회사의 공급자에 대한 채무(매입채무, 기업구매카드 등)에 대하여 제공한 공급자 금융약정 공시내용을 검토
A35: 7. 재무제표 공시 사항의 적정성 검토(공시사항점검표 참조) | J35: C, CL, U, P
A36: 8. 감사결론의 기술
A39: Part 2. 추가 고려 절차
A40: 감사절차 | J40: 경영진주장 | K40: 조서번호
A41: 1. 조회 시 유의사항
A42: (1) 과소계상된 매입채무를 적발하기 위하여는 비경상적인 소액거래처를 표본으로 추출하여 조회서를 발송한다. 특히, 전기대비 매입채무가 크게 감소한 매입처에 대해 집중적으로 조회한다.
A43: (2) 채권자에 대한 조회, 이사회의사록과 기타서류의 검토 등을 통하여 매입채무에 대한 담보권 및 담보로 제공된 자산을 확인한다.
A44: (3) 금융기관조회서 검토시 Usance 거래 및 기업구매카드, 기업구매자금대출에 대한 장부상 부채계상을 확인한다.
...

Sheet BBDD
A1: 실 증 절 차
A2: (BB.DD. 장단기차입금,사채)
A4: 회사명 | C4: =A!C4 -> 0 | F4: 작성자 | G4: =A!G4 -> 0 | I4: 일자
A5: 결산일 | C5: =A!C5 -> 0 | F5: 검토자 | G5: =A!G5 -> 0 | I5: 일자
A6: 경영진 주장 :
A7: A | B7: : 정확성(Accuracy) | D7: E | E7: : 실재성(Existence) | G7: RO | H7: : 권리와 의무(Rights and obligations)
A8: C | B8: : 완전성(Completeness) | D8: O | E8: : 발생사실(Occurrence) | G8: CL | H8: : 분류(Classification)
A9: CO | B9: : 기간귀속(Cutoff) | D9: V | E9: : 평가(Valuation) | G9: U | H9: : 이해가능성(Understandability)
A10: P | B10: : 표시(Presentation)
A11: ※ 업무요령 : 조서번호 2302 감사위험의 평가(경영진 주장 수준)에서 파악된 위험과 조서번호 3100 위험에 대한 대응에 기재된 실증절차에 맞게 실증절차를 수행한다.
A13: Part 1. 절차 예시
A14: 감사절차 | J14: 경영진 주장 | K14: 조서번호
A15: 1. 장단기차입금 및 사채 총괄표의 작성 | J15: E, C, CL
A16: 당기말 잔액은 총계정원장과 전기말 잔액은 전기감사보고서와 대조하고 양년도간 특별한 변동이유를 규명한다.
A17: 2. 장단기차입금 및 사채 명세서 | J17: C, V
A18: (1) 명세서를 입수하여 금액을 계산검증하고 잔액이 보조부와 일치하는지를 확인한다.
A19: (2) 신규 사채발행내역을 유가증권신고서 등을 통하여 확인한다.
A20: 3. 외부 조회에 대한 구체적인 절차는 Audit Guide 3320 외부조회를 참고한다. | J20: E, RO, C, A
A21: 4. 차입계약서 상의 주요 계약사항의 준수 여부를 확인한다. | J21: RO, CL
A22: 5. 중요한 증감거래에 대하여 입출금거래를 확인하고, 피감사회사가 실제로 회계연도중에 상환한 금액과 비교한다. | J22: E, C
A23: 6. 은행조회서 상의 최종이자지급일을 확인하여 미지급(선급)이자 계산을 확인하고, 미지급비용명세 또는 선급비용명세와 연결한다. | J23: C, V, A
A24: 7. 차입금 평균금액과 이자율을 이용하여 이자비용에 대한 Overall Test를 실시한다. 이때 약정이자율에 대한 신뢰성을 검토하여야 한다. | J24: C, A
A25: 8. 연불수입조건으로써 Banker's Usance 잔액이 조회될 경우 단기차입금 계상의 적정성을 검토한다.(이자는 금융비용임) | J25: C, CL
A26: 9. 재무제표 표시사항 검토 | J26: CL, P
A27: (1) 단기차입금에 당좌차월, 어음상의 채무 포함여부를 확인
A28: (2) 1년 이후에 상환될 차입금은 장기채무로 재분류(상환계획서, 은행조회서, 기재사항 대조)
A29: (3) 장기채무중 1년이내에 상환될 차입금은 유동성장기부채로 재분류
A30: (4) 보고기간종료일로부터 1년 이내에 상환되어야 하는 채무는, 보고기간종료일과 재무제표가 사실상 확정된 날 사이에 보고기간종료일로부터 1년을 초과하여 상환하기로 합의하더라도 유동부채로 분류(K-IFRS 1001 문단 74 참조)
A31: (5) 기업이 보고기간말 현재 기존의 대출계약조건에 따라 보고기간 후 적어도 12개월 이상 부채를 연장할 권리가 있다면, 보고기간 후 12개월 이내에 만기가 도래한다 하더라도 비유동부채로 분류한다. 만약 기업에 그러한 권리가 없다면, 차환가능성을 고려하지 않고 유동부채로 분류(K-IFRS 1001 문단 73 참조)
A32: (6) 보고기간 후 적어도 12개월 이상 부채의 결제를 연기할 수 있는 기업의 권리는 기업이 차입 약정 상의 특정 조건(이하 ‘약정사항’)을 준수하는지 여부에 좌우될 수 있다 ⑴ K-IFRS 1001 문단 74~75의 예시와 같이 만약 기업이 보고기간말 또는 보고기간말 이전에 약정사항을 준수하도록 요구받는다면, 이러한 약정사항은 K-IFRS 1001 문단 69⑷를 적용할 때 보고기간말 현재 그러한 권리가 존재하는지 여부에 영향을 미친다. 비록 약정사항의 준수 여부가 보고기간 후에만 평가되더라도(예: 약정사항은 보고기간말 현재 기업의 재무상태를 기초로 하지만, 약정의 준수 여부는 보고기간 후에만 평가되는 경우), 이러한 약정사항은 보고기간말 현재 그러한 권리가 존재하는지 여부에 영향을 미친다. ⑵ 만약 기업이 보고기간 후에만 약정사항을 준수하도록 요구받는다면(예: 기업의 보고기간말 6개월 후 재무상태에 기초한 약정사항), 이러한 약정사항은 K-IFRS 1001 문단 69⑷를 적용할 때 보고기간말 현재 그러한 권리가 존재하는지 여부에 영향을 미치지 않는다. (K-IFRS 1001 문단 72B 참조)
A33: (7) 사채할인차금은 사채에서 차감하는 형식으로 기재
A34: (8) 전환증권의 경우 상환할증금, 할인할증발행차금, 전환권 등 조정을 액면가액에 가감하는 형식으로 표시
A35: 10. 주주총회 또는 이사회 의사록, 계약서, 금융기관조회서 또는 기타 서류를 검토하여 고정부채에 대한 승인 및 신용한도의 유무를 확인한다. | J35: C, CL
A36: 11. 재무제표 공시사항의 적정성 검토(공시사항점검표 참조) | J36: C, CL, U, P
A37: 12. 감사결론의 기술
A40: Part 2. 추가 고려 절차
A41: 감사절차 | J41: 경영진 주장 | K41: 조서번호
A42: 1. 조회 시 유의사항 | J42: E, RO, C, A
A43: (1) 은행, 보험회사, 종금사 등 채권자에 직접조회하여 기말잔액, 상환기한, 이자율, 최종이자지급일, 담보내용 주요차입조건 등을 확인(중도상환은행 포함)
A44: (2) 조회서의 회신금액과 은행연합회 제공 여수신현황표와 대사 확인한다.
...

Sheet CC
A1: 실 증 절 차
A2: (CC. 기타유동부채)
A4: 회사명 | C4: =A!C4 -> 0 | F4: 작성자 | G4: =A!G4 -> 0 | I4: 일자
A5: 결산일 | C5: =A!C5 -> 0 | F5: 검토자 | G5: =A!G5 -> 0 | I5: 일자
A6: 경영진 주장 :
A7: A | B7: : 정확성(Accuracy) | D7: E | E7: : 실재성(Existence) | G7: RO | H7: : 권리와 의무(Rights and obligations)
A8: C | B8: : 완전성(Completeness) | D8: O | E8: : 발생사실(Occurrence) | G8: CL | H8: : 분류(Classification)
A9: CO | B9: : 기간귀속(Cutoff) | D9: V | E9: : 평가(Valuation) | G9: U | H9: : 이해가능성(Understandability)
A10: P | B10: : 표시(Presentation)
A11: ※ 업무요령 : 조서번호 2302 감사위험의 평가(경영진 주장 수준)에서 파악된 위험과 조서번호 3100 위험에 대한 대응에 기재된 실증절차에 맞게 실증절차를 수행한다.
A13: Part 1. 절차 예시
A14: 감사절차 | J14: 경영진 주장 | K14: 조서번호
A15: 1. 기타유동부채의 총괄표 작성 | J15: E, C, CL
A16: 당기말잔액은 총계정원장과, 전기말잔액은 전기감사보고서와 각각 대조하고, 양년도간 특별한 변동사항은 그 원인을 규명한다.
A17: 2. 기타유동부채 명세서 | J17: E, RO, V
A18: (1) 계정별로 거래처, 거래내용, 계산근거, 기말잔액이 표시된 명세서를 입수하여 금액을 계산검증하고 보조부와 대조 확인한다.
A19: (2) 기초와 기말의 내역을 비교하고 회계처리의 계속성을 확인한다.
A20: (3) 명세서를 스캔하여 유의적이거나 비경상적인 항목들을 검토한다.
A21: 3. 기타유동부채 외부 조회 | J21: A, E, C, RO
A22: 주요 거래처에 대한 채무가 중요할 경우 외부 확인을 수행하며 외부 확인에 대한 구체적인 절차는 Audit Guide 3320 외부조회를 참고한다.
A23: 4. 중요한 항목 및 금액에 대하여 관련증빙을 대조확인한다. | J23: A, E, V
A24: 기타 유동부채 중 주요금액에 대하여는 관련 증빙서류와 대조하여 거래발생 및 금액의 타당성을 확인한다. 상세테스트의 방법은 Audit Guide 3300 감사증거 및 Audit Guide 3310 표본감사를 참고한다.
A25: 5. 미지급계상의 완전성 검토 | J25: C, CO
A26: 손익계산서 및 제조원가명세서 상의 비용항목을 검토하여 미지급계상의 완전성을 확인한다.
A27: 6. 보고기간종료일 이후에 지급된 금액 검토 | J27: C, CO
A28: 보고기간종료일 이후 지급된 금액을 조사하여 당기에 제공받은 용역과 관련된 지급에 대하여 해당기간에 적절히 부채로 계상되었는지를 확인한다.
A29: 7. 외화표시 채무의 환산내용을 검토한다. | J29: V, CL
A30: 8. 재무제표 표시사항의 적정성 검토 | J30: CL, U, P
A31: (1) 가수금 등의 미결산 항목은 그 성질을 나타내는 적절한 과목으로 표시
A32: (2) 기타의 유동부채 중 그 성질이나 금액이 중요한 경우 구분 기재
A33: (3) 기타유동부채중 1년 이후에 지급될 금액을 재분류
A34: 9. 특수관계자와의 거래 | J34: E, CL
A35: 특수관계자와의 거래에 대한 구체적인 절차는 Audit Guide 3500 특수관계자 거래를 참고한다.
A36: 10. 재무제표 공시사항의 적정성 검토(공시사항점검표 참조) | J36: C, CL, U, P
A37: 11. 감사결론의 기술
A40: Part 2. 추가 고려 절차
A41: 감사절차 | J41: 경영진 주장 | K41: 조서번호
A42: 1. 장기 미처리거래에 대한 확인 | J42: E, V
A43: 장기 미처리거래가 존재할 경우 이유를 규명하고 적절한 회계처리를 유도
A44: 2. 감사인측 및 경영진측 전문가 수행업무의 평가 | J44: A, E, C,
...

Sheet EE
A1: 실 증 절 차
A2: (EE. 퇴직급여부채, 급여)
A4: 회사명 | C4: =A!C4 -> 0 | F4: 작성자 | G4: =A!G4 -> 0 | I4: 일자
A5: 결산일 | C5: =A!C5 -> 0 | F5: 검토자 | G5: =A!G5 -> 0 | I5: 일자
A6: 경영진 주장 :
A7: A | B7: : 정확성(Accuracy) | D7: E | E7: : 실재성(Existence) | G7: RO | H7: : 권리와 의무(Rights and obligations)
A8: C | B8: : 완전성(Completeness) | D8: O | E8: : 발생사실(Occurrence) | G8: CL | H8: : 분류(Classification)
A9: CO | B9: : 기간귀속(Cutoff) | D9: V | E9: : 평가(Valuation) | G9: U | H9: : 이해가능성(Understandability)
A10: P | B10: : 표시(Presentation)
A11: ※ 업무요령 : 조서번호 2302 감사위험의 평가(경영진 주장 수준)에서 파악된 위험과 조서번호 3100 위험에 대한 대응에 기재된 실증절차에 맞게 실증절차를 수행한다.
A13: Part 1. 절차 예시
A14: 감사절차 | J14: 경영진 주장 | K14: 조서번호
A15: 1.퇴직급여부채의 총괄표 작성 | J15: E, C, CL
A16: 총괄표를 입수하여 다음을 수행한다.
A17: (1)총괄표를 총계정원장 및 전기 감사조서와 대사한다.
A18: (2)총괄표의 산술적 정확성을 검토한다.
A19: 2.퇴직급여 및 기타장기종업원급여의 파악
A20: 다음의 절차를 수행하여 기업의 퇴직급여제도와 기타장기종업원급여를 파악한다.
A21: (1)급여 지급에 대한 법적 의무를 확인하기 위해서 경영진에게 질의하고 각각의 관련 법률이나 기업의 문서(예: 노동조합 협약서)를 검토한다.
A22: (2)퇴직연금 및 기타급여를 비공식적으로 지급하는 반복적인 관행이 있는지에 대해서 경영진에게 질의한다. 만약 있다면, 퇴직연금을 지급하는 기업의 비공식적 관행이 의제의무를 발생시키는지 여부를 평가한다. | J22: E, C, RO
A23: (3)제도에 대한 요약 설명자료, 내부적인 규약 및 노동조합계약서와 같은 이용가능한 정보를 검토하고 문서화된 조건과 상이한 조건으로 급여를 지급하는 비공식적 관행에 대해서 경영진 및 가능하다면 연금제도관리인이나 보험자에게 질의한다하여 비공식적인 관행을 포함한 각 제도의 조건들을 이해한다.
A24: 3.퇴직급여제도의 분류를 검토
A25: 퇴직급여제도의 주요한 조건에서 도출된 경제적 실질에 기초하여, 제도의 분류가 확정기여형 제도인지 또는 확정급여형 제도인지 평가한다. | J25: CL, U
A26: 4.확정급여제도의 보험계리인의 보고서 검토
A27: 회사의 보험수리적 평가에 대한 원본 자료를 입수하여 다음의 절차를 수행한다.
A28: (1)재무제표의 인식된 금액이 보고기간말에 결정될 금액과 중요한 차이가 나지 않을 정도의 주기를 두고 공정가치 평가가 수행되었는지 여부를 평가한다.
A29: (2)보험계리인의 평가가 보고기간 말 전에 수행되었다면 평가보고서상의 금액과 재무상태표에 인식된 금액 간의 차이 조정내역을 입수하여 검토한다. | J29: A, V
A30: (3)보험계리인의 보고서를 검토하여 퇴직급여제도의 모든 정확한 조건, 관련된 요소, 또는 조건의 변경이 적절하게 반영되었는지 여부를 확인하고 예측단위적립방식이 적용되었는지 검토한다.
A31: (4)확정급여제도를 위한 기금이 적립되었다면, 사외적립자산 수탁자의 보고서 원본이나 사외적립자산에 대한 그 밖의 목록을 입수하여 다음을 수행한다.
A32: ①목록의 산술적 정확성을 검토하고 합계금액을 총계정원장이나 재무제표의 공시사항과 직접 대사하여 확인한다.
A33: ②사외적립자산을 수탁자(또는 다른 실체)가 보유하고 있는 조건에 대한 설명을 입수하고 해당자산이 사외적립자산의 정의를 충족하는지 평가한다.
A34: ③기업이 기금에 납부하여야 하는 미지급기여금과 기업이 발행한 양도불가능한 금융상품은 사외적립자산에서 제외되었음을 검토한다.
A35: ④종업원급여와 관계없는 기금부채, 신탁자산 또는 기업이 보유하는 그밖의 사외적립자산이 있다면 이는 사외적립자산에서 차감되었는지 확인한다(예: 매입채무 및 파생상품관련부채 등)
A36: (5)사외적립자산이 공정가치로 측정되었는지 확인한다.
A37: (6)보험계리인이 적용한 할인율 및 기타 재무적 정보(미래 임금상승률 등)의 적정성을 검토한다.
A38: (7)다음과 같이 보고서 상의 정보를 총계정원장과 대사한다.
A39: ①합계금액을 퇴직연금 및 그 밖의 종업원급여 계정잔액에 대한 비교표시된 요약자료와 대사한다.
A40: ②산술적 정확성을 검토한다.
A41: ③질문과 조사를 통해서 비교표시된 요약자료와 보험수리보고서 간의 조정항목이 적절한지 판단한다.
... A44: 5확정기여제도에 대한 회계처리를 검토한다.
...

Sheet FF
A1: 실 증 절 차
A2: (FF. 제충당부채)
A4: 회사명 | C4: =A!C4 -> 0 | F4: 작성자 | G4: =A!G4 -> 0 | I4: 일자
A5: 결산일 | C5: =A!C5 -> 0 | F5: 검토자 | G5: =A!G5 -> 0 | I5: 일자
A6: 경영진 주장 :
A7: A | B7: : 정확성(Accuracy) | D7: E | E7: : 실재성(Existence) | G7: RO | H7: : 권리와 의무(Rights and obligations)
A8: C | B8: : 완전성(Completeness) | D8: O | E8: : 발생사실(Occurrence) | G8: CL | H8: : 분류(Classification)
A9: CO | B9: : 기간귀속(Cutoff) | D9: V | E9: : 평가(Valuation) | G9: U | H9: : 이해가능성(Understandability)
A10: P | B10: : 표시(Presentation)
A11: ※ 업무요령 : 조서번호 2302 감사위험의 평가(경영진 주장 수준)에서 파악된 위험과 조서번호 3100 위험에 대한 대응에 기재된 실증절차에 맞게 실증절차를 수행한다.
A13: Part 1. 절차 예시
A14: 감사절차 | J14: 경영진 주장 | K14: 조서번호
A15: 1. 제충당부채 총괄표 작성 | J15: E, C, CL
A16: 당기말 잔액은 총계정원장과 전기말잔액은 전기감사보고서와 각각 대조하고 양년도간에 특별한 변동사항이 있는 경우에는 그 원인을 규명한다.
A17: 2. 제충당부채 명세서 | J17: C, A
A18: 제충당부채 명세서를 입수하여 금액을 계산검증하고 잔액이 보조부와 일치하는지를 확인한다.
A19: 3. 제충당부채 변경 내역에 대한 검토 | J19: C, E, RO
A20: (1) 충당부채의 전체 또는 일부의 사용에 대해서 사용된 금액은 의무의 이행과 대응되는지 확인하기 위하여, 관련 증빙 문서 검토, 관련된 비용과의 대사, 지출된 비용이 당초 충당부채에서 사용되었음을 회사의 회계기록에서 확인한다.
A21: (2) 충당부채의 전체 또는 일부의 환입에 대해서 관련 사유 및 증빙 문서를 검토하고, 의무 이행을 위하여 자원이 유출될 가능성이 더 이상 높지 않은지 평가하며 환입이 관련된 손익계산서 상의 당초 비용과 동일한 계정과목에 반영되었는지 여부를 확인한다.
A22: 4. 제충당부채 완전성 확인 | J22: C
A23: 회사와 사업에 대한 지식 및 전년도 감사결과, 다른 테스트에서 입수한 감사증거 등을 통하여 회사의 제충당부채의 완전성에 대하여 검토한다.
A24: 5. 제충당부채의 산정근거의 가정/방법 이해,(소급적검토 포함) 데이터 신뢰성 및 산식의 적절성을 검토한다. | J24: V
A25: 6. 제충당부채에 대한 외부조회 | J25: A, E, C, RO
A26: 주요 거래처에 대한 채무가 중요할 경우 또는 제충당부채의 계약 조건에 대한 외부 확인이 필요할 경우 외부 확인을 수행하며 외부 확인에 대한 구체적인 절차는 Audit Guide 3320 외부조회를 참고한다.
A27: 7. 기간계산에 의하여 인식되는 계정에 대하여는 기간 계산내용을 검증한다. | J27: C, CO
A28: 8. 외화표시부채의 환산내용을 검토한다. | J28: V
A29: 9. 특수관계자와의 거래 | J29: E, CL
A30: 특수관계자와의 거래에 대한 구체적인 절차는 Audit Guide 3500 특수관계자 거래를 참고한다.
A31: 10. 재무제표 공시사항 검토(공시사항점검표 참조) | J31: C, CL, U, P
A32: 11. 감사결론의 기술
A35: Part 2. 추가 고려 절차
A36: 감사절차 | J36: 경영진 주장 | K36: 조서번호
A37: 1. 현재가치에 의한 평가의 적정성 | J37: V, A
A38: 제충당부채 중 현재가치에 의한 평가사항이 있는 경우 동 평가액과 동할인차금의 계산이 적정한지 검증하고, 관련손익계정에 반영되었는지 확인한다.
A39: 2. 감사인측 및 경영진측 전문가 수행업무의 평가 | J39: A, E, C,
A40: 감사증거로 사용될 정보가 경영진측 전문가가 수행한 업무의 도움으로 작성되거나 감사과정에서 감사인측 전문가가 수행한 업무를 활용하는 경우 Audit Guide 2131 전문가의 활용을 참조하여 평가한다. | J40: O, V
A41: 3. 제품보증충당부채의 감사절차(예시) | J41: RO, C, V,
A42: 고객에게 보증을 별도로 구매할 수 있는 선택권이 없고 약속한 보증(또는 그 일부)이 합의된 규격에 제품이 부합한다는 확신에 더하여 고객에게 용역을 제공하는 것이 아닌 확신유형 보증의 경우, 아래의 절차를 추가한다.
A43: (1) 회사의 제품보증정책에 대해 파악하고, 판매계약서․약정서 등을 검토하여 이를 확인한다. | J43: A
A44: (2) 제품보증충당부채와 관련비용계정의 변동을 검토하고, 동종업계 및 산업평균비율과 비교한다.
...

Sheet FFF
A1: 실 증 절 차
A2: (FFF. 기타의 비유동부채)
A4: 회사명 | C4: =A!C4 -> 0 | F4: 작성자 | G4: =A!G4 -> 0 | I4: 일자
A5: 결산일 | C5: =A!C5 -> 0 | F5: 검토자 | G5: =A!G5 -> 0 | I5: 일자
A6: 경영진 주장 :
A7: A | B7: : 정확성(Accuracy) | D7: E | E7: : 실재성(Existence) | G7: RO | H7: : 권리와 의무(Rights and obligations)
A8: C | B8: : 완전성(Completeness) | D8: O | E8: : 발생사실(Occurrence) | G8: CL | H8: : 분류(Classification)
A9: CO | B9: : 기간귀속(Cutoff) | D9: V | E9: : 평가(Valuation) | G9: U | H9: : 이해가능성(Understandability)
A10: P | B10: : 표시(Presentation)
A11: ※ 업무요령 : 조서번호 2302 감사위험의 평가(경영진 주장 수준)에서 파악된 위험과 조서번호 3100 위험에 대한 대응에 기재된 실증절차에 맞게 실증절차를 수행한다.
A13: Part 1. 절차 예시
A14: 감사절차 | J14: 경영진 주장 | K14: 조서번호
A15: 1. 기타의 비유동부채 총괄표 작성 | J15: E, C, CL
A16: 당기말 잔액은 총계정원장과 전기말잔액은 전기감사보고서와 각각 대조하고 양년도간에 특별한 변동사항이 있는 경우에는 그 원인을 규명한다.
A17: 2. 기타의 비유동부채 명세서 | J17: C, A
A18: 기타의 비유동부채 명세서를 입수하여 금액을 계산검증하고 잔액이 보조부와 일치하는지를 확인한다.
A19: 3. 기타의 비유동부채의 완전성 확인 | J19: C
A20: 회사와 사업에 대한 지식 및 전년도 감사결과, 다른 테스트에서 입수한 감사증거 등을 통하여 회사의 기타의 비유동부채의 완전성에 대하여 검토한다.
A21: 4. 기타의 비유동부채에 대한 외부조회 | J21: A, E, C, RO
A22: 주요 거래처에 대한 채무가 중요할 경우 외부 확인을 수행하며 외부 확인에 대한 구체적인 절차는 Audit Guide 3320 외부조회를 참고한다.
A23: 5. 기간계산에 의하여 인식되는 계정에 대하여는 기간 계산내용을 검증한다. | J23: C, CO
A24: 6. 외화표시부채의 환산내용을 검토한다. | J24: V
A25: 7. 특수관계자와의 거래 | J25: E, CL
A26: 특수관계자와의 거래에 대한 구체적인 절차는 Audit Guide 3500 특수관계자 거래를 참고한다.
A27: 8. 재무제표 공시사항 검토(공시사항점검표 참조) | J27: C, CL, U, P
A28: 9. 감사결론의 기술
A31: Part 2. 추가 고려 절차
A32: 감사절차 | J32: 경영진 주장 | K32: 조서번호
A33: 1. 현재가치에 의한 평가의 적정성 | J33: V, A
A34: 기타의 비유동부채중 현재가치에 의한 평가사항이 있는 경우 동 평가액과 동할인차금의 계산이 적정한지 검증하고, 관련손익계정에 반영되었는지 확인한다.
A35: 2. 감사인측 및 경영진측 전문가 수행업무의 평가 | J35: A, E, C,
A36: 감사증거로 사용될 정보가 경영진측 전문가가 수행한 업무의 도움으로 작성되거나 감사과정에서 감사인측 전문가가 수행한 업무를 활용하는 경우 Audit Guide 2131 전문가의 활용을 참조하여 평가한다. | J36: O, V
A38: Part 3. 추가감사절차
A40: * 감사인이 상기 감사절차예시 이외의 추가절차를 수행할 경우, 아래에 해당 내용을 기재한다.
A42: 감사절차 | J42: 경영진주장 | K42: 조서번호

Sheet TUL
A1: 실 증 절 차
A2: (TUL. 부외부채)
A4: 회사명 | C4: =A!C4 -> 0 | F4: 작성자 | G4: =A!G4 -> 0 | I4: 일자
A5: 결산일 | C5: =A!C5 -> 0 | F5: 검토자 | G5: =A!G5 -> 0 | I5: 일자
A6: 경영진 주장 :
A7: A | B7: : 정확성(Accuracy) | D7: E | E7: : 실재성(Existence) | G7: RO | H7: : 권리와 의무(Rights and obligations)
A8: C | B8: : 완전성(Completeness) | D8: O | E8: : 발생사실(Occurrence) | G8: CL | H8: : 분류(Classification)
A9: CO | B9: : 기간귀속(Cutoff) | D9: V | E9: : 평가(Valuation) | G9: U | H9: : 이해가능성(Understandability)
A10: P | B10: : 표시(Presentation)
A11: ※ 업무요령 : 조서번호 2302 감사위험의 평가(경영진 주장 수준)에서 파악된 위험과 조서번호 3100 위험에 대한 대응에 기재된 실증절차에 맞게 실증절차를 수행한다.
A13: Part 1. 절차 예시
A14: 감사절차 | J14: 경영진 주장 | K14: 조서번호
A15: 1. 어음수표에 대한 부외부채 확인 | J15: RO, C, V
A16: (1) 어음수표 총괄표 확인
A17: 회사로부터 거래은행별로 다음 내용이 포함된 어음수표총괄표를 징구하고, 어음수표관리대장과 일치하는지 확인한다.
A18: - 거래은행명
A19: - 전기말 미사용 내역(번호 및 매수)
A20: - 어음수표구입상황(구입일자, 매수, 번호)
A21: - 발행상황(발행번호 및 매수)
A22: - 폐기내용(작성시 오기, 담보제공어음 회수등)
A23: - 미사용 내역(번호 및 매수)
A24: - 누락번호 및 매수
A25: (2) 어음수표 수불 Test
A26: 어음․수표별 당기 사용매수에 대한 총괄적검증 결과 불일치의 경우 (A)>(B) 부외부채가능성이 있으므로 주의한다.
B27: 전기 미사용수량 | F27: 회계장부상 발행수량
B28: (+)당기중교부받은수량 | F28: (+)비망기록상 발행수량
B29: (-)기말 미사용수량 | F29: (+)폐기 수량
B30: (A)당기 어음․수표사용수량 | F30: (B)당기 어음․수표사용수량
A32: - 전기말 미사용내역：전기말 Cut-off 자료, 어음수표부본, 발행대장등과 대조 확인
A33: - 당기 교부받은 내역：은행별로 은행조회서 또는 은행보관 어음수표 교부대장사본과 비교확인(중도해지 은행을 포함하여야함)
A34: - 당기 발행내역 :
A35: ① 회사의 어음수표 발행대장, 회계장부기록, 또는 어음수표부본과 대조확인(지급어음, 단기차입등 금융어음)
A36: ② 비망기록(융통어음, 담보견질어음수표, 대여어음)을 검토하여 감사일현재 회수된 것은 실물을 확인하고 미회수된 것은 보관증을 확인대조하거나 상대채권자에 조회 확인.
A37: - 폐기내역：실물확인하거나 은행보고용 자료에 의해 확인
A38: - 미사용내역：현물을 실사하거나 어음수표발행대장과 어음수표부본을 개별대조 확인
A39: - 은행조회서에서 미회수어음수표내역이 확인되는 경우에는 그 미회수내용을 규명함으로서 위에 기술한 중복되는 절차를 생략 가능
A40: - 자가어음 발행의 경우：은행도어음 이외에 자가어음을 발행하는 경우도 상기 절차에 준하여 추가적으로 부외부채 발생가능성 검토
A41: 2. 결산일 전후의 자금거래내역 파악 | J41: RO, C, V, A
A42: 결산일 이후 감사보고서일과 근접한 일자까지 발생한 지급거래에 대하여 부채로 미반영된 사항이 있는지 여부를 확인한다.
A43: 3. 감사결론의 기술
...

Sheet CL
A1: 실 증 절 차
A2: (CL. 우발부채 및 약정사항)
A4: 회사명 | C4: =A!C4 -> 0 | F4: 작성자 | G4: =A!G4 -> 0 | I4: 일자
A5: 결산일 | C5: =A!C5 -> 0 | F5: 검토자 | G5: =A!G5 -> 0 | I5: 일자
A6: 경영진 주장 :
A7: A | B7: : 정확성(Accuracy) | D7: E | E7: : 실재성(Existence) | G7: RO | H7: : 권리와 의무(Rights and obligations)
A8: C | B8: : 완전성(Completeness) | D8: O | E8: : 발생사실(Occurrence) | G8: CL | H8: : 분류(Classification)
A9: CO | B9: : 기간귀속(Cutoff) | D9: V | E9: : 평가(Valuation) | G9: U | H9: : 이해가능성(Understandability)
A10: P | B10: : 표시(Presentation)
A11: ※ 업무요령 : 조서번호 2302 감사위험의 평가(경영진 주장 수준)에서 파악된 위험과 조서번호 3100 위험에 대한 대응에 기재된 실증절차에 맞게 실증절차를 수행한다.
A13: Part 1. 절차 예시
A14: 감사절차 | J14: 경영진 주장 | K14: 조서번호
A15: 1. 우발부채 및 약정사항 명세서의 입수 | J15: E, C, CL
A16: 모든 유의한 우발부채 및 약정사항 명세서를 입수하여 다음의 절차를 수행한다. 여기에는 해당된다면 전기 재무상태표 상의 대응되는 금액 및 전기에 존재하였던 약정을 포함한다.
A17: (1) 명세서의 산술적 정확성을 테스트한다.
A18: (2) 중요한 우발부채를 초래하는 사건이나 상황에 관하여 경영진에 대하여 질문하고 각각의 논의된 사항들에 대하여 문서화한다.
A19: 2. 우발부채 및 약정사항의 완전성 검토 | J19: C
A20: 다음사항을 참조하여 기말현재의 우발부채 및 약정사항의 완전성을 검토한다.
A21: (1) 회사의 거래 금융기관으로부터 받은 외부조회서
A22: (2) 주총, 이사회 등의 의사록에 대한 검토 내용
A23: (3) 은행연합회 기업신용정보자료
A24: (4) 소송과 배상청구에 대한 회사의 내·외부 법률고문과의 커뮤니케이션. 소송과 배상청구에 대한 구체적인 절차는 Audit Guide 3301 감사증거-특정항목에 대한 구체적인 고려사항를 참고한다.
A25: (5) 회사의 인감 날인부
A26: (6) 회사의 차입금, 지급보증, 파생상품 등 금융상품계약 및 장기매입(확정)계약서에 대한 검토 내용
A27: 3. 우발부채 계상의 적정성 | J27: A, C, V
A28: (1) 우발부채중 확정채무화 될 것이 확실하고 그 손실금액을 예측할 수 있는 것에 대해서는 부채로 계상되었는지를 검토한다
A29: (2) 필요한 경우에는 보증채무, 보증예약 등에 대하여 상대 거래처에게 직접 확인
A30: (3) 제조물책임, 환경문제 등을 원인으로 하는 우발부채를 고려할 필요가 없는가를 검토
A31: (4) 경영지도각서와 같은 보증에 준하는 우발부채의 원인으로 될 가능성이 있는 행위를 하고 있지 않은가에 대하여 경영자에 대한 질문
A32: (5) 보고기간 후에 입수한 정보가 재무제표에 이미 인식된 금액에는 영향을 미치지 않으나 재무제표의 공시 내용의 수정 필요성 검토
A33: 4. 서면진술서 | J33: C, V, CL, U
A34: 보고기간종료일 현재의 우발부채(부표내용 포함) 및 약정사항에 대하여는 서면진술서에 기재(모든 부채의 완전성에 관한 사항을 포함)하여 책임자의 서명 날인을 받는다.
A35: 5. 특수관계자 거래 | J35: E, CL
A36: 특수관계자와의 거래에 대한 구체적인 절차는 Audit Guide 3500 특수관계자 거래를 참고한다.
A37: 6. 재무제표 공시사항의 적정성 검토(공시사항점검표 참조) | J37: C, CL, U, P
A38: 7. 감사결론의 기술
A41: Part 2. 추가 고려 절차
A42: 감사절차 | J42: 경영진 주장 | K42: 조서번호
A43: 1. 매출채권의 양도, 할인 | J43: V, CL
A44: 매출채권의 양도(어음의 배서) 또는 할인 내용을 확인하기 위해 관계책임자에게 질문 또는 매출채권 계정을 검토하여 감소(어음은 만기일전)된 내용을 검토하고 회계처리의 적정정을 검토한다.
...

Sheet GG
A1: 실 증 절 차
A2: (GG. 자본)
A4: 회사명 | C4: =A!C4 -> 0 | F4: 작성자 | G4: =A!G4 -> 0 | I4: 일자
A5: 결산일 | C5: =A!C5 -> 0 | F5: 검토자 | G5: =A!G5 -> 0 | I5: 일자
A6: 경영진 주장 :
A7: A | B7: : 정확성(Accuracy) | D7: E | E7: : 실재성(Existence) | G7: RO | H7: : 권리와 의무(Rights and obligations)
A8: C | B8: : 완전성(Completeness) | D8: O | E8: : 발생사실(Occurrence) | G8: CL | H8: : 분류(Classification)
A9: CO | B9: : 기간귀속(Cutoff) | D9: V | E9: : 평가(Valuation) | G9: U | H9: : 이해가능성(Understandability)
A10: P | B10: : 표시(Presentation)
A11: ※ 업무요령 : 조서번호 2302 감사위험의 평가(경영진 주장 수준)에서 파악된 위험과 조서번호 3100 위험에 대한 대응에 기재된 실증절차에 맞게 실증절차를 수행한다.
A13: Part 1. 절차 예시
A14: 감사절차 | J14: 경영진 주장 | K14: 조서번호
A15: 1. 자본계정의 총괄표 작성 | J15: E, C, CL
A16: 당기말잔액은 총계정원장과 전기말잔액은 전기감사보고서와 각각 대조하고, 양년도간 특별한 변동이유를 규명한다.
A17: 2. 자본계정의 명세서 | J17: C, A
A18: 기초잔액, 증가, 감소 및 기말잔액, 수권주식수 및 기말 현재 발행주식수, 주당 액면가액 등을 포함하여, 주식 종류별로 구분된 자본 계정에 대한 명세서를 입수하여 금액을 계산검증하고 잔액이 보조부와 일치하는지 확인한다.
A19: 3. 자본금 변동사항에 대하여 관련 증빙과 대조 확인하고 회계처리의 적정성을 확인한다. | J19: E, C, V
A20: 4. 자본잉여금 변동사항에 대하여 관련 증빙과 대조 확인하고 회계처리의 적정성을 확인한다. | J20: E, C, V
A21: 5. 기타포괄손익누계액(기타포괄손익-공정가치측정 금융자산 평가손익, 해외사업환산손익, 현금흐름위험회피 파생상품평가손익 등) 항목에 대한 금액의 정확성 및 회계처리의 적정성을 확인한다. | J21: V, A
A22: 6. 주당이익(손실)의 계산을 검증한다. | J22: A, U
A23: (희석증권이 있는 경우 희석화 여부를 판단하라)
A24: 7. 재무제표 표시사항 검토 | J24: CL, U, P
A25: (1) 납입자본과 적립금을 자본금, 주식발행초과금, 적립금 등과 같은 분류로 세분화
A26: (2) 주당이익(손실)(공개기업이나 상장절차를 진행하고 있는 기업이 아닌 경우 주당이익을 공시하지 않을 수 있음)
A27: 8. 재무제표 공시사항의 적정성 검토(공시사항점검표 참조) | J27: C, CL, U, P
A28: 9. 감사결론의 기술
A30: Part 2. 추가 고려 절차
A31: 감사절차 | J31: 경영진 주장 | K31: 조서번호
A32: 1. 자본금 | J32: E, C, V
A33: (1) 증자가 있는 경우 수권자본범위, 입금기록(유상증자), 등기부등본을 확인
A34: (2) 감자가 있는 경우 적법성과 감자차손익의 적정성을 확인하고 등기부등본 확인
A35: (3) 현물출자일 경우 공정가액평가와 회계처리의 적정성 확인
A36: (4) 신주청약증거금, 청약미수금이 있는 경우 관련 증빙과 대조 확인
A37: (5) 정관 및 법인등기부등본을 입수하여 자본계정의 내역을 확인
A38: (6) 주주명부나 주식대장을 검토하여 기중 자본의 변동상황을 확인
A39: 2. 자본잉여금 | J39: E, C, V
A40: (1) 자본잉여금 내용 및 증감사항의 타당성을 검토
A41: (2) 전환증권의 발행 및 전환 등에 대한 회계처리의 적정성을 검토
A42: 3. 이익잉여금 | J42: E, C, V
A43: 이익잉여금 증감사항의 타당성 확인을 위해 전기 및 당기의 이익잉여금처분계산서를 검토하고, 다음 절차를 수행한다.
...

Sheet P
A1: 실 증 절 차
A2: (P. 매출 및 기타수익)
A4: 회사명 | C4: =A!C4 -> 0 | F4: 작성자 | G4: =A!G4 -> 0 | I4: 일자
A5: 결산일 | C5: =A!C5 -> 0 | F5: 검토자 | G5: =A!G5 -> 0 | I5: 일자
A6: 경영진 주장 :
A7: A | B7: : 정확성(Accuracy) | D7: E | E7: : 실재성(Existence) | G7: RO | H7: : 권리와 의무(Rights and obligations)
A8: C | B8: : 완전성(Completeness) | D8: O | E8: : 발생사실(Occurrence) | G8: CL | H8: : 분류(Classification)
A9: CO | B9: : 기간귀속(Cutoff) | D9: V | E9: : 평가(Valuation) | G9: U | H9: : 이해가능성(Understandability)
A10: P | B10: : 표시(Presentation)
A11: ※ 업무요령 : 조서번호 2302 감사위험의 평가(경영진 주장 수준)에서 파악된 위험과 조서번호 3100 위험에 대한 대응에 기재된 실증절차에 맞게 실증절차를 수행한다.
A13: Part 1. 절차 예시
A14: 감사절차 | J14: 경영진 주장 | K14: 조서번호
A15: 1. 회계정책을 이해하고 평가함 | J15: O, A, CL
A16: (1) 새로운 수익 인식 기준에 따라서 수익(반품, 할인, 충당금 등의 수익 차감 항목 포함), 계약자산, 계약부채를 인식하고 기록하는 회사의 회계정책을 이해한다. (2) 수익 인식의 적합성을 평가하는 경영진의 프로세스를 이해한다. (3) 회계정책이 이전 보고기간과 일관성이 있는지 확인한다. (4) 회사의 회계정책은 해당 재무보고 체계 및 회사의 사업과 산업의 성격에 대한 이해에 비추어 적합한지 평가한다.
A17: 2. 매출액 비교분석표 작성 | J17: O, A, CL
A18: 당기 금액은 총계정원장과 전기 금액은 전기감사보고서와 각각 대조하고 양년도간에 특별한 변동사항이 있는 경우에는 그 원인을 규명한다.
A19: 3. 매출액명세서 및 부가가치세신고서의 입수 | J19: O, A
A20: 수익종류별, 월별 또는 지역별 매출액명세서의 잔액이 보조부와 일치하는지를 확인하고 부가가치세신고서와 대조, 계산의 정확성을 검증한다.
A21: 감사절차 | J21: 경영진 주장 | K21: 조서번호
A22: 4. 분석적 검토 | J22: O, C, A
A23: 최근 2-3년간 손익계산서에 대한 다음의 분석적검토를 실시한다.
A24: (1) 매출액의 내용별 구성비율의 분석
A25: (2) 매출액과 판매비(운반비, 수출비, 판매수수료등)와의 비교분석
A26: (3) 월별매출액의 비교분석
A27: (4) 매출총이익율의 분석
A28: (5) 매출액 대비 환입, 에누리, 할인등의 비교분석
A29: (6) 재무비율의 추이를 분석하고 결과치를 산업평균과 경쟁사와 비교
A30: (7) 월별 또는 분기별 예산과 실제 매출액을 비교하고, 중요한 차이에 대한 검토
A31: (8) 결산일 전후 수일간의 매출액을 당해연도 평균 일일 매출액과 비교
A32: (9) 당기의 월별 판매단가자료를 입수하여 추세를 분석하고, 전기의 평균판매단가와 비교
A33: 5. 거래형태별 수익인식기준의 타당성을 검토한다. | J33: O, C, A, CL
A34: 5-1. 수익회계기준서(K-IFRS 제1115호)에서 제시한 5단계 수익인식모형에 따른 수익인식조건을 검토한다. (4000P-1 조서를 작성한다.) 5-2. 기간에 걸쳐 인식하는 매출(지적재산권의 라이선스 포함)이 있는 경우 Part 2 또는 4000P-1의 관련 절차를 추가 고려한다. | J34: O
A35: 6. 결산일 직전․후의 거래에 대하여 실증절차(인수(검수)증, BL원장 등 증빙확인 등)를 수행하여 기간귀속의 적정성을 확인한다. | J35: C, A,CO
A36: 6-1. 기중 회사의 거래내역을 분석하여 매출의 발생사실을 확인한다. | J36: O
A37: 7. 기타수익의 적정성 | J37: O, A
A38: 기타수익의 종류별, 월별 또는 지역별 명세서의 잔액이 보조부와 일치하는지를 확인한다.
A39: 8. 특수관계자와의 거래 | J39: O, CL
A40: 관계회사등 특수관계자와의 거래유무를 확인하고, 거래가 있으면 이해관계없는 제3자와의 거래와 같이 정당하고 공정하게 이루어졌는가를 검토한다. 특수관계자와의 거래에 대한 구체적인 절차는 Audit Guide 3500 특수관계자 거래를 참고한다.
A41: 9. 재무제표 공시사항 검토(공시사항점검표 참조) | J41: CL, P
A42: 10. 감사결론의 기술
...

Sheet Q
A1: 실 증 절 차
A2: (Q. 매출원가, 제조원가)
A4: 회사명 | C4: =A!C4 -> 0 | F4: 작성자 | G4: =A!G4 -> 0 | I4: 일자
A5: 결산일 | C5: =A!C5 -> 0 | F5: 검토자 | G5: =A!G5 -> 0 | I5: 일자
A6: 경영진 주장 :
A7: A | B7: : 정확성(Accuracy) | D7: E | E7: : 실재성(Existence) | G7: RO | H7: : 권리와 의무(Rights and obligations)
A8: C | B8: : 완전성(Completeness) | D8: O | E8: : 발생사실(Occurrence) | G8: CL | H8: : 분류(Classification)
A9: CO | B9: : 기간귀속(Cutoff) | D9: V | E9: : 평가(Valuation) | G9: U | H9: : 이해가능성(Understandability)
A10: P | B10: : 표시(Presentation)
A11: ※ 업무요령 : 조서번호 2302 감사위험의 평가(경영진 주장 수준)에서 파악된 위험과 조서번호 3100 위험에 대한 대응에 기재된 실증절차에 맞게 실증절차를 수행한다.
A13: Part 1. 절차 예시
A14: 감사절차 | J14: 경영진 주장 | K14: 조서번호
A15: 1. 매출원가 비교분석표 작성 | J15: C, O, CL
A16: (1) 전기의 매출원가 금액은 전기감사보고서와 대조하고, 기초재고액과 당기매입액(또는 당기제조원가) 및 기말재고액은 재고자산조서와 연결한다.
A17: (2) 총괄표상의 계산의 정확성을 검증한다.
A18: (3) 전기말 대비 당기말 잔액의 변동내역을 확인하고 양년도간 특별한 변동사항은 그 원인을 규명한다.
A19: 2. 매출원가와 매출액을 전기와 비교하여 매출이익률의 변동이 큰 경우에는 그 원인을 조사한다. | J19: C, A
A20: 3. 매출원가의 구성을 검토 | J20: A
A21: (1) 타계정에서 대체된 내용과 타계정으로 대체된 명세서를 입수하여 그 처리의 적정성을 검토
A22: (2) 관세환급금등 매출원가에서 차감할 사항의 유무를 검토
A23: (3) 중요한 타계정 금액에 대해서는 금액적 중요성 및 발생원천을 고려하여 관련 증빙의 적정성을 검증
A24: 4. 원가계산방법의 타당성 | J24: A
A25: 회사가 채택하고 있는 원가계산제도에 따른 원가계산 방법이 타당한가를 검토한다.(원가계산관계서류 징구)
A26: 5. 제조원가명세서의 적정성 | J26: O, C, A
A27: 전기 대비 제조원가명세서를 징구하여 제조원가 명세서의 구성항목과 제조원가에서 각각의 원재료비, 노무비, 경비가 차지하는 비중이 적절한지에 대하여 검토한다.
A28: 6. 제조원가항목의 분석적검토 | J28: O, C, A
A29: 제조원가 각 항목의 월별 변동사항을 검토하고, 전기와도 비교하여 그 변동의 타당성을 확인
A30: 7. 보고기간종료일 직전․후의 거래를 분석하여 기간귀속의 적정성을 확인한다. | J30: C, CO
A31: 8. 특수관계자 거래 | J31: E, CL
A32: 특수관계자와의 거래에 대한 구체적인 절차는 Audit Guide 3500 특수관계자 거래를 참고한다.
A33: 9. 재무제표 공시사항 검토(공시사항점검표 참조) | J33: C, CL, U, P
A34: 10. 감사결론의 기술
A35: Part 2. 추가 고려 절차
A36: 감사절차 | J36: 경영진 주장 | K36: 조서번호
A37: 1. 제조원가명세서의 적정성 | J37: O, C, A
A38: 전기 대비 제조원가명세서를 징구하여 다음의 감사절차를 수행한다.
A39: (1) 원가구성비율등을 제조원가 요소별로 전기와 대비하여 적정성을 검토하고 비정상적인 거래에 대해서는 증빙대조하여 그 타당성을 확인한다.
A40: (2) 보조부 및 총계정원장과 대조하고 보조부를 개관하여 특이한 금액이 있으면 증빙을 검토한다.
A41: (3) 제조원가와 판매관리비와의 구분기준을 검토하며, 배부된 간접비를 관련 증빙과 비교하고 계산을 검증한다.
A42: (4) 제조원가중 재무상태표와 연결되는 부분을 검토한다.
...

Sheet R
A1: 실 증 절 차
A2: (R. 판매비와관리비)
A4: 회사명 | C4: =A!C4 -> 0 | F4: 작성자 | G4: =A!G4 -> 0 | I4: 일자
A5: 결산일 | C5: =A!C5 -> 0 | F5: 검토자 | G5: =A!G5 -> 0 | I5: 일자
A6: 경영진 주장 :
A7: A | B7: : 정확성(Accuracy) | D7: E | E7: : 실재성(Existence) | G7: RO | H7: : 권리와 의무(Rights and obligations)
A8: C | B8: : 완전성(Completeness) | D8: O | E8: : 발생사실(Occurrence) | G8: CL | H8: : 분류(Classification)
A9: CO | B9: : 기간귀속(Cutoff) | D9: V | E9: : 평가(Valuation) | G9: U | H9: : 이해가능성(Understandability)
A10: P | B10: : 표시(Presentation)
A11: ※ 업무요령 : 조서번호 2302 감사위험의 평가(경영진 주장 수준)에서 파악된 위험과 조서번호 3100 위험에 대한 대응에 기재된 실증절차에 맞게 실증절차를 수행한다.
A13: Part 1. 절차 예시
A14: 감사절차 | J14: 경영진 주장 | K14: 조서번호
A15: 1. 판매비와 관리비 총괄표 작성 | J15: C, O, CL
A16: 당기 금액은 총계정원장과, 전기 금액은 전기감사보고서와 각각 대조하고, 양년도간 특별한 변동 사항은 그 원인을 규명한다.
A17: 2. 수출제비용, 포장비 등 변동비 월별명세서 를 입수하여 다음의 절차를 수행한다. | J17: O, C, A
A18: (1) 전기와 대비하여 검토
A19: (2) 매출액에 대한 구성비율 검토
A20: (3) 보조부 및 총계정원장과 대조
A21: (4) 보조부를 개관하여 특별한 금액이 있으면 담당자에게 질문하고 필요한 경우 증빙을 확인
A22: 3. 판매비와 관리비 중 관련되는 자산 또는 부채계정이 있을 경우 해당 자산 또는 부채 계정의 감사조서와 연결하여 검토한다. | J22: V, A
A23: 4. 전력비, 수도료, 임차료, 사용료등 매월 지급되는 비용은 최종월지급분의 계상유무를 검토한다. | J23: C, CO
A24: 5. 보고기간종료일 직전․후의 거래를 분석하여 기간귀속의 적정성을 확인한다. | J24: C, CO
A25: 6. 판매관리비용이 성격에 따라 적절히 분류되었는지를 파악한다. 특히, 판매관리비와 제조원가의 혼동, 판매관리비와 영업외비용의 혼동에 유의한다. | J25: CL
A26: 7. 특수관계자와의 거래 | J26: E, CL
A27: 특수관계자와의 거래에 대한 구체적인 절차는 Audit Guide 3500 특수관계자 거래를 참고한다.
