Workbook

Sheet 2100
A2: 2100 회사의 사업 및 법규에 대한 이해 (기준서 315)
A4: 회사명 | C4: 작성자 | E4: 일자
A5: 결산일 | C5: 검토자 | E5: 일자
A7: 항 목 | D7: 조서번호 | E7: 수 행 자 | F7: 비 고
A8: (회사 및 각 환경 측면에서의 이해)
A9: 1.해당 재무보고체계 등 관련 산업적 요인, 규제적 요인 및 기타 외부적 요인 을 이해하여야 한다.
A10: 2.재무제표에 예상되는 거래유형과 계정잔액 및 공시 등의 이해를 위한 회사의 성격을 이해하여야 한다. 여기에는 다음과 같은 사항들이 포함된다.
A11: (1)회사의 경영활동
A12: (2)회사의 소유 및 지배 구조
A13: (3)특수목적기업에 대한 투자 등 회사가 진행 중이거나 계획하고 있는 투자의 유형
A14: 4)회사의 조직구조와 자금조달 방식
A15: 3.회사의 회계정책의 선택과 적용을 이해하여야 하며, 회계정책의 변경 시 그 이유도 포함한다. 회사의 회계정책이 당해 회사의 사업에 적합한지, 그리고 그것이 해당 재무보고체계 및 관련 산업에서 적용되는 회계정책과 일관성이 있는지 여부를 평가하여야 한다.
A16: 4.회사의 목적과 전략 및 중요왜곡표시위험을 초래할 수 있는 관련 사업위험을 이해하여야 한다.
A17: 5.회사의 재무성과의 측정과 검토를 이해하여야 한다.
A18: (법규 측면에서의 이해)
A19: 1.회사와 산업에 적용되는 법규 및 회사가 이러한 법규를 어떻게 준수하고 있는 지 이해하여야 한다.
... A25: 5.식별되었거나 의심되는 위반이 없는 경우, 상기 절차 외에 회사의 법규준수에 관한 감사절차의 수행이 요구되지 아니한다.

Sheet 2100A
A2: 2100A 회사의 사업 및 법규에 대한 이해요약표 (기준서 315)
A4: 회사명 | B4: ='2100'!B4 -> 0 | D4: 작성자 | E4: ='2100'!D4 -> 0 | G4: 일자
A5: 결산일 | B5: ='2100'!B5 -> 0 | D5: 검토자 | E5: ='2100'!D5 -> 0 | G5: 일자
A7: 항 목 | B7: 내 역
A8: (회사 및 각 환경 측면에서의 이해)
A9: 1.산업의 분류 및 성격
A10: 2.산업별 규제요인 및 기타 외부적 요인
A11: 3.산업별 보고 요구사항 | B11: 산업별 감독기관에서 요구하는 보고서와 같이, 감사에 적용되는 산업별 보고 요구사항이 있다면 기재
A15: 4.적용되는 회계처리기준 및 회계정책 | B15: 회계처리기준 및 회계정책의 선택과 적용, 변경이 있는 경우는 변경의 이유를 문서화
A19: 5.목적과 전략 및 사업위험
A20: 6.회사 일반사항 | B20: 회사명
B21: 국문:
B22: 영문:
B23: 대표이사명:
B24: 주소
B25: 본사:
B26: 공장:
A27: 7.회사연혁 | B27: (1) 설립연월일:
B28: (2) 기업공개일:
B29: (3) 자본금 증감내역:
B30: 일 자 | D30: 증자금액 | F30: 증자후 자본금 | H30: 재원
B34: (4) 합작여부
B35: 합작선 | D35: 합작일 | F35: 투자금액 | H35: 지분율
B39: (5) 주주 현황 및 관계
B40: 대주주 | D40: 주주명 | F40: 지분율 | H40: 영업상 관계
B44: (6) 투자하고 있는 회사 또는 투자 예정 중인 회사
B45: 회사명 | D45: 지분율 | F45: 영업상관계
A50: 8.회사의 조직 | B50: (1) 주요 부서별 인원
D51: 본 사 | F51: ( )공장 | H51: ( )공장
B52: 임원
B53: 관리부서
B54: 생산부서
B55: 영업부서
B58: (2) 종업원 복지후생
B59: - 노동조합 결성 여부:
B60: - 복지제도:
B62: (3) 자문기관
B63: - 변호사:
B64: - 세무고문:
B65: - 기타:
...

Sheet 2110
A2: 2110 감사계획의 수립 (기준서 300)
A4: 회사명 | B4: ='2100'!B4 -> 0
A5: 결산일 | B5: ='2100'!B5 -> 0
A7: Part A. 전반감사전략과 감사계획수립
A8: 항 목 | F8: 조서번호 | G8: 수행자 | H8: 비고
A9: (감사팀의 구성)
A10: 1.업무수행이사 및 다른 핵심 업무팀원의 역할을 수행할 팀원을 식별하여 감사팀을 구성한다.
A11: 2 업무품질관리검토자가 지정되었는지 또는 회계법인의 품질관리규정등에 의거 지정되어야 하는지 여부를 확인한다.
A12: 3 감사인 측 전문가의 참여를 고려한다. 감사인측 전문가를 감사에 활용하는 경우, 조서번호 2131 감사인측 전문가의 활용 을 참고한다.
A13: 4 내부 감사인 또는 서비스조직의 업무를 활용할 필요성에 대해서 고려한다.
A14: (1) 회사에 내부감사기능이 있다면 조서번호 2132 내부감사의 활용을 참조한다.
A15: (2) 서비스조직을 감사업무에 활용하고자 하는 경우 조서번호 2133 서비스조직의 활용을 참조한다.
A16: 5 감사팀, 그리고 감사팀에 소속되지 않은 감사인 측 전문가가, 전문가적 기준 및 해당 법규의 요구사항에 따라 감사 업무를 수행하기에 적합한 적격성과 및 역량을 갖추고 있는지 여부를 고려한다.
A17: (업무의 지휘/감독, 검토 및 자문)
A18: 1 업무팀원들에 대한 지휘와 감독 및 업무팀원들이 수행한 작업의 검토에 대하여 그 성격과 시기 및 범위를 계획하여야 한다.
A19: (1)경험이 적은 팀원의 업무는 보다 경험이 많은 팀원이 검토한다는 것을 기반으로 하여, 업무팀원 간에 업무의 작성과 검토에 대한 역할과 책임을 지정한다.
A20: (2)업무팀원 간 주요 내부 회의(예를 들어, kick-off meeting, debrief meetings 등)와 검토 (적절한 경우에는 업무품질관리검토자의 검토를 포함)의 시기를 결정하고 기록한다.
A21: 항 목 | F21: 조서번호 | G21: 수행자 | H21: 비고
A22: (*) 어느 시기에 인력이 배치될 것인지, 업무담당자 및 지시, 감독 및 검토 담당자를 조서번호 2110A 업무분장표를 활용하여 표시할 수 있다.
A23: 2 업무수행이사는 자문과 관련하여 다음의 절차를 수행하여야 한다.
A24: (1) 어렵거나 논쟁의 여지가 있는 사항들에 관하여 업무팀 내부 및 업무팀과 회계법인 내․외부의 적합한 위치의 자들 간에 적합한 자문을 실시
A25: (2) 감사업무 수행과정에서 실시된 자문의 성격, 범위와 그 결론을 감사문서에 포함
A26: (3)업무팀 내부나 자문수행자, 또는 해당되는 경우 업무수행이사와 업무품질관리검토자간에 의견의 불일치가 발생하면, 이를 처리하고 해결하기 위한 회계법인의 정책과 절차를 준수
A27: (업무팀원간 토의)
A28: 1 업무수행이사와 다른 핵심 업무팀원들은 업무팀원간의 토의를 계획하고 참여하는 등 감사계획에 참여하여야 한다. 업무팀원간의 토론내용 및 도달된 유의적 결정사항을 문서화한다.
A29: 2 업무수행이사와 다른 핵심업무팀원은 부정이나 오류 가능성에 대해 토의하여야 하며 이때 아래의 내용을 포함한다.
A30: (1) 부정이 어떻게 발생할 것인지 등 기업의 재무제표가 부정에 의하여 어디서 어떻게 중요하게 왜곡표시될 위험성이 높은지
A31: (2) 해당 재무보고체계에 대하여 기업의 실질과 상황에 맞게 적용하는 문제
A32: (3) 특수관계 및 그 거래로부터 유발될 수 있는, 부정이나 오류에 의해 재무제표가 중요하게 왜곡표시될 취약성에 대한 특별한 고려
A33: (4) 특수관계자에 대해 입수한 관련 정보를 업무팀의 다른 구성원과 공유
... A35: 4 업무수행이사는 토의에 참여하지 않은 업무팀원들에게 어떤 사항을 커뮤니케이션할 것인지 결정하여야 한다.
A36: 항 목 | F36: 조서번호 | G36: 수행자 | H36: 비고
A37: (감사계획 수립의 확인)
A38: 1 주요감사계약 내용의 확인
A39: (1) 감사목적과범위：상장( ), 코스닥( ), 코넥스( ), 일반( ), 임의( )
A40: (2) 연결재무제표 감사 여부：여( ), 부( )
A41: (3)감사일정:
A42: 감사계획:
A43: 중간감사:
A44: 재고 실사입회:
...

Sheet 2110A
A1: 2110A 업 무 분 장 표 (기준서 300)
A3: 회 사 명 : | B3: ='2100'!B4 -> 0 | E3: 작 성 자 : | G3: ='2100'!D4 -> 0
A4: 결 산 일 : | B4: ='2100'!B5 -> 0 | E4: 일 자 :
A5: 감 사 절 차 | B5: 1분기검토 | C5: 반기검토 | D5: 3분기검토 | E5: 중간감사 | F5: 기말감사 | G5: 1차검토 | H5: 2차검토
B6: 담당자명 | C6: 담당자명 | D6: 담당자명 | E6: 담당자명 | F6: 담당자명 | G6: 담당자명 | H6: 담당자명
A7: (1) 위험평가
A8: 1) 회사의 사업등에 대한 이해
A9: 2) 감사위험의 평가
A10: 3) 통제환경, 위험평가, 모니터링에 대한 이해 및 평가
A11: 4) 정보시스템 이해 및 평가
A12: 5) 통제활동의 이해 및 평가
A13: 6) 전반감사계획의 수립
A14: 7)
A15: (2) 위험에 대한 대응
A16: (3) 계정별 실증절차
A17: 1) 현금및현금성자산, 장단기금융상품
A18: 2) 매출과 매출채권
... A40: (6) 품질관리검토

Sheet 2120
A2: 2120 분석적절차(계획단계) (기준서 315)
A5: 회사명 | B5: 0 | C5: 작성자 | D5: 0 | E5: 일 자
A6: 결산일 | B6: 0 | C6: 검토자 | D6: 0 | E6: 일 자
A9: 항 목 | F9: 조서번호 | G9: 수 행 자 | H9: 비 고
A10: 1전체재무제표 수준 및 경영진주장 수준의 중요왜곡표시위험의 식별과 평가를 위해 위험평가 분석적절차를 설계하고 수행하여야 한다.
A11: (1)회사의 영업과 산업, 일반적인 경제 상황 및 전기의 감사 경험등을 고려하고, 재무 또는 비재무적 정보 간의 관계(예를 들면, 매출액과 판매장 면적)와 일관성이 있는 지 검토한다.
A12: (2)분석 내역에 대해 문서화한다.
A13: 2 비경상적인 거래나 사건, 금액, 비율 그리고 추세의 존재를 식별하였다면, 회사에 질문 등을 통하여 이러한 항목들을 이해하고 감사 절차의 성격, 시기 및 범위를 고려하여 적합한 감사 절차를 포함하도록 감사 계획을 수정한다.
A14: 3 위험평가 분석적절차에서 발견된 위험요소를 식별하고 위험을 평가, 문서화한다(관련 위험은 조서번호 2301 감사위험의 평가(재무제표 수준), 2302 감사위험의 평가(경영진 주장 수준) 및 2110 감사계획의 수립 에 반영한다)
A15: (*) 분석적절차 수행 시 조서번호 2120A 분석적절차(계획단계)를 활용할 수 있음
A16: (**) 만약 감사인이 계획단계 분석적절차를 실증절차(실증적 분석적절차)로 활용하고자 한다면, 조서번호3300 분석적절차(수행단계)의 각 요구사항을 고려하여야 함
A18: 1. 전체재무제표 수준의 분석
A19: 과거 2～3년간의 재무제표와 당기 (당반기, 당분기등) 재무제표를 입수하여 다음과 같은 분석수행
A20: (1)당좌, 재고자산등 소분류항목을 중심으로 백분율 재무제표를 작성하고 주요 변동원인 규명
A21: (2)백분율 손익계산서를 작성하고 원가율등 주요 변동원인 규명
A22: (3)재무상태표와 손익계산서의 주요 항목에 대한 추세비율을 분석하고 동종산업의 일반적인 추세 등과 대비
... A69: (3)현금흐름의 추세분석

Sheet 2120A
A2: 2120A 위험평가 분석적절차 (기준서 315)
B4: 회사명 | E4: 작성자 | H4: 일 자
B5: 결산일 | E5: 검토자 | H5: 일 자
A8: 계정의 유의성 판단기준(금액) | F8: 100 | G8: 백만원
A9: 계정의 유의성 판단기준(비율) | F9: 10 | G9: %
A11: 재무제표 | D11: 당기 | F11: 전기 | H11: Variance | J11: 불일치 또는 | L11: 설명 또는 감사계획에 반영할 사항 | M11: 관련 조서번호
J12: 유의적인 차이(O/X)
D13: 금액 | E13: 백분율 | F13: 금액 | G13: 백분율 | H13: 금액 | I13: % | J13: 잠정 | K13: 최종
A14: 재무상태표
A15: 유동자산 | D15: =D16+D21 -> 0 | E15: =D15/$D$30 -> #DIV/0! | F15: =F16+F21 -> 0 | G15: =F15/$F$30 -> #DIV/0! | H15: =+F15-D15 -> 0 | I15: =H15/F15 -> #DIV/0!
B16: 당좌자산 | D16: =SUM(D17:D20) -> 0 | E16: =D16/$D$30 -> #DIV/0! | F16: =SUM(F17:F20) -> 0 | G16: =F16/$F$30 -> #DIV/0! | H16: =+F16-D16 -> 0 | I16: =H16/F16 -> #DIV/0!
C17: 현금및현금성자산 | E17: =D17/$D$30 -> #DIV/0! | G17: =F17/$F$30 -> #DIV/0! | H17: =+F17-D17 -> 0 | I17: =H17/F17 -> #DIV/0! | J17: =IF(ISERROR(OR(ABS(H17)>=$F$8,ABS(I17)>=$F$9)),"",IF(AND(ABS(H17)>=$F$8,ABS(I17)>=$F$9),"O",IF(OR(ABS(H17)>=$F$8,ABS(I17)>=$F$9),"△","X")))
C18: 단기투자자산 | E18: =D18/$D$30 -> #DIV/0! | G18: =F18/$F$30 -> #DIV/0! | H18: =+F18-D18 -> 0 | I18: =H18/F18 -> #DIV/0! | J18: =IF(ISERROR(OR(ABS(H18)>=$F$8,ABS(I18)>=$F$9)),"",IF(AND(ABS(H18)>=$F$8,ABS(I18)>=$F$9),"O",IF(OR(ABS(H18)>=$F$8,ABS(I18)>=$F$9),"△","X")))
C19: 매출채권 | E19: =D19/$D$30 -> #DIV/0! | G19: =F19/$F$30 -> #DIV/0! | H19: =+F19-D19 -> 0 | I19: =H19/F19 -> #DIV/0! | J19: =IF(ISERROR(OR(ABS(H19)>=$F$8,ABS(I19)>=$F$9)),"",IF(AND(ABS(H19)>=$F$8,ABS(I19)>=$F$9),"O",IF(OR(ABS(H19)>=$F$8,ABS(I19)>=$F$9),"△","X")))
C20: 기타 | E20: =D20/$D$30 -> #DIV/0! | G20: =F20/$F$30 -> #DIV/0! | H20: =+F20-D20 -> 0 | I20: =H20/F20 -> #DIV/0! | J20: =IF(ISERROR(OR(ABS(H20)>=$F$8,ABS(I20)>=$F$9)),"",IF(AND(ABS(H20)>=$F$8,ABS(I20)>=$F$9),"O",IF(OR(ABS(H20)>=$F$8,ABS(I20)>=$F$9),"△","X")))
B21: 재고자산 | E21: =D21/$D$30 -> #DIV/0! | G21: =F21/$F$30 -> #DIV/0! | H21: =+F21-D21 -> 0 | I21: =H21/F21 -> #DIV/0! | J21: =IF(ISERROR(OR(ABS(H21)>=$F$8,ABS(I21)>=$F$9)),"",IF(AND(ABS(H21)>=$F$8,ABS(I21)>=$F$9),"O",IF(OR(ABS(H21)>=$F$8,ABS(I21)>=$F$9),"△","X")))
A22: 비유동자산 | D22: =D23+D27+D28+D29 -> 0 | E22: =D22/$D$30 -> #DIV/0! | F22: =F23+F27+F28+F29 -> 0 | G22: =F22/$F$30 -> #DIV/0! | H22: =+F22-D22 -> 0 | I22: =H22/F22 -> #DIV/0!
B23: 투자자산 | D23: =SUM(D24:D26) -> 0 | E23: =D23/$D$30 -> #DIV/0! | F23: =SUM(F24:F26) -> 0 | G23: =F23/$F$30 -> #DIV/0! | H23: =+F23-D23 -> 0 | I23: =H23/F23 -> #DIV/0!
C24: 장기투자자산 | E24: =D24/$D$30 -> #DIV/0! | G24: =F24/$F$30 -> #DIV/0! | H24: =+F24-D24 -> 0 | I24: =H24/F24 -> #DIV/0! | J24: =IF(ISERROR(OR(ABS(H24)>=$F$8,ABS(I24)>=$F$9)),"",IF(AND(ABS(H24)>=$F$8,ABS(I24)>=$F$9),"O",IF(OR(ABS(H24)>=$F$8,ABS(I24)>=$F$9),"△","X")))
C25: 지분법적용투자주식 | E25: =D25/$D$30 -> #DIV/0! | G25: =F25/$F$30 -> #DIV/0! | H25: =+F25-D25 -> 0 | I25: =H25/F25 -> #DIV/0! | J25: =IF(ISERROR(OR(ABS(H25)>=$F$8,ABS(I25)>=$F$9)),"",IF(AND(ABS(H25)>=$F$8,ABS(I25)>=$F$9),"O",IF(OR(ABS(H25)>=$F$8,ABS(I25)>=$F$9),"△","X")))
C26: 기타 | E26: =D26/$D$30 -> #DIV/0! | G26: =F26/$F$30 -> #DIV/0! | H26: =+F26-D26 -> 0 | I26: =H26/F26 -> #DIV/0! | J26: =IF(ISERROR(OR(ABS(H26)>=$F$8,ABS(I26)>=$F$9)),"",IF(AND(ABS(H26)>=$F$8,ABS(I26)>=$F$9),"O",IF(OR(ABS(H26)>=$F$8,ABS(I26)>=$F$9),"△","X")))
B27: 유형자산 | E27: =D27/$D$30 -> #DIV/0! | G27: =F27/$F$30 -> #DIV/0! | H27: =+F27-D27 -> 0 | I27: =H27/F27 -> #DIV/0! | J27: =IF(ISERROR(OR(ABS(H27)>=$F$8,ABS(I27)>=$F$9)),"",IF(AND(ABS(H27)>=$F$8,ABS(I27)>=$F$9),"O",IF(OR(ABS(H27)>=$F$8,ABS(I27)>=$F$9),"△","X")))
B28: 무형자산 | E28: =D28/$D$30 -> #DIV/0! | G28: =F28/$F$30 -> #DIV/0! | H28: =+F28-D28 -> 0 | I28: =H28/F28 -> #DIV/0! | J28: =IF(ISERROR(OR(ABS(H28)>=$F$8,ABS(I28)>=$F$9)),"",IF(AND(ABS(H28)>=$F$8,ABS(I28)>=$F$9),"O",IF(OR(ABS(H28)>=$F$8,ABS(I28)>=$F$9),"△","X")))
B29: 기타비유동자산 | E29: =D29/$D$30 -> #DIV/0! | G29: =F29/$F$30 -> #DIV/0! | H29: =+F29-D29 -> 0 | I29: =H29/F29 -> #DIV/0! | J29: =IF(ISERROR(OR(ABS(H29)>=$F$8,ABS(I29)>=$F$9)),"",IF(AND(ABS(H29)>=$F$8,ABS(I29)>=$F$9),"O",IF(OR(ABS(H29)>=$F$8,ABS(I29)>=$F$9),"△","X")))
A30: 자산총계 | D30: =D15+D22 -> 0 | E30: =D30/$D$30 -> #DIV/0! | F30: =F15+F22 -> 0 | G30: =F30/$F$30 -> #DIV/0! | H30: =+F30-D30 -> 0 | I30: =H30/F30 -> #DIV/0!
A31: 유동부채 | D31: =SUM(D32:D38) -> 0 | E31: =D31/$D$63 -> #DIV/0! | F31: =SUM(F32:F38) -> 0 | G31: =F31/$F$63 -> #DIV/0! | H31: =+F31-D31 -> 0 | I31: =H31/F31 -> #DIV/0!
B32: 단기차입금 | E32: =D32/$D$63 -> #DIV/0! | G32: =F32/$F$63 -> #DIV/0! | H32: =+F32-D32 -> 0 | I32: =H32/F32 -> #DIV/0! | J32: =IF(ISERROR(OR(ABS(H32)>=$F$8,ABS(I32)>=$F$9)),"",IF(AND(ABS(H32)>=$F$8,ABS(I32)>=$F$9),"O",IF(OR(ABS(H32)>=$F$8,ABS(I32)>=$F$9),"△","X")))
B33: 매입채무 | E33: =D33/$D$63 -> #DIV/0! | G33: =F33/$F$63 -> #DIV/0! | H33: =+F33-D33 -> 0 | I33: =H33/F33 -> #DIV/0! | J33: =IF(ISERROR(OR(ABS(H33)>=$F$8,ABS(I33)>=$F$9)),"",IF(AND(ABS(H33)>=$F$8,ABS(I33)>=$F$9),"O",IF(OR(ABS(H33)>=$F$8,ABS(I33)>=$F$9),"△","X")))
B34: 미지급법인세 | E34: =D34/$D$63 -> #DIV/0! | G34: =F34/$F$63 -> #DIV/0! | H34: =+F34-D34 -> 0 | I34: =H34/F34 -> #DIV/0! | J34: =IF(ISERROR(OR(ABS(H34)>=$F$8,ABS(I34)>=$F$9)),"",IF(AND(ABS(H34)>=$F$8,ABS(I34)>=$F$9),"O",IF(OR(ABS(H34)>=$F$8,ABS(I34)>=$F$9),"△","X")))
B35: 이연법인세부채 | E35: =D35/$D$63 -> #DIV/0! | G35: =F35/$F$63 -> #DIV/0! | H35: =+F35-D35 -> 0 | I35: =H35/F35 -> #DIV/0! | J35: =IF(ISERROR(OR(ABS(H35)>=$F$8,ABS(I35)>=$F$9)),"",IF(AND(ABS(H35)>=$F$8,ABS(I35)>=$F$9),"O",IF(OR(ABS(H35)>=$F$8,ABS(I35)>=$F$9),"△","X")))
B36: 유동성장기부채 | E36: =D36/$D$63 -> #DIV/0! | G36: =F36/$F$63 -> #DIV/0! | H36: =+F36-D36 -> 0 | I36: =H36/F36 -> #DIV/0! | J36: =IF(ISERROR(OR(ABS(H36)>=$F$8,ABS(I36)>=$F$9)),"",IF(AND(ABS(H36)>=$F$8,ABS(I36)>=$F$9),"O",IF(OR(ABS(H36)>=$F$8,ABS(I36)>=$F$9),"△","X")))
B37: 연차수당부채 | E37: =D37/$D$63 -> #DIV/0! | G37: =F37/$F$63 -> #DIV/0! | H37: =+F37-D37 -> 0 | I37: =H37/F37 -> #DIV/0! | J37: =IF(ISERROR(OR(ABS(H37)>=$F$8,ABS(I37)>=$F$9)),"",IF(AND(ABS(H37)>=$F$8,ABS(I37)>=$F$9),"O",IF(OR(ABS(H37)>=$F$8,ABS(I37)>=$F$9),"△","X")))
B38: 기타 | E38: =D38/$D$63 -> #DIV/0! | G38: =F38/$F$63 -> #DIV/0! | H38: =+F38-D38 -> 0 | I38: =H38/F38 -> #DIV/0! | J38: =IF(ISERROR(OR(ABS(H38)>=$F$8,ABS(I38)>=$F$9)),"",IF(AND(ABS(H38)>=$F$8,ABS(I38)>=$F$9),"O",IF(OR(ABS(H38)>=$F$8,ABS(I38)>=$F$9),"△","X")))
A39: 비유동부채 | D39: =SUM(D40:D45) -> 0 | E39: =D39/$D$63 -> #DIV/0! | F39: =SUM(F40:F45) -> 0 | G39: =F39/$F$63 -> #DIV/0! | H39: =+F39-D39 -> 0 | I39: =H39/F39 -> #DIV/0!
B40: 사채 | E40: =D40/$D$63 -> #DIV/0! | G40: =F40/$F$63 -> #DIV/0! | H40: =+F40-D40 -> 0 | I40: =H40/F40 -> #DIV/0! | J40: =IF(ISERROR(OR(ABS(H40)>=$F$8,ABS(I40)>=$F$9)),"",IF(AND(ABS(H40)>=$F$8,ABS(I40)>=$F$9),"O",IF(OR(ABS(H40)>=$F$8,ABS(I40)>=$F$9),"△","X")))
B41: 장기차입금 | E41: =D41/$D$63 -> #DIV/0! | G41: =F41/$F$63 -> #DIV/0! | H41: =+F41-D41 -> 0 | I41: =H41/F41 -> #DIV/0! | J41: =IF(ISERROR(OR(ABS(H41)>=$F$8,ABS(I41)>=$F$9)),"",IF(AND(ABS(H41)>=$F$8,ABS(I41)>=$F$9),"O",IF(OR(ABS(H41)>=$F$8,ABS(I41)>=$F$9),"△","X")))
B42: 퇴직급여충당부채 | E42: =D42/$D$63 -> #DIV/0! | G42: =F42/$F$63 -> #DIV/0! | H42: =+F42-D42 -> 0 | I42: =H42/F42 -> #DIV/0! | J42: =IF(ISERROR(OR(ABS(H42)>=$F$8,ABS(I42)>=$F$9)),"",IF(AND(ABS(H42)>=$F$8,ABS(I42)>=$F$9),"O",IF(OR(ABS(H42)>=$F$8,ABS(I42)>=$F$9),"△","X")))
B43: 충당부채 | E43: =D43/$D$63 -> #DIV/0! | G43: =F43/$F$63 -> #DIV/0! | H43: =+F43-D43 -> 0 | I43: =H43/F43 -> #DIV/0! | J43: =IF(ISERROR(OR(ABS(H43)>=$F$8,ABS(I43)>=$F$9)),"",IF(AND(ABS(H43)>=$F$8,ABS(I43)>=$F$9),"O",IF(OR(ABS(H43)>=$F$8,ABS(I43)>=$F$9),"△","X")))
B44: 이연법인세부채 | E44: =D44/$D$63 -> #DIV/0! | G44: =F44/$F$63 -> #DIV/0! | H44: =+F44-D44 -> 0 | I44: =H44/F44 -> #DIV/0! | J44: =IF(ISERROR(OR(ABS(H44)>=$F$8,ABS(I44)>=$F$9)),"",IF(AND(ABS(H44)>=$F$8,ABS(I44)>=$F$9),"O",IF(OR(ABS(H44)>=$F$8,ABS(I44)>=$F$9),"△","X")))
B45: 기타 | E45: =D45/$D$63 -> #DIV/0! | G45: =F45/$F$63 -> #DIV/0! | H45: =+F45-D45 -> 0 | I45: =H45/F45 -> #DIV/0! | J45: =IF(ISERROR(OR(ABS(H45)>=$F$8,ABS(I45)>=$F$9)),"",IF(AND(ABS(H45)>=$F$8,ABS(I45)>=$F$9),"O",IF(OR(ABS(H45)>=$F$8,ABS(I45)>=$F$9),"△","X")))
...

Sheet 2131
A2: 2131 감사인측 전문가의 활용 (기준서 620)
A4: 회사명 | B4: ='2100'!B4 -> 0 | C4: 작성자 | D4: ='2100'!D4 -> 0 | E4: 일 자
A5: 결산일 | B5: ='2100'!B5 -> 0 | C5: 검토자 | D5: ='2100'!D5 -> 0 | E5: 일 자
D6: Yes
A7: 항 목 | D7: 조서번호 | E7: 수 행 자 | F7: 비 고
A8: (계획단계)
A9: 1. 감사인은 다음을 고려하여 감사인측 전문가를 활용한 감사절차의 성격, 시기 및 범위를 결정한다.
A10: (1) 전문가의 업무가 관련되는 사항의 성격
A11: (2) 전문가의 업무가 관련되는 사항에 있어서의 중요왜곡표시위험
A12: (3)감사와 관련해서 해당 전문가 업무가 가지는 유의성
A13: (4)전문가가 수행한 과거 업무에 대한 감사인의 지식과 경험
A14: (5)전문가가 당해 회계법인의 품질관리정책과 절차를 준수하는지 여부
A15: 2. 감사인측 전문가가 감사 목적에서 필요한 적격성, 역량 및 객관성을 갖추고 있는지 여부를 평가한다. 감사인측 외부 전문가의 경우, 전문가의 객관성을 훼손시킬 수 있는 이해관계에 대하여 질문한다.
A16: 3. 전문가 업무의 성격, 범위 및 목적을 결정하고 전문가 업무의 충분성을 평가하기 위해, 감사인측 전문가의 전문분야를 충분히 이해한다.
A17: 4. 적절한 경우 감사인측 전문가와 다음 사항을 문서로 합의한다.
A18: (1)전문가 업무의 성격, 범위 및 목적
A19: (2)감사팀과 전문가 각각의 역할과 책임
... A30: (2) 해당 상황에 적합한 추가적인 감사절차를 수행한다.

Sheet 2132
A2: 2132 내부감사의 활용 (기준서 610)
A4: 회사명 | B4: ='2100'!B4 -> 0 | C4: 작성자 | D4: ='2100'!D4 -> 0 | E4: 일자
A5: 결산일 | B5: ='2100'!B5 -> 0 | C5: 검토자 | D5: ='2100'!D5 -> 0 | E5: 일자
A7: 항 목 | D7: 조서번호 | E7: 수 행 자 | F7: 비 고
A8: (계획단계)
A9: 1. 다음을 평가하여 내부감사의 업무가 감사 목적상 적절할 것인지 여부를 판단하고 문서화한다.
A10: (1) 내부감사기능이 갖는 책임의 성격 및 내부감사기능이 회사의 조직구조상 어떻게 자리잡고 있는지
A11: (2) 내부감사기능이 수행한 또는 수행할 활동
A12: (3)내부감사기능의 목적
A13: (4)내부감사의 기술적인 능력
A14: (5)내부감사가 필요한 전문가적 주의를 기울여 업무를 수행할 것인지 여부
A15: (6)내부감사와 감사팀 간에 효과적인 커뮤니케이션이 이루어질 수 있을지 여부
A16: 2. 다음을 고려하여 내부감사의 업무가 우리가 수행하는 절차의 성격, 시기 또는 범위의 계획에 미치는 영향을 판단하고 이를 문서화한다.
A17: (1) 내부감사에 의해 수행되었거나 수행될 예정인 특정 업무의 성격과 범위
A18: (2) 특정 거래 유형, 계정 잔액 및 공시에 대하여 경영진 주장 수준에서 평가된 중요왜곡표시위험
A19: (3) 관련 경영진 주장을 뒷받침하기 위해 내부감사가 수집한 감사 증거에 대한 평가에 관여된 주관성의 정도
... A34: 4. 내부감사업무에서 식별된 미비점이 있다면 내부통제 미비점으로 문서화한다. 내부 통제의 미비점, 부정 또는 재무제표의 왜곡표시 등 내부감사인이 식별한 유의한 회계 및 감사상의 모든 이슈가 계획된 감사 절차와 결론에 미치는 영향을 평가하고 문서화한다.

Sheet 2133
A2: 2133 서비스조직의 활용 (기준서 402)
A4: 회사명 | B4: ='2100'!B4 -> 0 | C4: 작성자 | D4: ='2100'!D4 -> 0 | E4: 일자
A5: 결산일 | B5: ='2100'!B5 -> 0 | C5: 검토자 | D5: ='2100'!D5 -> 0 | E5: 일자
A7: 항 목 | D7: 조서번호 | E7: 수 행 자 | F7: 비 고
A8: (계획단계)
A9: 1. 감사인은 이용자기업이 자신의 사업에 서비스조직의 서비스를 어떻게 이용하는지를 이해하여야 하며, 이에는 다음과 같은 내용이 포함되어야 한다.
A10: (1)이용자기업의 내부통제에 대한 영향 등 서비스조직이 제공하는 서비스의 성격과 그러한 서비스가 이용자기업에 미치는 유의성
A11: (2)서비스조직이 처리한 거래 또는 동 조직에 의해 영향을 받는 계정이나 재무보고절차의 성격과 중요성
A12: (3)서비스조직이 수행하는 활동과 이용자기업이 수행하는 활동의 상호작용 정도
A13: (4)서비스조직이 수행하는 활동에 대한 관련 계약조건 등 이용자기업과 서비스조직간 관계의 성격
A14: 2. 감사와 관련된 내부통제를 이해할 때, 서비스조직이 처리한 거래에 적용되는 통제 등 서비스조직이 제공한 서비스와 관련된 이용자기업의 관련 통제의 설계 및 실행을 평가하여야 한다.
A15: 3. 이용자기업 감사인은 중요왜곡표시위험의 식별과 평가의 근거를 제공하기 위하여, 서비스조직에 의해 제공된 서비스의 성격과 유의성 그리고 그러한 서비스가 이용자기업의 감사와 관련된 내부통제에 미치는 영향을 충분히 이해하였는지 결정하여야 한다.
A16: 4. 이용자기업 감사인이 이용자기업으로부터 충분한 이해를 얻을 수 없는 경우, 이용자기업 감사인은 다음 중 하나 이상의 절차를 통하여 이를 충분히 이해하여야 한다.
A17: (1) 입수가능한 경우, 유형 1 보고서 또는 유형 2 보고서를 입수
A18: (2) 특정 정보를 얻기 위하여 이용자기업을 통하여 서비스조직과 접촉
A19: (3)서비스조직을 방문하여 서비스조직의 관련 통제에 대해 필요한 정보를 제공할 절차를 수행
... A46: 3. 서비스조직의 감사인이 수행한 업무를 언급하는 것이 이용자기업 감사인의 변형의견을 이해시키는 것과 관련된다면, 이용자기업 감사보고서에는 그러한 언급이 동 변형의견에 대한 이용자기업 감사인의 책임을 경감시키지 아니함을 명시하여야 한다.

Sheet 2301
A2: 2301 감사위험의 평가 (기준서 315)
C3: (재무제표 수준)
A5: 회사명 | B5: ='2100'!B4 -> 0 | C5: 작성자 | D5: ='2100'!D4 -> 0 | E5: 일 자
A6: 결산일 | B6: ='2100'!B5 -> 0 | C6: 검토자 | D6: ='2100'!D5 -> 0 | E6: 일 자
A8: 구분(*1) | C8: 유의적 위험여부 (*2) (Y/N) | D8: 유의적위험 판단근거(*2) | G8: 기타 (*3)
D10: 왜곡표시의 성격 | E10: 왜곡표시 금액의 중요성 | F10: 왜곡표시 발생 가능성
A12: Ⅰ. 전체재무제표 수준에서의 왜곡표시위험 평가
A13: 1. 부정으로 인한 전체재무제표 왜곡표시위험
A14: 2. 회사의 계속기업으로서의 존속가능성에 관한 의문이 제기되는 경우
A15: 3. 특수관계자 거래가 적절하게 회계처리 및 공시되지 않을 위험
A16: 4. 법률과 규정의 미준수 사례가 존재할 위험
A17: 5. 기타사항
A18: [구체적으로 기술함]
A20: 구분(*1) | C20: 유의적 | D20: 유의적위험 판단근거(*2) | G20: 기타
C21: 위험여부 | G21: (*3)
C22: (*2)
C23: (Y/N) | D23: 왜곡표시의 성격 | E23: 왜곡표시금액의 중요성 | F23: 왜곡표시 발생가능성
A24: Ⅰ. 전체재무제표 수준에서의 왜곡표시위험 평가
A25: 1. 부정으로 인한 전체재무제표 왜곡표시위험 | C25: Y | D25: 상 | E25: 상 | F25: 하
A26: 2. 회사의 계속기업으로서의 존속가능성에 관한 의문이 제기되는 경우 | C26: N | D26: 상 | E26: 상 | F26: 하
A27: 3. 특수관계자 거래가 적절하게 회계처리 및 공시되지 않을 위험 | C27: Y | D27: 상 | E27: 상 | F27: 상
A28: 4. 법률과 규정의 미준수 사례가 존재할 위험 | C28: N | D28: 상 | E28: 상 | F28: 하
A29: 5. 기타사항 | C29: N/A
A30: [구체적으로 기술함]

Sheet 2302
A2: 2302 감사위험의 평가 (기준서 315)
A3: (경영진 주장 수준)
A5: 회사명 | C5: 0 | F5: 작성자 | G5: 0 | H5: 일자
A6: 결산일 | C6: 0 | F6: 검토자 | G6: 0 | H6: 일자
A9: 계정과목(*1) | B9: 유의적위험(Y/N) | C9: 유의적 위험 판단근거(*2) | I9: 유의적위험 내용(*3) | J9: 조서번호
C10: 1 | D10: 2 | E10: 3 | F10: 4 | G10: 5 | H10: 6 | J10: (*4)
A18: 계정과목(*1) | B18: 유의적위험(Y/N) | C18: 유의적 위험판단근거(*2) | I18: 유의적위험 내용(*3) | K18: 조서번호
C19: 1 | D19: 2 | E19: 3 | F19: 4 | G19: 5 | H19: 6 | K19: (*4)
A20: 현금성자산 | B20: N | C20: 하 | D20: 하 | E20: 하 | F20: 하 | G20: 하 | H20: 하 | I20: 일반적인 위험 | K20: xxx-xxxx
A21: 장단기금융상품 | B21: N | C21: 하 | D21: 하 | E21: 하 | F21: 하 | G21: 하 | H21: 하 | I21: 일반적인 위험 | K21: xxx-xxxx
A22: 차입금 | B22: N | C22: 하 | D22: 하 | E22: 하 | F22: 하 | G22: 하 | H22: 하 | I22: 일반적인 위험 | K22: xxx-xxxx
A23: 이자수익 | B23: N | C23: 하 | D23: 하 | E23: 하 | F23: 하 | G23: 하 | H23: 하 | I23: 일반적인 위험 | K23: xxx-xxxx
A24: 이자비용 | B24: N | C24: 하 | D24: 하 | E24: 하 | F24: 하 | G24: 하 | H24: 하 | I24: 일반적인 위험 | K24: xxx-xxxx
A25: 판매비와관리비 | B25: N | C25: 하 | D25: 하 | E25: 하 | F25: 하 | G25: 하 | H25: 하 | I25: 일반적인 위험 | K25: xxx-xxxx
A26: 매출 | B26: Y | C26: 하 | D26: 하 | E26: 하 | F26: 하 | G26: 상 | H26: 상 | I26: 외부이해관계자는 회사의 매출액 성장율에 관심이 많음. 따라서 특별한 반증이 없는 한 매출액 과대계상위험은 존재함 | K26: xxx-xxxx
I27: 기말결산 일 근처 매출과대계상이 높으므로 매출액의 기간귀속이 유의적 위험이라고 판단함.
A28: 매출채권 | B28: N | C28: 하 | D28: 하 | E28: 하 | F28: 하 | G28: 하 | H28: 하 | I28: 일반적인 위험 | K28: xxx-xxxx
A29: 대손상각비 | B29: N | C29: 하 | D29: 하 | E29: 하 | F29: 하 | G29: 하 | H29: 하 | I29: 일반적인 위험 | K29: xxx-xxxx
A30: 반품충당부채 | B30: N | C30: 하 | D30: 하 | E30: 하 | F30: 하 | G30: 하 | H30: 하 | I30: 일반적인 위험 | K30: xxx-xxxx
A31: 재고자산 | B31: N | C31: 하 | D31: 하 | E31: 하 | F31: 상 | G31: 상 | H31: 중 | I31: 신기술개발로 인한 단종재고에 대한 저가평가를 하지 않을 위험이 제기됨. 재고자산의 평가가 유의적 위험임. | K31: xxx-xxxx
A32: 매입채무 | B32: N | C32: 하 | D32: 하 | E32: 하 | F32: 하 | G32: 하 | H32: 하 | I32: 일반적인 위험 | K32: xxx-xxxx
A33: 미지급금 | B33: N | C33: 하 | D33: 하 | E33: 하 | F33: 하 | G33: 하 | H33: 하 | I33: 일반적인 위험 | K33: xxx-xxxx
A34: 매출원가 | B34: N | C34: 하 | D34: 하 | E34: 하 | F34: 하 | G34: 하 | H34: 하 | I34: 일반적인 위험 | K34: xxx-xxxx
A35: 유형자산 | B35: Y | C35: 하 | D35: 하 | E35: 하 | F35: 상 | G35: 상 | H35: 중 | I35: 단종모델을 생산하는 유형자산의 범용성이 낮으므로 손상의 가능성이 제기됨. | K35: xxx-xxxx
I36: 유형자산의 평가가 유의적 위험임.
A37: 무형자산 | B37: Y | C37: 하 | D37: 하 | E37: 하 | F37: 상 | G37: 상 | H37: 중 | I37: 단종모델의 개발비에 대한 손상가능성 | K37: xxx-xxxx
I38: 무형자산의 평가가 유의적 위험임.
A39: 감가상각비 | B39: N | C39: 하 | D39: 하 | E39: 하 | F39: 하 | G39: 하 | H39: 하 | I39: 일반적인 위험 | K39: xxx-xxxx
A40: 처분손익 | B40: N | C40: 하 | D40: 하 | E40: 하 | F40: 하 | G40: 하 | H40: 하 | I40: 일반적인 위험 | K40: xxx-xxxx
A41: 급여 | B41: N | C41: 하 | D41: 하 | E41: 하 | F41: 하 | G41: 하 | H41: 하 | I41: 일반적인 위험 | K41: xxx-xxxx
A42: 퇴직급여부채 | B42: N | C42: 하 | D42: 하 | E42: 하 | F42: 하 | G42: 하 | H42: 하 | I42: 일반적인 위험 | K42: xxx-xxxx
A43: 미지급법인세 | B43: N | C43: 하 | D43: 하 | E43: 하 | F43: 하 | G43: 하 | H43: 하 | I43: 일반적인 위험 | K43: xxx-xxxx
A44: 이연법인세자산 | B44: N | C44: 하 | D44: 하 | E44: 하 | F44: 하 | G44: 하 | H44: 하 | I44: 일반적인 위험 | K44: xxx-xxxx
A45: 법인세비용 | B45: N | C45: 하 | D45: 하 | E45: 하 | F45: 하 | G45: 하 | H45: 하 | I45: 일반적인 위험 | K45: xxx-xxxx
A47: [참고자료]
A48: 각 계정과목별로 발생할 수 있는 왜곡표시위험을 사례를 제시함.
A49: 경영진 주장 :
A50: A | C50: : 정확성(Accuracy) | E50: E | F50: : 실재성(Existence) | H50: RO | J50: : 권리와 의무(Rights and obligations)
A51: C | C51: : 완전성(Completeness) | E51: O | F51: : 발생사실(Occurrence) | H51: CL | J51: : 분류(Classification)
A52: CO | C52: : 기간귀속(Cutoff) | E52: V | F52: : 평가(Valuation) | H52: U | J52: : 이해가능성(Understandability)
...

Sheet 2511
A2: 2511 통 제 환 경 이 해 와 평 가 (기준서 315)
A5: 회사명 | B5: ='2100'!B4 -> 0 | E5: 작성자 | F5: ='2100'!D4 -> 0 | G5: 일자
A6: 결산일 | B6: ='2100'!B5 -> 0 | E6: 검토자 | F6: ='2100'!D5 -> 0 | G6: 일자
A9: 고려요소 | D9: 통제환경의 핵심요소(*1) | G9: 평가결과(*2) | J9: 관련조서번호
G10: 양호 | H10: 미흡 | I10: N/A | J10: (*3)
A11: 1. 정직성과 윤리적 가치에 대한 커뮤니케이션과 실천 <주요고려요소> - 업계에서의 경영자의 평판 - 회사의 윤리강령 존재 및 이를 교육 전파 여부 | D11: [ ] | E11: 경영진의 부정적인 의심을 고려할 사항이 발견되지 아니함.
D12: [ ] | E12: 윤리규정이 문서화 되어 있으며 주기적으로 교육을 실시한다.
D13: [ ] | E13: 문서화된 윤리규정은 존재하지 않으나 경영진이 경영과정에서 실천하는 행동 및 태도를 통하여 윤리경영을 실행하고 있다.
D14: [ ] | E14: 기타 [구체적 설명]
A15: 2. 적격성의 구비 <주요고려요소> - 회사의 임직원들이 업무수행을 위하여 요구되는 지식, 기술 및 정직성에 대한 판단 | D15: [ ] | E15: 회사의 임직원들은 업무수행을 위하여 요구되는 지식, 기술 및 정직성을 갖추고 있는 것으로 판단됨.
D16: [ ] | E16: 기타 [구체적 설명]
A17: 3. 지배기구의 참여 <주요고려요소> - 이사회 및 감사의 조직 및 자율성 - 이사회, 감사와 외부감사인 간의 의사소통 - 이사, 감사의 자질과 경험의 정도 - 회의 소집 횟수와 업무처리 내용 | E17: [구체적 설명]
A22: 4. 경영진의 철학과 경영방식 <주요고려요소> - 사업상의 위험을 관리하는 경영자의 자세 - 재무보고에 관한 경영자의 태도 - 계획과 실적을 비교, 보고하는 제도유무와 효율성 - 보고된 차이에 대응하는 경영자의 자세 - 정보처리기능 , 회계기능 및 회계인원에 대한 태도 | E22: [구체적 설명]
A29: 5. 조직구조 <주요고려요소> -회사의 규모,영업활동,위치에 따른 조직구조의 적정성 - 정보처리과정에서의 거래의 입력이나 변경 자료보관에 관한 조직부서간 권한 분담의 적정성 - 상충되는 기능의 적절한 분리 | D29: [ ] | E29: 회사 영업의 규모 및 복잡성을 고려하여 적절한 업무분장이 이루어지고 있다.
D30: [ ] | E30: 경영진이 밀접하게 관여를 하고 있어 부정확한 금액을 쉽게 식별할 수 있다. 이러한 밀접한 관여로 인하여 직원들은 보다 많은 주의를 기울인다.
A32: 6. 권한과 책임의 할당 <주요고려요소> - 직무규정, 이해조정, 행동규범에 대한 방침 - 조직목표, 업무수행 기능, 기타 규정 등을 다루는 권한과 책임의 부여 - 직무, 보고체계 및 업무관계에 대한 구체적인 기술서 유무 | D32: [ ] | E32: 회사의 조직은 단순하며 권한은 각 임직원들에게 배정되어 있다. 회사의 규모와 성격을 고려할 경우 적절하다고 판단됨.
D33: [ ] | E33: 기타 [구체적 설명]
A35: 7. 인적자원에 대한 정책과 실무 <주요고려요소> - 직원의 채용, 훈련, 동기부여, 평가, 승진 등에 관한 기준과 절차 - 직무를 명확히 한 문서화된 직무기술서와 업무설명서 | D35: [구체적 설명]
A39: 8. 기타(*4) | D39: [구체적 설명]

Sheet 2512
A2: 2512 위 험 평 가 절 차 이 해 와 평 가 (기준서 315)
A4: 회사명 | B4: ='2100'!B4 -> 0 | E4: 작성자 | F4: ='2100'!D4 -> 0 | G4: 일자
A5: 결산일 | B5: ='2100'!B5 -> 0 | E5: 검토자 | F5: ='2100'!D5 -> 0 | G5: 일자
A7: 고려요소 | C7: 위험평가절차의 핵심요소(*1) | F7: 평가결과(*2) | I7: 관련조서번호
F8: 양호 | G8: 미흡 | H8: N/A | I8: (*3)
A9: 1. 전사적 목표의 설정 <주요 고려요소> - 전사 목표의 수립 여부 - 전사 목표에 달성하기 위한 방안 수립 여부 - 전사 목표 달성하지 못할 위험요인 분석 여부 - 전사 목표와 사업위험에 근거하여 수정 보완 여부 | C9: 회사의 위험평가절차는 다음과 같은 특징을 가지고 있음.
C10: [ ] | D10: 연간 목표가 수립되고 경영진이 수립한 예산이 설정이 되어있음. 예산 대비 실제 금액에 대한 검토를 주기적으로 수행 한다. 이러한 검토는 수립된 목표를 정기적으로 검토할 수 있도록 해주고 비경상적이거나 예상치 않은 보고 금액을 식별할 수 있도록 해준다.
C11: [ ] | D11: 경영진은 월별/분기/반기 등 일정한 주기로 재무정보에 대한 검토 , 검증 및 분석을 수행하고 있으며 오류 및 비경상적인 보고금액을 식별 대응한다.
C12: [ ] | D12: 기타
C13: [ ] | D13: [구체적 설명]
C14: [ ] | D14: 경영진은 전사적 목표를 수립한 바 없음.
A15: 2. 주요 환경변화에 따른 경영진의 위험평가 분석 절차 재무적영향이 있으며 감사전략에 영향을 미칠 것으로 예상되는 환경변화를 경영진이 모두 식별하여 대응하는가?(경영진이 파악하지 못하는 재무보고 목적과 관련된 위험이 존재하는지 유무) <주요 환경변화요소> - 사업환경의 변화 : 규제 또는 영업환경의 변화는 경쟁상 압력의 변화 및 유의적으로 상이한 위험을 초래할 수 있다. - 신규인력: 신규인력은 내부통제에 대해 다른 관점을 가지거나 내부통제를 다르게 이해할 수 있다. - 신규 또는 개편되는 정보시스템 - 급속한 성장 - 새로운 기술 - 새로운 사업모델,제품 또는 활동 - 기업 구조조정 - 해외사업의 확장 - 새로운 회계기준 공표 | C15: [ ] | D15: 추가적으로 식별된 위험은 없음.
C16: [ ] | D16: 감사전략에 영향을 미칠 수 있는 것으로 경영진이 식별하지 못한 환경변화가 존재함
C17: [ ] | D17: [관련 위험의 설명을 기재]
A18: 3. 기타(*4) | C18: [ ] | D18: 기타
D19: [구체적 설명]

Sheet 2513
A2: 2513 통 제 의 모 니 터 링 이 해 와 평 가 (기준서 315)
A4: 회사명 | B4: ='2100'!B4 -> 0 | E4: 작성자 | F4: ='2100'!D4 -> 0 | G4: 일자
A5: 결산일 | B5: ='2100'!B5 -> 0 | E5: 검토자 | F5: ='2100'!D5 -> 0 | G5: 일자
A8: 고려요소 | C8: 통제활동의 모니터링의 핵심요소(*1) | F8: 평가결과(*2) | I8: 관련조서번호
F9: 양호 | G9: 미흡 | H9: N/A | I9: (*3)
A10: 1. 지속적인 모니터링 활동여부 <고려요소> - 업무수행과정에서 중간관리자 등이 직원들의 업무 수행을 검토 확인여부 | C10: 회사의 절차는 다음과 같은 특징을 가지고 있음.
C12: [ ] | D12: 각 기능별 또는 조직별 중간관리자는 정기적으로 각 기능별 활동별 성과보고서를 검토한다. 이러한 검토는 경영진의 검토보다 상세한 수준에서 더 짧은 주기로 수행한다.
C13: [ ] | D13: 중요한 결제문서 등에는 해당정보의 원천자료등 과 대사하는 절차를 수행한다.
C14: [ ] | D14: 경영진이 사업의 운영에 밀접하게 관여하고 있어 재무자료에서의 오류식별을 용이하게 한다.
C15: [ ] | D15: 기타
D16: [구체적 설명]
A17: 2. 정기적인 모니터링 < 주요고려요소> - 내부감사부서의 지속적인 활동여부 - 내부회계관리제도 활용 여부 | C17: [ ] | D17: 정기적인 감사를 수행하고 예외사항에 대하여는 적절하게 사후조치가 이루어진다.
C18: [ ] | D18: 내부회계관리제도를 활용하여 주기적 평가를 수행하며 예외사항에 대하여는 사후조치가 이루어진다.
C20: [ ] | D20: 경영진은 감사결과(외부감사포함)를 받아들여 재발방지를 위한 내부통제제도 강화하기 위한 노력을 한다.
C21: [ ] | D21: 적절한 기록을 확인하기 위한 정기적인 자산실사
C22: [ ] | D22: 기타
D23: [구체적 설명]
A24: 3. 경영성과의 검토 <주요고려요소> - 예산 대비 실적분석을 통한 내부통제 효과성분석여부 | D24: 예산대비 실적 검토 등이 주기적으로 수행하며 예외사항 및 비경상적인 사항에 대하여는 사후조치를 수행한다.
C25: [ ]
A27: 4. 기타사항 | C27: [ ] | D27: 기타
D28: [구체적 설명]

Sheet 2520
A2: 2520 재무보고 관련 정보시스템 및 커뮤니케이션에 대한 이해 (기준서 315)
A4: 회사명 | B4: 0 | C4: 작성자 | D4: 0 | E4: 일자
A5: 결산일 | B5: 0 | C5: 검토자 | D5: 0 | E5: 일자
A7: 항 목 | D7: 조서번호 | E7: 수 행 자 | F7: 비 고
A8: 1.다음 사항을 포함하여 관련 사업프로세스 등 재무보고에 관련된 정보시스템을 이해한다. (재무보고에 대한 정보시스템의 이해에는 재무제표에 공시되는 총계정원장과 보조원장 내에서 또는 외부에서 입수한 정보에 대한 정보시스템의 관련 측면을 포함)
A9: (1)기업의 경영활동에서 재무제표에 유의적인 거래유형 | D9: 2531
A10: (2)정보기술 및 수작업시스템 내에서 거래가 개시, 기록, 처리되고, 필요한 수정이 이루어져 총계정원장으로 전기되고 재무제표에 보고되는 절차 | D10: 2531A
A11: (3)거래의 개시, 기록, 처리, 보고에 이용되는 관련 회계기록과 증빙 그리고 재무제표 내의 특정 계정(부정확한 정보의 수정과 정보가 총계정원장으로 전기되는 방법 포함) | D11: 2531A
A12: (4)정보시스템이 제반 거래 외에도 재무제표에 유의적인 사건과 상황을 포착하는 방법 | D12: 2531A
A13: (5)유의적 회계추정과 공시 등 기업의 재무제표 작성에 이용되는 재무보고절차 | D13: 2531A
A14: (6)비반복적이고 비경상적인 거래 또는 조정사항을 기록할 때 이용되는 비표준적인 분개 등 분개를 둘러싼 통제 | D14: 2531A
A15: 2. 다음 사항들을 포함하여 기업이 재무보고의 역할과 책임 및 재무보고와 관련된 유의적 사항들을 어떻게 커뮤니케이션하는지 이해한다.
A16: (a) 경영진과 지배기구간의 커뮤니케이션 (b) 규제기관과 같은 외부와의 커뮤니케이션

Sheet 2530
A2: 2530 감사에 관련된 통제활동의 이해 (기준서 315, 265)
A4: 회사명 | B4: 0 | C4: 작성자 | D4: 0 | E4: 일자
A5: 결산일 | B5: 0 | C5: 검토자 | D5: 0 | E5: 일자
A7: 항 목 | D7: 조서번호 | E7: 수 행 자 | F7: 비 고
A8: 1.감사에 관련성이 있는 통제활동을 이해한다. 즉 해당 기업의 관련자들에 대한 질문 외에 추가적인 절차를 수행함으로써 이러한 통제의 설계를 평가하고, 또 통제가 실제로 실행되고 있는지 여부를 결정한다. | D8: 2531
A9: 다음과 같은 통제는 감사에 관련성이 있다. ① 유의적 위험으로 식별된 위험과 관련된 통제활동 ② 실증절차만으로는 충분하고 적합한 감사증거를 입수하는 것이 실무적으로 불가능한 위험이 있는 경우, 그 위험에 대한 통제활동 ③ 비반복적이고 비경상적인 거래 또는 조정사항을 기록할 때 이용되는 비표준적인 분개 등 분개를 둘러싼 통제 ④ 통제활동이 효과적으로 운용될 것으로 기대하고 실증절차의 성격, 시기, 범위를 결정할 때 통제의 운영효과성에 의존하려고 하는 경우 (즉 중요왜곡표시위험을 평가할 때 통제위험이 낮다고 평가한 경우) 재무제표에 유의적인 각 거래유형, 계정잔액 및 공시 또는 이들과 관련된 모든 경영진주장에 대하여 그 모든 통제활동을 이해할 것을 요구하지는 아니한다.
A10: 2. 기업의 통제활동을 이해할 때 기업이 정보기술로부터 발생하는 위험에 대하여 어떻게 대응해 왔는지 이해한다. | D10: 2532
A11: 3. 하나 이상의 내부통제 미비점을 식별한 경우, 다음 절차를 수행한다.
A12: (1)식별된 내부통제 미비점이 개별적으로 혹은 결합하여 유의적 미비점을 형성하는지 여부를 결정한다. | D12: 2531
A13: (2)식별된 유의적 내부통제 미비점들을 지배기구에게 적시에 서면으로 커뮤니케이션한다.
A14: (3)적합한 수준의 책임을 가진 경영진에게 다음과 같은 사항들을 적시에 커뮤니케이션한다. (a) (해당 상황에서 경영진에게 직접 커뮤니케이션하는 것이 부적합하지 않는 한), 유의적 내부통제 미비점들을 경영진과 서면으로 커뮤니케이션함 (b) 감사 중에 식별된 내부통제의 기타 미비점들로서 다른 관계자가 경영진에게 커뮤니케이션하지 않았고, 감사인의 전문가적 판단에 따라, 경영진이 주의를 기울일 만큼 충분한 중요성이 있다고 판단되는 미비점들을 경영진과 커뮤니케이션함

Sheet 2531
A2: 2531 통제활동의 이해와 평가 및 내부통제 미비점 식별: 통제 test (기준서 330)
A4: 회사명 | B4: 0 | C4: 작성자 | D4: 0 | E4: 일자
A5: 결산일 | B5: 0 | C5: 검토자 | D5: 0 | E5: 일자
A8: 관련위험 (*1) | B8: 통 제 절 차(*2) | C8: 통제활동의 이해 및 평가 조서번호 (*3) | D8: 통제테스트 조서번호 (*4) | E8: 실증절차에 대한 영향 (*5)
A19: 관련위험 | B19: 통 제 절 차(*2) | C19: 통제활동 | D19: 통제테스트 | E19: 실증절차에 대한 영향
A20: (*1) | C20: 이해 및 평가 | D20: 조서번호
C21: 조서번호 | D21: (*4)
C22: (*3)
A23: 부정으로 인한 전체재무제표 왜곡표시위험 | B23: 부정위험과 관련된 회사 통제절차 요약 | C23: xxx-xxx | D23: NA | E23: 통제활동에 대한 테스트를 수행하지 않으므로 실증절차를 확대 실시함
A24: 특수관계자 거래가 적절하게 회계처리 및 공시되지 않을 위험 | B24: 특수관계자와 관련된 회사의 통제절차 요약 | C24: xxx-xxx | D24: xxx-xxx | E24: 통제양호하므로 세부테스트시 샘플범위를 축소함
A25: (모든 경영진주장)
A26: 매출액 | B26: 기간귀속과 관련된 회사의 매출통제활동요약 | C26: xxx-xxx | D26: xxx-xxx | E26: 통제양호하므로 세부테스트시 샘플범위를 축소함
A27: (기간귀속)
A28: 매출액 | B28: 관련 회사의 매출통제활동 요약 | C28: xxx-xxx | D28: xxx-xxx | E28: 통제양호하므로 세부테스트시 샘플범위를 축소함
A29: (발생사실 등)
A30: 매출채권 | B30: 관련 회사의 매출통제활동 요약 | C30: xxx-xxx | D30: xxx-xxx | E30: 통제양호하므로 세부테스트시 샘플범위를 축소함
A31: (실재성 등)
A32: 반품충당부채 | B32: 관련 회사의 매출통제활동 요약 | C32: xxx-xxx | D32: xxx-xxx | E32: 통제양호하므로 세부테스트시 샘플범위를 축소함
A33: (완전성 등)
A34: 재고자산 | B34: 관련 회사의 재고자산통제활동 요약 | C34: xxx-xxx | D34: xxx-xxx | E34: 통제양호하므로 세부테스트시 샘플범위를 축소함
A35: (실재성 등)
A36: 매입채무 | B36: 관련 회사의 매입통제활동 요약 | C36: xxx-xxx | D36: xxx-xxx | E36: 통제양호하므로 세부테스트시 샘플범위를 축소함
A37: (완전성 등)
A38: 매출원가 | B38: 관련 회사의 매입통제활동 요약 | C38: xxx-xxx | D38: xxx-xxx | E38: 통제양호하므로 세부테스트시 샘플범위를 축소함
A39: (발생사실 등)
A40: 유형자산 | B40: 관련 회사의 유형자산통제활동 요약 | C40: xxx-xxx | D40: NA | E40: 회사의 통제활동에 대한 테스트를 수행하지 않으므르 실증절차만을 수행함.
A41: (평가)
A42: 유형자산 | B42: 관련 회사의 유형자산통제활동 요약 | C42: xxx-xxx | D42: xxx-xxx | E42: 통제양호하므로 세부테스트시 샘플범위를 축소함
A43: (실재성)
A44: 무형자산 | B44: 관련 회사의 무형자산통제활동 요약 | C44: xxx-xxx | D44: NA | E44: 회사의 통제활동에 대한 테스트를 수행하지 않으므르 실증절차만을 수행함.
A45: (평가)
A46: 급여 | B46: 관련 회사의 급여통제활동 요약 | C46: xxx-xxx | D46: xxx-xxx | E46: 통제양호하므로 세부테스트시 샘플범위를 축소함
A47: (발생사실 등)
A48: 퇴직급여부채 | B48: 관련 회사의 급여통제활동 요약 | C48: xxx-xxx | D48: xxx-xxx | E48: 통제양호하므로 세부테스트시 샘플범위를 축소함
A49: (정확성 등)
A52: (매출 및 매출채권 관련 내부통제활동)
A53: 통 제 목 적 | C53: 통 제 절 차
A54: 1.발생한 매출거 래는 모두 기록 된다.(완전성) | C54: 출하서류(주문서, 거래명세서)없이는 출고될 수 없다.
C55: 거래명세서는 일련번호가 부여되어 출력된다.
C56: 모든 주문서에 대한 거래명세서가 작성되었는지 확인한다.
...

Sheet 2531A
A1: 2531A-P 추적조사(매입)
B3: 회사명 | D3: 작성자 | F3: 일자
B4: 결산일 | D4: 검토자 | F4: 일자
B7: 유의적인 거래 유형과 관련 계정
B8: 거래 유형 | C8: 원재료 매입
B9: 관련 재무제표 계정 | C9: 재고자산(원재료), 매입채무
B11: 1. 거래가 개시, 기록, 처리, 보고되는 (관련 회계기록과 증빙 포함) 절차를 기술한다.
B12: 1. 발주 요청: 생산팀 생산계획 담당자는 생산계획에 따라 추가 매입이 필요한 원재료의 원재료구매요청서를 작성한다. 원재료구매요청서는 생산팀장의 승인을 받은 후 구매팀에 송부한다. 2. 발주: 구매팀 담당자는 원재료구매요청서에 따라 ERP상에 품목, 수량, 단가를 입력하고 발주서를 생성한다. 생성된 발주서는 전결 규정에 따라 구매팀장, 생산·구매 담당 임원, 대표이사(XXX원 이상)의 승인을 받은 후 공급처에 송부한다. 3. 입고 : 물품이 입고되면 물류팀 원료창고 담당자가 인수하여 검수 후 입고전표를 작성한다. 입고전표상 수량은 검수 수량, 단가는 거래명세표상 단가를 입력한다. 입고전표는 물류팀장의 결재를 받은 후 ERP상 매입장에 등록한다. 4. 인수 확인: 구매팀 담당자는 ERP상에서 입고 내역을 발주서 및 거래명세표(세금계산서)와 비교, 검토한다. 입고전표는 재무회계팀에 회람하며 재무회계팀장까지 결재한다. 5. 청구 : 세금계산서 및 거래명세서는 원료창고 담당자가 창고에서 수령하여 구매팀 담당자의 검토를 받은 후 재무회계팀에 송부한다. 재무회계팀 담당자는 발주서, 입고전표, 거래명세표(세금계산서)를 대조 확인한다. 6. 채무계상 : 재무회계팀 담당자는 위와 같은 대조 확인 후 회계전표(재고자산/매입채무 계상)를 생성한다. 회계전표는 입고전표를 선택하면 ERP 상에서 자동 생성된다. 생성된 회계전표는 재무회계팀장의 승인을 받은 후 총계장원장으로 전기한다. 5. 월말 검토 : 매월말 재무회계팀 결산담당자는 외상대 결제액 집계표를 작성한다. 집계표는 원재료구매요청서를 기초로 발주 내역을 집계하여 ERP상 발주내역과 대조하고 생산팀, 구매팀 각 담당자에 회람하여 승인 받는다. 이후 발주내역과 입고전표를 1:1로 대조하여 수량 및 단가가 변동된 발주 건을 별도 집계한 후 생산·구매 담당 임원과 대표이사의 승인을 받는다.
B14: 2. 거래 흐름을 이해하기 위해 수행한 절차를 기술한다. * 통제활동에 대한 이해를 수행하는 경우, 해당 통제활동을 포함하여 추적조사를 수행한다. (통제활동의 성격과 설계 및 실행 테스트 결과는 아래 3.에 기술)
B15: 추적조사 대상 거래: | C15: 202X년 1월~10월 매입장에서 임의 추출한 X월 XX일 XXX 매입 건
B16: 수행한 절차 | E16: 입수한 증거 | F16: 증빙조서번호 | G16: 통제활동번호
B17: (1) 원재료구매요청서상 품목, 수량을 확인하고 생산팀장의 승인 여부를 검사함 (품목 XXX, 수량 XXX) | E17: 원재료구매요청서(B2.1.1)
B18: (2) 발주서상 품목, 수량과 원재료구매요청서상 품목, 수량의 일치함을 확인함 구매팀장과 담당 임원의 발주서 승인 여부를 검사함 | E18: 발주서(B2.1.2)
B19: (3) 입고전표상 수량, 단가 확인. 창고 담당자에게 질문한 결과 수량은 실제 검수 수량으로 단가는 거래명세표 단가로 입력하였다는 답변을 받음 물류팀장, 재무회계팀장의 입고전표 승인 확인 | E19: 입고전표(B2.1.3), 매입장(B2.1.4) | G19: P-01
B20: (4) 거래명세표와 세금계산서를 검사하여 발주서, 입고전표, 거래명세표상 수량과 단가 일치 확인 | E20: 거래명세표(B2.1.5), 세금계산서(B2.1.6) | G20: P-02
B21: (5) 회계전표를 검사하여 회계전표상 일자 및 금액이 거래명세표와 일치함을 확인 회계전표상 재무회계팀장의 승인 확인. 재무회계팀장에게 질문한 결과 재무회계팀장은 발주서, 입고전표, 거래명세표상 수량과 단가가 일치하는 경우에만 회계전표를 승인함 | E21: 매입전표(B2.1.7), 총계정원장(B2.1.8) | G21: P-02
B22: (6) X월 외상대 결제액 집계표를 검사하고 수량 및 단가가 변동된 발주 건이 없음을 확인 | E22: 외상대 결제액 집계표(B2.1.9) | G22: P-03
B24: 3. (통제활동의 설계와 실행 여부를 평가한 경우) 해당 통제활동과 설계 및 실행 여부 평가 결과를 기술한다
B25: 통제활동번호 | C25: 관련 위험 | D25: 통제 활동 | F25: 설계 효과성 및 실행 여부 | G25: 핵심통제활동여부(O,X)
B26: P-01 | C26: 가공의 매입이 기록된다. 매입 수량, 금액이 잘못 기록된다. | D26: 입고전표상 수량은 입고증과 일치하고 단가는 거래명세표와 일치하는 지 물류팀장과 재무회계팀장이 각각 확인하고 입고전표 승인합니다. | F26: 효과적임 | G26: O
B27: P-02 | C27: 원재료 매입이 기록되지 않는다. 매입 수량, 금액이 잘못 기록된다. | D27: 재무회계팀장은 발주서, 입고전표, 거래명세표에 대한 수량과 단가를 대조 확인한 후 일치하는 경우에만 매입 회계전표를 승인한다. | F27: 효과적임 | G27: O
B28: P-03 | C28: 원재료 매입이 기록되지 않는다. 가공의 매입이 기록된다. 매입 수량, 금액이 잘못 기록된다. | D28: 재무회계팀 결산담당자는 매월 외상대 결제액 집계표를 작성하여 구매담당자에게 회람한 후 대표이사의 승인받는다. | F28: 효과적임 | G28: O
B30: 4. 내부통제 미비점이 식별된 경우. 유의적 미비점에 해당하는지 결정하고 감사기준서 265에 따라 경영진 또는 지배기구와 커뮤니케이션 한다.
B31: 내부통제 미비점 | C31: 유의적 미비점 여부(Y/N) | D31: 경영진 또는 지배기구와의 커뮤니케이션 여부 및 시기 | F31: 상세 커뮤니케이션 조서 참조

Sheet 2532
A2: 2532 정보기술(IT)시스템과 IT일반통제의 이해와 평가 (기준서 315)
A3: (IT시스템 내부통제질문서)
A5: 회사명 | B5: ='2100'!B4 -> 0 | C5: 작성자 | E5: ='2100'!D4 -> 0 | I5: 일자
A6: 결산일 | B6: ='2100'!B5 -> 0 | C6: 검토자 | E6: ='2100'!D5 -> 0 | I6: 일자
A8: 질 문 사 항 | E8: Y | G8: N | I8: N/A | K8: 서술내용
A9: Ⅰ. 일반통제
A10: 1. 일반사항 : 전산환경에 대한 일반적 정보
A11: (1) 전산실의 조직과 전산화 Master Plan의 징구
A12: (2) 당년도중 시스템 신규개발계획이나 변경계획 유무 확인
A13: (3) 전기이후 중요한 변경이 된 프로그램 리스트 징구
A14: (4) 현재 전산처리되고 있는 업무분야의 리스트 징구
A15: (5) 주전산기의 형태
A16: - 설치장소
A17: - 본체
A18: 제작사 : IBM, HP, UNISYS, Fuzitz, VAX, 기타( )
A19: 시스템 모델 :
A20: 소유형태 : 임차, 매입, 리스
... A158: [결론을 기재한다]

Sheet 2600
B2: 2600 내부회계관리제도 검토
A3: * 2025년부터 경영진은 내부회계관리제도의 설계 및 운영실태를 평가함에 있어 금융감독원에서 발표한 [평가 및 보고 기준]을 적용해야 함
A5: 회사명 | B5: 0 | D5: 작성자 | E5: 0 | F5: 작성일자
A6: 결산일 | B6: 0 | D6: 검토자 | E6: 0 | F6: 검토일자
A8: Ⅰ. 외부감사법 등 법규 요구사항의 충족여부 검토절차 예시
A9: 항 목 | D9: 관련법규 | E9: 수행내용 또는 조서번호 | F9: 수 행 자 | G9: 비 고
A12: 1. 내부회계관리규정에 다음의 항목들이 포함되어 있는가? | D12: 법 제8조 ①, 시행령 제9조 ②
A13: a) 회계정보(회계정보의 기초가 되는 거래에 관한 정보를 포함)의 식별·측정·분류·기록 및 보고방법에 관한 사항
A14: b) 회계정보의 오류를 통제하고 이를 수정하는 방법에 관한 사항
A15: c) 회계정보에 대한 정기적인 점검 및 조정 등 내부검증에 관한 사항
A16: d) 회계정보를 기록·보관하는 장부(자기테이프·디스켓 그 밖의 정보보존장치를 포함)의 관리방법과 위조·변조·훼손 및 파기를 방지하기 위한 통제절차에 관한 사항
A17: e) 회계정보의 작성 및 공시와 관련된 임직원의 업무분장과 책임에 관한 사항(*1)
A18: f) 법 제8조1항에 따른 내부회계관리규정의 제정 및 개정절차에 관한 사항
A19: g) 법 제8조제3항에 따른 내부회계관리자의 자격요건 및 임면절차
A20: h) 법 제8조제4항에 따른 회사 대표자의 운영실태보고의 기준 및 절차(*2)
A21: I) 법 제8조제5항에 따른 감사(감사위원회)의 평가·보고의 기준 및 절차(*3)
A22: j) 법 제8조제5항에 따른 감사(감사위원회)의 평가 결과를 회사의 대표자등의 인사·보수 및 차기 사업연도 내부회계관리제도 운영계획 등에 반영하기 위한 절차 및 방법
A23: k) 내부회계관리규정 위반의 예방 및 사후조치에 관한 다음 사항 ① 회사의 대표자등을 대상으로 하는 교육·훈련의 계획·성과평가·평가결과의 활용 등에 관한 사항
A24: ② 회사의 대표자등이 내부회계관리규정을 관리·운영하는 임직원 또는 회계정보를 작성·공시하는 임직원에게 내부회계관리규정에 위반되는 행위를 지시하는 경우에 해당 임직원이 지시를 거부하더라도 그와 관련하여 불이익을 받지 아니하도록 보호하는 제도에 관한 사항
... A28: ⑥ 내부회계관리규정을 위반한 임직원의 징계 등에 관한 사항
A29: (*1) 회계정보의 작성 및 공시와 관련된 임직원의 업무 분장과 책임에 관한 사항` 회사는 법 제8조제1항제5호에 따른 회계정보의 작성·공시와 관련된 임직원의 업무분장과 책임에 관한 사항을 법 제8조제1항제1호부터 제4호까지의 업무가 효과적으로 수행될 수 있도록 정하여야 한다. 법 제8조제1항 각 호의 사항이 포함된 내부회계관리규정과 이를 관리·운영하는 조직(이하 "내부회계관리제도"라 한다)과 관련된 임직원 및 회계정보의 작성·공시와 관련된 임직원은 맡은 업무를 수행하는데 필요한 권한과 역량을 충분히 갖추어야 한다. | D29: 외부감사 및 회계 등에 관한 규정 제6조 ①과 ②
A30: (*2) 회사 대표자의 운영실태보고의 기준 및 절차 회사는 다음을 고려하여 내부회계관리제도 운영실태보고서를 작성하는데 필요한 기준 및 절차를 정하여야 한다. <내부회계관리제도 운영실태보고서 작성에 관한 사항> a) 내부회계관리제도가 회사에 적합한 형태로 설계·운영될 것 b) 신뢰할 수 있는 회계정보의 작성과 공시를 저해하는 위험을 예방하거나 적시에 발견하여 조치할 수 있는 상시적·정기적인 점검체계를 갖출 것 c) 내부회계관리제도의 효과성을 점검하기 위한 객관적인 성과지표를 정할 것 d) 회사의 대표자는 다목에 따른 성과지표 및 내부회계관리제도에 취약사항이 있는지에 대한 점검결과 등을 고려하여 회사의 내부회계관리제도가 효과적인지에 대한 의견을 제시할 것 e) 내부회계관리제도에 대하여 영 제29조에 따른 감리를 받은 경우에는 그 감리에 따른 시정조치 계획을 영 제9조제4항제1호의 계획에 반영할 것 | D30: 외부감사 및 회계 등에 관한 규정 제6조 ③
A31: (*3) 감사(감사위원회)의 평가·보고의 기준 및 절차 회사는 다음을 고려하여 내부회계관리제도 평가보고서를 작성하는데 필요한 기준 및 절차를 정하여야 한다. a) 회사의 경영진 및 회사의 경영에 사실상 영향력을 미칠 수 있는 자가 회계정보의 작성·공시 과정에 부당하게 개입할 수 없도록 내부회계관리제도가 설계 및 운영되는지를 평가할 것 b) 법 제8조제1항제1호부터 제6호까지의 사항이 실질적으로 운영되는지를 평가할 것 c) 회사의 대표자가 내부회계관리제도 운영실태보고서 작성에 관한 기준 및 절차를 준수하는지를 평가할 것 | D31: 외부감사 및 회계 등에 관한 규정 제6조 ③
A32: 항 목 | D32: 관련법규 | E32: 수행내용 또는 조서번호 | F32: 수 행 자 | G32: 비 고
A34: 2. 내부회계관리규정의 제정 및 개정 시 감사의 승인 및 이사회의 결의를 득하고 있는가? 이 경우 감사와 이사회는 승인 또는 결의의 이유 등을 문서(전자문서를 포함한다. 이하 같다)로 작성·관리하여야 한다 | D34: 시행령 제9조③
A35: 3.1 대표자가 내부회계관리제도의 관리·운영에 대한 책임을 지고 있는가? | D35: 법 제8조 ③, 시행령 제2조의 3②
A36: 3.2 상근이사(담당하는 이사가 없는 경우 당해 이사의 업무를 집행하는 자) 1인을 내부회계관리자로 지정하고 있는가?
A37: 3.3 내부회계관리자는 이사회 또는 감사(감사위원회를 포함한다)가 법 제2조의2제4항 및 제5항의 직무를 수행하기 위하여 자료의 제출을 요구하는 경우에 성실히 따르고 있는가?
A38: 4. 회사의 대표자(대표자가 필요하다고 판단하는 경우 이사회 및 감사에 대한 보고는 내부회계관리자가 보고 가능하며 이 경우 보고 전에 회사의 대표자가 내부회계관리자가 보고하는 사유를 이사회 및 감사에게 문서로 제출하여야 한다)가 사업연도마다 내부회계관리제도의 운영실태를 주주총회, 이사회 및 감사(감사위원회)에 대면 보고하였는가? 대표자의 내부회계관리제도 운영실태보고서에는 다음 내용이 포함되어야 한다. | D38: 법 제8조④, 시행령 제9조의④
A39: a) 내부회계관리제도의 운영실태를 점검한 결과 및 취약 사항에 대한 시정조치 계획 b) 직전 사업연도에 보고한 제1호에 따른 시정조치 계획의 이행 결과 c) 다음 사항을 확인하고 서명하여 보고 내용에 첨부하였다는 사실 ① 가. 보고 내용이 거짓으로 기재되거나 표시되지 아니하였고, 기재하거나 표시하여야 할 사항을 빠뜨리고 있지 아니하다는 사실 ② 나. 보고 내용에 중대한 오해를 일으키는 내용이 기재되거나 표시되지 아니하였다는 사실 ③ 다. 충분한 주의를 다하여 보고 내용의 기재 사항을 직접 확인·검토하였다는 사실
A40: 5. 감사(위원회)가 사업연도별로 내부회계관리제도의 운영실태를 평가하여 내부회계관리제도 평가보고서를 작성하고 주주총회 1주일 전까지 이사회에 보고하고 해당회사의 본점에 5년간 비치하고 있는가? 감사(위원회)의 내부회계관리제도 평가보고서는 다음 내용을 포함하여야 한다. | D40: 법 제8조 ⑤, 시행령 제9조⑤
A41: a) 내부회계관리제도의 관리·운영에 대하여 시정 의견이 있으면 그 의견 b) 해당 회사의 내부회계관리제도가 신뢰성 있는 회계정보의 작성 및 공시에 실질적으로 기여하는지를 평가한 결과 및 시정 의견 c) 내부회계관리제도 운영실태보고서에 거짓으로 기재되거나 표시된 사항이 있거나, 기재하거나 표시하여야 할 사항을 빠뜨리고 있는지를 점검한 결과 및 조치 내용 d) 내부회계관리제도 운영실태보고서의 시정 계획이 회사의 내부회계관리제도 개선에 실질적으로 기여할 수 있는지를 검토한 결과 및 대안
A42: 6.1 회사는 내부회계관리제도에 의해 회계정보를 작성하는가? | D42: 법 제8조 ②
A43: 6.2 내부회계관리제도에 의하여 작성된 회계정보를 위조·변조·훼손 및 파기 하지 않는가? | D43: 시행령 제9조 ⑥
A44: 7. 감사(위원회)가 내부회계관리제도 운영실태보고 및 실태에 대한 평가를 수행하기 위하여 필요한 자료나 정보의 제출을 요구하는 경우 회사의 대표자는 성실히 응하고 있는가? | D44: 시행령제제9조 ⑥
A45: 8.1 다음 항목들을 사업보고서에 첨부하여 공시하고 있는가?[사업보고서 제출대상법인만 해당] a) 법 제8조제1항에 따른 내부회계관리규정과 이를 관리·운영하는 조직 및 인력에 관한 사항 b) 법 제8조제6항에 따른 감사인의 검토의견 또는 감사의견 c) 내부회계관리제도 운영실태보고서(내부회계관리자 또는 대표자) d) 내부회계관리제도 평가보고서(감사) | D45: 시행령 제9조 ⑨, 외부감사 및 회계 등에 관한 규정 제7조
A46: 8.2 금융위원회가 정하는 바에 따라 내부회계관리제도에 관한 사항을 공시하고 있는가? [사업보고서 제출대상법인만 해당]
A47: Ⅱ. 경영진 자체평가 근거자료의 적정성 검토절차 예시
A48: 항 목 | D48: 회사의 준비자료 | E48: 수행내용 또는 조서번호 | F48: 수 행 자 | G48: 비 고
A50: 1. 내부회계관리제도 범위선정 자료
...

Sheet 2700
A2: 2700 중요성
A4: 회사명 | B4: ='2100'!B4 -> 0 | C4: 작성자 | D4: ='2100'!D4 -> 0 | E4: 일자
A5: 결산일 | B5: ='2100'!B5 -> 0 | C5: 검토자 | D5: ='2100'!D5 -> 0 | E5: 일자
A7: 항 목 | D7: 조서번호 | E7: 수 행 자 | F7: 비 고
A8: (중요성 금액의 결정)
A10: 1. 전반감사전략을 수립할 때 재무제표 전체에 대한 중요성을 결정해야 한다.
A11: 2. 감사인은 중요왜곡표시위험을 평가하고 추가감사절차의 성격, 시기 및 범위를 결정하기 위하여 수행중요성을 결정하여야 한다.
A12: 3. 당해 기업의 특정한 상황에서, 하나 이상의 특정 거래유형과 계정잔액 및 공시에 대하여 재무제표 전체에 대한 중요성보다 작은 왜곡표시가 재무제표에 기초한 이용자의 경제적 의사결정에 영향을 줄 것이라고 합리적으로 예상되는 경우, 감사인은 이러한 거래유형과 계정잔액 및 공시에 적용되는 중요성 수준도 결정하여야 한다.
A13: 4. 감사인은 명백하게 사소한 것을 제외하고는 감사 중 식별된 왜곡표시를 집계하여야 한다.
A14: 일정한 금액에 미달되는 왜곡표시는 명백하게 사소하여 재무제표에 중요한 영향을 미치지 않을 것으로 예상할 수 있을 것이다. 따라서 이러한 금액은 집계할 왜곡표시에 포함시키지 않도록 그 금액을 지정할 수 있을 것이다. 명백하게 사소한 중요성 금액의 산정과 관련하여 Audit Guide 2700 중요성을 참조하고, 이와 관련된 적절한 절차는 조서번호 8100 왜곡표시의 평가를 참조한다.
A15: (중요성 금액의 변경)
A16: 1. 감사인은 최초에 설정한 중요성을 다르게 결정했을 정보를 감사 중에 알게 된 경우, 재무제표 전체에 대한 중요성 (그리고 해당되는 경우, 특정 거래유형과 계정잔액 및 공시에 대한 중요성 수준)을 수정하여야 한다.
A17: 2. 감사인은 재무제표 전체에 대한 중요성 (그리고 해당되는 경우, 특정 거래유형과 계정잔액 및 공시에 대한 중요성 수준)을 최초에 결정한 중요성보다 낮추는 것이 적합하다고 결정한 경우, 수행중요성을 수정하는 것이 필요한지 그리고 추가감사절차의 성격, 시기 및 범위가 여전히 적합한지 여부를 결정하여야 한다.
A18: (문서화)
A19: 1. 다음의 금액 그리고 그러한 금액을 결정할 때 고려한 요소들을 감사문서에 포함시켜야 한다.
A20: (1) 재무제표 전체에 대한 중요성
... A24: 2. 감사인은 그 미만의 왜곡표시는 명백하게 사소하다고 간주될 금액을 감사문서에 포함시켜야 한다.
